Workbook

Sheet Jak działa gra v10
A1: HARBORLIGHT10 • jak działa gra
A2: Czytaj cztery widoczne zakładki v10. Bieżące zasady obejmują frontend-v15 i v16; wszystkie 52 zakładki Excela 9 zachowano jako ukryte archiwum. Dawne kalkulatory i opisy nie zastępują tych nowszych zasad.
A5: Mechanika | B5: Zasada w najwyżej trzech zdaniach | C5: Źródło / status
A6: Cel wyspy | B6: Rozbudowujesz całą osadę, zapewniając mieszkańcom żywność, domy, pracę i szczęście. Produkcja, handel, transport oraz wszystkie budynki wspólnie umożliwiają rozwój wyspy. | C6: V15-09
A7: Start | B7: Zaczynasz z 12 osobami w domu, Ratuszem 1 i po 100 każdego z sześciu zasobów. Nie ma przydzielonych pracowników, a szczęście wynosi 0%. Oddzielny profil nowego gracza nie kasuje poprzedniej wyspy. | C7: Start / oddzielny zapis
A8: Nazwa i profil | B8: Podczas rejestracji wybierasz nazwę swojej wyspy, zapisywaną dopiero po poprawnym zatwierdzeniu formularza. Samodzielny formularz kieruje do normalnego nowego profilu, a wejście z istniejącej wyspy zachowuje jej profil i slot. Nazwa pozostaje dosłowna w obu językach, a zapis nie tworzy prawdziwego konta. | C8: V15-05
A9: Poziom i mieszkanie | B9: Poziom Ratusza jest poziomem gry i ogranicza ulepszanie innych budynków. Ratusz daje limit 24 mieszkańców na poziom, a Dom osobno zapewnia 24 łóżka na swój poziom. Brak łóżek zmniejsza szczęście wszystkich o 1 pp/h za każdą osobę bez miejsca. | C9: Reguły V7/V8 zachowane
A10: Przydział i podróż | B10: Każde z ośmiu miejsc pracy ma limit 12 × własny poziom, ze wspólnej puli wolnych osób w domu. Do pracy i z powrotem idzie się po 5 minut. Po zwolnieniu osoba bez ładunku od razu rozpoczyna powrót. | C10: V9-19 / F04
A11: Tragarz z ładunkiem | B11: Odwołany tragarz najpierw kończy rozpoczętą dostawę i do tego czasu nadal pracuje. Nie bierze kolejnego kursu, potem wraca do domu przez 5 minut. Dopiero powrót czyni go dostępnym. | C11: V9-19
A12: Produkcja | B12: Poziomy 1, 2, 3, 4 dają na osobę 20, 24, 26, 28 sztuk/h, a dalej +2 sztuki/h na poziom. Każda osoba ma własny postęp gotowej sztuki; nowa baza nadal podlega głodowi i istniejącym premiom. Zwolnienie kasuje jej niedokończoną sztukę. | C12: V9-50 + V15-15
A13: Młyn i tartak | B13: Młyn zużywa 2 zboża z centrali na 1 żywność, a tartak 2 drewna na 1 deskę. Surowiec schodzi dopiero przy ukończeniu produktu. Brak wejścia lub miejsca wstrzymuje postęp bez jego utraty. | C13: V9-50
A14: Dwa magazyny | B14: Gotowe produkty czekają lokalnie: pojemność wynosi 200 × własny poziom producenta. Dopiero tragarze zanoszą je do centrali, skąd można je wydawać i karmić ludzi. Monety są osobno w skarbcu. | C14: V8 / V9-45
A15: Pojemność centrali | B15: Magazyn 1 mieści 1000 każdego materiału i 4000 łącznie; oba limity rosną ×1,5 na poziom. 50 × poziom Magazynu pojemności łącznej jest zarezerwowane dla żywności. Materiały przypisane budowie nadal zajmują miejsce aż do odbioru przez tragarza. | C15: V9-14,45
A16: Jedzenie | B16: Każdy mieszkaniec zużywa 1 żywność/h, automatycznie i równomiernie z centrali. Jedna sztuka wystarcza 12 osobom na 5 minut. Po wyczerpaniu posiłku wszystkich dotyczy brak jedzenia. | C16: V9-46
... A90: 25. Zrób przegląd swojej wyspy | B90: Wróć do menu wyspy i sprawdź żywność, pracę, magazyny, szczęście i plany budowy. Możesz już samodzielnie zarządzać wyspą. | C90: Po 100–300 każdego z pięciu materiałów; Share daje drugi raz tę samą skrzynię.

Sheet Budynki v10
A1: BUDYNKI V10 • po co są i co kosztują
A2: L to obecny własny poziom, N to nowy poziom. Koszty kolejki rosną o 10% i są zaokrąglane w górę. T to rzeczywisty transport od pierwszego odbioru do ostatniej dostawy; podany czas budowania nie zawiera samej dostawy.
A5: Budynek | B5: EN | C5: Po co jest | D5: Ludzie: start / limit | E5: Korzyść poziomu | F5: Koszt ulepszenia | G5: Sama budowa | H5: Ważna zasada
A6: Ratusz | B6: Town Hall | C6: Określa poziom wyspy, limit mieszkańców i granicę rozbudowy innych budynków. | D6: 0 | E6: 24 × L mieszkańców; L budów + L kolejki | F6: 500 × L każdego z 6 zasobów | G6: T | H6: Efekty u góry; zarządzanie budową tylko tutaj
A7: Dom | B7: House | C7: Zapewnia miejsca mieszkalne, wolne osoby do pracy i codzienną pulę szczęścia. | D7: 0 | E7: 24 × L łóżek; dzienna pula według populacji | F7: 500 × L każdego z 6 zasobów | G7: T | H7: Zbiorcze zarządzanie pracą tylko tutaj; automat 23:58
A8: Farma | B8: Farm | C8: Produkuje zboże, które młyn przetwarza na żywność. | D8: 0 / 12 × własny L | E8: 20/24/26/28… szt./os./h; bufor 200L | F8: L × (72 drewna +72 kamienia +120 zboża) | G8: T | H8: Osobne postępy; magazyn lokalny i centrala
A9: Młyn | B9: Windmill | C9: Przetwarza 2 zboża z centrali na 1 żywność dla mieszkańców. | D9: 0 / 12 × własny L | E9: 20/24/26/28… szt./os./h; bufor 200L | F9: 2L × (72 drewna +72 kamienia +120 żywności) | G9: T | H9: Wejście pobierane przy gotowej sztuce
A10: Kamieniołom | B10: Quarry | C10: Wydobywa kamień do rozbudowy budynków i ulepszania ścieżek. | D10: 0 / 12 × własny L | E10: 20/24/26/28… szt./os./h; bufor 200L | F10: 2L × (72 drewna +192 kamienia) | G10: T | H10: Suma kamienia konstrukcyjnego i własnego produktu
A11: Drwale | B11: Lumber Camp | C11: Dostarczają drewno do budowy i przetwarzania w tartaku. | D11: 0 / 12 × własny L | E11: 20/24/26/28… szt./os./h; bufor 200L | F11: 2L × (192 drewna +72 kamienia) | G11: T | H11: Suma drewna konstrukcyjnego i własnego produktu
A12: Tartak | B12: Sawmill | C12: Przetwarza 2 drewna z centrali na 1 deskę do budowy. | D12: 0 / 12 × własny L | E12: 20/24/26/28… szt./os./h; bufor 200L | F12: 2L × (72 drewna +72 kamienia +120 desek) | G12: T | H12: Wejście pobierane przy gotowej sztuce
A13: Magazyn | B13: Warehouse | C13: Przechowuje zasoby i wysyła tragarzy po produkcję oraz z materiałami na budowy. | D13: 0 / 12 × własny L | E13: L1: 120/kurs; pojemność ×1,5 i ładunek ×1,1/poziom | F13: 300 × L każdego z 6 zasobów | G13: T | H13: Miejsce 50L dla żywności; fizyczne rezerwacje zajmują skład
A14: Targ | B14: Market | C14: Wymienia towary na inne w tej samej grupie z marżą 10%, od Ratusza 2. | D14: 0 / 12 × własny L | E14: L1: 1000 łącznie i 120/kurs, dalej odpowiednio ×1,5 i ×1,1 | F14: 300 × L każdego z 6 zasobów | G14: T | H14: 10→9; 1 h blokady; własny transport; wymiana przy 0 obsady
A15: Port | B15: Harbor | C15: Kupuje i sprzedaje materiały za monety oraz obsługuje ich transport statkiem, od Ratusza 4. | D15: 0 / 12 × własny L | E15: L1: 1000/rodzaj, 4000 łącznie, 120/kurs; potem limity ×1,5 i ładunek ×1,1 | F15: 400 × L każdego z 6 zasobów | G15: T | H15: Paczki 100; 2 etapy transportu; osobne partie 24 h
A16: Kaplica | B16: Chapel | C16: Udziela błogosławieństw zapewniających zasoby i czasowe szczęście. | D16: 0 | E16: +10 × N pp oraz mechaniczne podatki ×2 na 10 h | F16: N × (180 monet +20 drewna +60 kamienia +10 desek) | G16: 3T × (N−1) | H16: Darmowe użycie nie przesuwa blokady płatnego
A17: Latarnia | B17: Lighthouse | C17: Nagradza odbudowę premiami i oferuje wizyty podnoszące szczęście mieszkańców. | D17: 0 | E17: 100% H i produkcja ×2 przez 24 h × N | F17: 500 × max(1,L) każdego z 6 zasobów | G17: 4T | H17: Poziom 0: Ruiny; własne nazwy 1–100; wizyty 4 h, osobiste 24 h, grupa +10 pp/6 h

Sheet Do decyzji v10
A1: DO DECYZJI V10 • tylko to, co nadal odłożone
A2: Uzgodnione zasady i jawne ustawienia projektu nie wracają jako nowe pytania. Wysokości lojalności nie wymyślamy, a lokalne prototypy nie są prawdziwą integracją dostawcy.
A5: ID | B5: Temat | C5: Co już wiadomo / co pozostaje | D5: Status
A6: P01 | B6: Wysokości premii lojalnościowych | C6: Seria kolejnych dni, reset po przerwie, koniec po 10 nagrodach lub przy Ratuszu 4 i północ czasu polskiego są ustalone. Brakuje kwot nagród; nie przyznajemy w ich miejsce monet ani skrzyń samouczka. | D6: NIEUSTALONE KWOTY
A7: P02 | B7: Prawdziwe reklamy i nagrody reklamowe | C7: Nie podłączono odtwarzania i weryfikacji reklam. Docelowe dodatkowe czasy lub mnożniki po reklamie nadal wymagają osobnej konfiguracji i integracji. | D7: INTEGRACJA ODŁOŻONA
A8: P03 | B8: Konta, płatności, publikacje i polecenia | C8: Formularze i lokalne reguły nie tworzą rzeczywistych kont, płatności ani postów. Serwerowe powiązanie profilu użytkownika z grą i weryfikacja publikacji/poleceń pozostają do wdrożenia. | D8: BACKEND / INTEGRACJE ODŁOŻONE
A9: P04 | B9: Osobna aktywność modlitewna | C9: Nie ustalono odrębnej liczby miejsc, czasu ani efektów modlitwy. Obecne ręczne błogosławieństwa Kaplicy są niezależną, działającą mechaniką. | D9: ODŁOŻONE

Sheet Kalkulator v10
A1: KALKULATOR V10 • jeden scenariusz
A2: Niebieskie pola można zmieniać. Wyniki są przykładami, a nie odczytem zapisu gry. Nowa baza produkcji i ładunku, koszt atrakcji i skrzynie odpowiadają bieżącym zasadom; krzywe trudności minigier pozostają jawną konfiguracją projektu.
A5: Obszar | B5: Parametr / wynik | C5: Wartość | D5: Jednostka | E5: Znaczenie
A6: Produkcja oraz transport
A7: Wejście | B7: Własny poziom producenta / tragarzy | C7: 1 | D7: poziom
A8: Wejście | B8: Pełny poziom wszystkich dróg | C8: 0 | D8: 0…5
A9: Wejście | B9: Pracujący tragarze | C9: 6 | D9: osób
A10: Wejście | B10: Wyżywienie | C10: 1 | D10: 1 lub 0,5
A11: Wejście | B11: Każdy z pięciu materiałów do przewozu | C11: 500 | D11: szt. | E11: Każdy rodzaj wymaga osobnych kursów.
A12: Wejście | B12: Mnożnik samej fazy budowania | C12: 1 | D12: × | E12: Zwykle 1; latarnia 4; kaplica 3 × (nowy poziom−1).
A13: Wynik | B13: Produkcja bazowa na osobę | C13: =IF(C7=1,20,2*(C7+10)) -> 20 | D13: szt./godz.
A14: Wejście | B14: Mnożnik aktywnej gry | C14: 1 | D14: 1 lub 2 | E14: Aktywna gra nie przyspiesza transportu.
A15: Wejście | B15: Mnożnik premii latarni | C15: 1 | D15: 1 lub 2
A16: Wynik | B16: Produkcja po premiach i głodzie | C16: =C13*C10*C14*C15 -> 20 | D16: szt./os./godz.
A17: Wynik | B17: Ładunek na kurs | C17: =ROUNDDOWN(ROUNDDOWN(120*1.1^(C7-1),0)*(1+0.1*MAX(0,C8-2)),0) -> 120 | D17: szt.
A18: Wynik | B18: Kursy dla pięciu materiałów | C18: =5*ROUNDUP(C11/C17,0) -> 25 | D18: kursów
A19: Wynik | B19: Normalny transport bez innych zadań | C19: =IF(C9>0,ROUNDUP(C18/C9,0)*5/(1+0.1*C8)/C10,"brak obsady") -> 25 | D19: min | E19: Estymata; rzeczywisty T obejmuje przerwy.
A20: Wynik | B20: Sama budowa z tego T | C20: =IF(ISNUMBER(C19),C19*C12,"brak estymaty") -> 25 | D20: min
A21: Wynik | B21: Transport i budowa | C21: =IF(ISNUMBER(C19),C19+C20,"brak estymaty") -> 50 | D21: min
A22: Wynik | B22: Natychmiastowy transport: cena | C22: =C18*10 -> 250 | D22: monet | E22: Dotyczy jednego wybranego etapu.
A24: Prognozy FIFO i Premium
A25: Wejście | B25: Miniony rzeczywisty T | C25: 10 | D25: min
A26: Wejście | B26: Normalna estymata reszty transportu | C26: 5 | D26: min | E26: Przy zerowej obsadzie: jeden hipotetyczny tragarz.
A27: Wynik | B27: Budowanie po dowozie Premium | C27: =(C25+C26)*C12 -> 15 | D27: min
A28: Wejście | B28: Fizycznie dostępny kamień | C28: 200 | D28: szt.
A29: Wejście | B29: Bazowy kamień każdego z dwóch planów | C29: 300 | D29: szt.
A30: Wynik | B30: Każdy plan po kolejce +10% | C30: =ROUNDUP(C29*1.1,0) -> 330 | D30: szt.
A31: Wynik | B31: Rezerwacja pierwszego planu | C31: =MIN(C28,C30) -> 200 | D31: szt.
A32: Wynik | B32: Brak pierwszego planu | C32: =MAX(0,C30-C31) -> 130 | D32: szt.
A33: Wynik | B33: Dopłata pierwszego planu | C33: =ROUNDUP(C32*0.5*0.25,0) -> 17 | D33: monet
A34: Wynik | B34: Rezerwacja drugiego planu | C34: =MIN(MAX(0,C28-C31),C30) -> 0 | D34: szt.
A35: Wynik | B35: Brak drugiego planu | C35: =MAX(0,C30-C34) -> 330 | D35: szt.
A36: Wynik | B36: Dopłata drugiego planu | C36: =ROUNDUP(C35*0.5*0.25,0) -> 42 | D36: monet
A37: Wynik | B37: Obie dopłaty | C37: =C33+C36 -> 59 | D37: monet | E37: Ten sam kamień jest zastawiony tylko raz.
A39: Atrakcja • jedna na całej wyspie przez sześć godzin
A40: Wejście | B40: Cała populacja | C40: 48 | D40: osób
A41: Wejście | B41: Utrwalony w ofercie zasięg | C41: 25 | D41: % populacji | E41: Losowanie 1–50 przy utworzeniu oferty.
A42: Wejście | B42: Uprawnieni mieszkańcy | C42: 20 | D42: osób | E42: Bez zamrożonych nowych osób i już szczęśliwych w 100%.
A43: Wejście | B43: Y z oferty | C43: 50 | D43: pp | E43: Od 5 do 100.
A44: Wejście | B44: Numer zakupu tego rodzaju | C44: 2 | D44: 1…5 | E44: Reset przyzwyczajenia po 24 h przerwy.
...

Sheet Jak działa gra
A1: HARBORLIGHT9 • jak działa gra
A2: Czytaj tylko cztery widoczne zakładki. Każda mechanika ma najwyżej trzy zdania; 45 zakładek wersji 8 zachowano jako ukryte archiwum, którego nie trzeba czytać. Zasady V9 i nowsza rozmowa mają pierwszeństwo; stan testów i publikacji gry znajduje się w dokumentacji repozytorium.
A5: Mechanika | B5: Zasada w najwyżej trzech zdaniach | C5: Źródło / status
A6: Start | B6: Zaczynasz z 12 osobami w domu, Ratuszem 1 i po 100 każdego z sześciu zasobów. Nie ma przydzielonych pracowników, a szczęście wynosi 0%. Oddzielny profil nowego gracza nie kasuje poprzedniej wyspy. | C6: Start / oddzielny zapis
A7: Poziom i mieszkanie | B7: Poziom Ratusza jest poziomem gry i ogranicza ulepszanie innych budynków. Ratusz daje limit 24 mieszkańców na poziom, a Dom osobno zapewnia 24 łóżka na swój poziom. Brak łóżek zmniejsza szczęście wszystkich o 1 pp/h za każdą osobę bez miejsca. | C7: Reguły V7/V8 zachowane
A8: Przydział i podróż | B8: Każde z ośmiu miejsc pracy ma limit 12 × własny poziom, ze wspólnej puli wolnych osób w domu. Do pracy i z powrotem idzie się po 5 minut. Po zwolnieniu osoba bez ładunku od razu rozpoczyna powrót. | C8: V9-19 / F04
A9: Tragarz z ładunkiem | B9: Odwołany tragarz najpierw kończy rozpoczętą dostawę i do tego czasu nadal pracuje. Nie bierze kolejnego kursu, potem wraca do domu przez 5 minut. Dopiero powrót czyni go dostępnym. | C9: V9-19
A10: Produkcja | B10: Poziomy 1, 2, 3, 4 dają na osobę 10, 12, 13, 14 sztuk/h, a dalej +1 sztukę/h na poziom. Każda osoba ma własny postęp gotowej sztuki. Zwolnienie kasuje jej niedokończoną sztukę. | C10: V9-50
A11: Młyn i tartak | B11: Młyn zużywa 2 zboża z centrali na 1 żywność, a tartak 2 drewna na 1 deskę. Surowiec schodzi dopiero przy ukończeniu produktu. Brak wejścia lub miejsca wstrzymuje postęp bez jego utraty. | C11: V9-50
A12: Dwa magazyny | B12: Gotowe produkty czekają lokalnie: pojemność wynosi 200 × własny poziom producenta. Dopiero tragarze zanoszą je do centrali, skąd można je wydawać i karmić ludzi. Monety są osobno w skarbcu. | C12: V8 / V9-45
A13: Pojemność centrali | B13: Magazyn 1 mieści 1000 każdego materiału i 4000 łącznie; oba limity rosną ×1,5 na poziom. 50 × poziom Magazynu pojemności łącznej jest zarezerwowane dla żywności. Materiały przypisane budowie nadal zajmują miejsce aż do odbioru przez tragarza. | C13: V9-14,45
A14: Jedzenie | B14: Każdy mieszkaniec zużywa 1 żywność/h, automatycznie i równomiernie z centrali. Jedna sztuka wystarcza 12 osobom na 5 minut. Po wyczerpaniu posiłku wszystkich dotyczy brak jedzenia. | C14: V9-46
A15: Głód i ponowne karmienie | B15: Brak jedzenia od razu zmniejsza wydajność do połowy; po 12 h nalicza −5 pp/h. Posiłek od razu zatrzymuje karę i przywraca wydajność. Dopiero pełna godzina nieprzerwanego karmienia zeruje wcześniejszy licznik głodu. | C15: V9-1
A16: Szczęście | B16: Każda osoba ma własne szczęście ograniczone do −100…100%, a wyspa pokazuje średnią. Jedzenie i rzeczywista praca dodają osobno +1 pp/h; brak pracy po 12 h daje −5 pp/h. Prezentacja zaokrągla w górę do pełnego procentu, lecz rachunek zachowuje ułamki. | C16: V7/V8 + V9-1,2
... A51: Nowy interfejs | B51: Nie ma lewego paska ani pięciu materiałów w nagłówku; są pracujący, ETA nowej osoby i Punkty. Kafelki budynków mają ustaloną kolejność i stany osób, a zasoby pokazują lokalny / centralny (wszystkie przewozy w toku). Ustawienia obejmują EN/PL, filtry powiadomień oraz animacje, a rozwijane szczegóły efektu są pod i. | C51: F01…F06,F09…F15,F17

Sheet Budynki v9
A1: BUDYNKI • jedna czytelna tabela
A2: L oznacza obecny własny poziom budynku, N jego nowy poziom. Koszt kolejki: każdy składnik +10%, zaokrąglony w górę. T to zakończony rzeczywisty transport od pierwszego odbioru do ostatniej dostawy; kolumna budowania nie zawiera samego transportu. Wszystkie ceny bazowe pozostają zgodne z V8, z osobnymi nowymi zasadami usług i rezerwacji.
A5: Budynek | B5: EN | C5: Po co jest | D5: Ludzie: start / limit | E5: Co daje poziom | F5: Koszt ulepszenia | G5: Sama budowa | H5: Najważniejsza uwaga
A6: Ratusz | B6: Town Hall | C6: Poziom gry i limit innych budynków | D6: 0 | E6: 24 × L mieszkańców; L budów + L kolejki | F6: 500 × L każdego z 6 zasobów | G6: T | H6: Efekty u góry; zarządzanie budową tylko tutaj
A7: Dom | B7: House | C7: Łóżka, mieszkańcy i pula szczęścia | D7: 0 | E7: 24 × L łóżek; dzienna pula według populacji | F7: 500 × L każdego z 6 zasobów | G7: T | H7: Zbiorcze zarządzanie pracą tylko tutaj; automat 23:58
A8: Farma | B8: Farm | C8: Zboże | D8: 0 / 12 × własny L | E8: 10/12/13/14… szt./os./h; bufor 200L | F8: L × (72 drewna +72 kamienia +120 zboża) | G8: T | H8: Osobne postępy; magazyn lokalny i centrala
A9: Młyn | B9: Windmill | C9: 2 zboża → 1 żywność | D9: 0 / 12 × własny L | E9: Wydajność i bufor własnego poziomu | F9: 2L × (72 drewna +72 kamienia +120 żywności) | G9: T | H9: Wejście pobierane przy gotowej sztuce
A10: Kamieniołom | B10: Quarry | C10: Kamień | D10: 0 / 12 × własny L | E10: Wydajność i bufor własnego poziomu | F10: 2L × (72 drewna +192 kamienia) | G10: T | H10: Suma kamienia konstrukcyjnego i własnego produktu
A11: Drwale | B11: Lumber Camp | C11: Drewno | D11: 0 / 12 × własny L | E11: Wydajność i bufor własnego poziomu | F11: 2L × (192 drewna +72 kamienia) | G11: T | H11: Suma drewna konstrukcyjnego i własnego produktu
A12: Tartak | B12: Sawmill | C12: 2 drewna → 1 deska | D12: 0 / 12 × własny L | E12: Wydajność i bufor własnego poziomu | F12: 2L × (72 drewna +72 kamienia +120 desek) | G12: T | H12: Wejście pobierane przy gotowej sztuce
A13: Magazyn | B13: Warehouse | C13: Centrala i kursy produkcji/budów | D13: 0 / 12 × własny L | E13: Pojemność ×1,5; ładunek ×1,1/poziom | F13: 300 × L każdego z 6 zasobów | G13: T | H13: Miejsce 50L dla Food; fizyczne rezerwacje zajmują skład
A14: Targ | B14: Market | C14: Barter w 2 grupach, od Ratusza 2 | D14: 0 / 12 × własny L | E14: 1000 łącznie na L1, dalej ×1,5 | F14: 300 × L każdego z 6 zasobów | G14: T | H14: 10→9; 1 h blokady; własny transport; wymiana przy 0 obsady
A15: Port | B15: Harbor | C15: Handel monetowy od Ratusza 4 | D15: 0 / 12 × własny L | E15: 1000 na rodzaj /4000 łącznie na L1, dalej ×1,5 | F15: 400 × L każdego z 6 zasobów | G15: T | H15: Paczki 100; 2 etapy transportu; osobne partie 24 h
A16: Kaplica | B16: Chapel | C16: Premia rozbudowy i błogosławieństwa | D16: 0 | E16: +10 × N pp oraz mechaniczne podatki ×2 na 10 h | F16: N × (180 monet +20 drewna +60 kamienia +10 desek) | G16: 3T × (N−1) | H16: Darmowe użycie nie przesuwa blokady płatnego
A17: Latarnia | B17: Lighthouse | C17: Premia rozbudowy, wizyty i zadania | D17: 0 | E17: 100% H i produkcja ×2 przez 24 h × N | F17: 500 × max(1,L) każdego z 6 zasobów | G17: 4T | H17: Wizyty 4 h, osobiste 24 h, grupa +10 pp/6 h

Sheet Do decyzji
A1: DO DECYZJI • tylko rzeczy pozostawione na później
A2: Wszystkie 58 decyzji logicznych z rozmowy są rozstrzygnięte i zachowane w ukrytej zakładce Decyzje v9. Poniżej nie wracają stare pytania ani rozstrzygnięte konflikty. Ogłoszone przed GO założenia wdrożeniowe są jawnie opisane, a nie przedstawiane jako nieustalone reguły.
A5: ID | B5: Co pozostało | C5: Co już wiadomo / granica realizacji | D5: Status
A6: P01 | B6: Docelowe plansze i limity czasu minigier; krzywa prototypu musi być jawnie oznaczona jako projektowa. | C6: Reguły puli i potrąceń są zatwierdzone; krzywa czasu 180/(1+0,1×(runda−1)) jest wyłącznie konfiguracją prototypu. | D6: JAWNIE NA PÓŹNIEJ
A7: P02 | B7: Zewnętrzne reklamy, dodawanie czasu/podwajanie, hasło i limity. | C7: Nie podłączono odtwarzania ani weryfikacji reklam; nie pokazujemy fikcyjnego potwierdzenia obejrzenia. | D7: JAWNIE NA PÓŹNIEJ
A8: P03 | B8: Wysokości premii lojalnościowych i odbiór po konfiguracji. | C8: Zasady serii i końca programu są zatwierdzone; brak kwot blokuje wypłatę, nie liczenie dni. | D8: JAWNIE NA PÓŹNIEJ
A9: P04 | B9: Osobna aktywność modlitewna. | C9: Nie ustalono czasu, miejsc ani efektu osobnej modlitwy; ręczne błogosławieństwo kaplicy jest gotową odrębną regułą. | D9: JAWNIE NA PÓŹNIEJ
A10: P05 | B10: Prawdziwe konta/OAuth, płatności i serwerowa weryfikacja publikacji/poleceń. | C10: Reguły i czyste punkty integracji nie są prawdziwymi kontami, publikacjami, poleceniami ani transakcjami. | D10: JAWNIE NA PÓŹNIEJ

Sheet Kalkulator
A1: KALKULATOR • jeden scenariusz zamiast wielu tabel
A2: Niebieskie wartości możesz zmieniać. To przykłady, nie odczyt zapisu gry; założenia są podane przy wynikach. Krzywa czasu ekspedycji oraz kwoty samouczka są jawnie projektowe. Koszty transportu i budowy nie obejmują wcześniejszego zbierania zasobów ani czekania w kolejce.
A5: Obszar | B5: Parametr / wynik | C5: Wartość | D5: Jednostka | E5: Znaczenie
A6: Transport i budowa
A7: Wejście | B7: Własny poziom magazynu | C7: 1 | D7: poziom | E7: Scenariusz edytowalny
A8: Wejście | B8: Ukończony poziom dróg | C8: 0 | D8: 0…5 | E8: Scenariusz edytowalny
A9: Wejście | B9: Dostępni magazynierzy | C9: 6 | D9: osób | E9: Scenariusz edytowalny
A10: Wejście | B10: Wyżywienie | C10: 1 | D10: 1 albo 0,5 | E10: Scenariusz edytowalny
A11: Wejście | B11: Drewno do przewozu | C11: 500 | D11: szt. | E11: Scenariusz edytowalny
A12: Wejście | B12: Kamień do przewozu | C12: 500 | D12: szt. | E12: Scenariusz edytowalny
A13: Wejście | B13: Zboże do przewozu | C13: 500 | D13: szt. | E13: Scenariusz edytowalny
A14: Wejście | B14: Żywność do przewozu | C14: 500 | D14: szt. | E14: Scenariusz edytowalny
A15: Wejście | B15: Deski do przewozu | C15: 500 | D15: szt. | E15: Scenariusz edytowalny
A16: Wejście | B16: Mnożnik fazy budowania | C16: 1 | D16: 1 /4 /3×(N−1) | E16: Scenariusz edytowalny
A17: Wynik | B17: Ładunek na kurs | C17: =ROUNDDOWN(ROUNDDOWN(60*1.1^(C7-1),0)*(1+0.1*MAX(0,C8-2)),0) -> 60 | D17: szt. | E17: Własny poziom i dodatkowa pojemność dróg
A18: Wynik | B18: Potrzebne kursy | C18: =SUM(ROUNDUP(C11/C17,0),ROUNDUP(C12/C17,0),ROUNDUP(C13/C17,0),ROUNDUP(C14/C17,0),ROUNDUP(C15/C17,0)) -> 45 | D18: kursów | E18: Każdy rodzaj osobno; także ostatni niepełny
A19: Wynik | B19: Normalny transport bez innych zadań | C19: =IF(C9>0,ROUNDUP(C18/C9,0)*5/(1+0.1*C8)/C10,"brak obsady") -> 40 | D19: min | E19: To estymata; rzeczywisty T obejmuje przerwy i zmiany obsady
A20: Wynik | B20: Sama budowa z tego T | C20: =IF(ISNUMBER(C19),C19*C16,"brak estymaty") -> 40 | D20: min
A21: Wynik | B21: Transport + budowa | C21: =IF(ISNUMBER(C19),C19+C20,"brak estymaty") -> 80 | D21: min
A22: Wynik | B22: Instant transport: cena | C22: =C18*10 -> 450 | D22: monet | E22: Wyłącznie wskazany etap dostawy
A24: Premium dowóz w trakcie transportu
A25: Wejście | B25: Rzeczywisty miniony T | C25: 10 | D25: min | E25: Od pierwszego odbioru, także przerwy
A26: Wejście | B26: Normalna estymata reszty | C26: 5 | D26: min | E26: Przy 0 osób użyj jednego hipotetycznego tragarza
A27: Wynik | B27: Zamrożona sama budowa | C27: =(C25+C26)*C16 -> 15 | D27: min | E27: Dostawa jest natychmiastowa; budowanie nie zeruje się
A29: Prognozy FIFO — ten sam kamień tylko raz
A30: Wejście | B30: Kamień fizycznie dostępny | C30: 200 | D30: szt. | E30: Przed pierwszym planem
A31: Wejście | B31: Bazowy koszt każdego planu | C31: 300 | D31: szt. | E31: Dwa kolejne plany tego samego materiału
A32: Wynik | B32: Każdy plan po kolejce +10% | C32: =ROUNDUP(C31*1.1,0) -> 330 | D32: szt.
A33: Wynik | B33: Rezerwacja pierwszego planu | C33: =MIN(C30,C32) -> 200 | D33: szt. | E33: Nadal zajmuje miejsce do odbioru
A34: Wynik | B34: Brak pierwszego planu | C34: =MAX(0,C32-C33) -> 130 | D34: szt.
A35: Wynik | B35: Dopłata pierwszego | C35: =ROUNDUP(C34*0.5*0.25,0) -> 17 | D35: monet
A36: Wynik | B36: Rezerwacja drugiego | C36: =MIN(MAX(0,C30-C33),C32) -> 0 | D36: szt.
A37: Wynik | B37: Brak drugiego | C37: =MAX(0,C32-C36) -> 330 | D37: szt.
A38: Wynik | B38: Dopłata drugiego | C38: =ROUNDUP(C37*0.5*0.25,0) -> 42 | D38: monet
A39: Wynik | B39: Obie dopłaty | C39: =C35+C38 -> 59 | D39: monet | E39: Osobne zakupy zaokrąglane osobno;17+42=59
A41: Atrakcja: rzeczywiści odbiorcy
A42: Wejście | B42: Poziom Ratusza | C42: 4 | D42: poziom | E42: Maksymalna liczba odbiorców
A43: Wejście | B43: Uprawnieni odbiorcy | C43: 2 | D43: osób | E43: Bez100%H i bez zamrożonych nowych osób
A44: Wejście | B44: Wylosowane Y | C44: 50 | D44: 5…100 | E44: Zapisane w ofercie
A45: Wejście | B45: Kolejny zakup tego rodzaju | C45: 2 | D45: 1…5 | E45: Reset po 24 h bez zakupu tego rodzaju
...

Sheet Start
A1: HARBORLIGHT V8 • pełne zasady i zmiany interfejsu
A2: Źródło: niezmieniony HARBORLIGHT7-zasady.xlsx, 17 decyzji D01–D17 oraz WSZYSTKIE późniejsze zaakceptowane zmiany frontendu i gospodarki. Nowe arkusze: Zmiany v8, Frontend v8, Atrakcje, Atrakcje - kalkulator, Sciezki, Sciezki - transport, Efekty i notyfikacje, Sprawdzenia v8. Archiwalne źródła i 48 komentarzy użytkownika zachowano. Nowsze decyzje w Zmiany v8 mają pierwszeństwo.
A5: Obszar | B5: Co zmieniono | C5: Gdzie sprawdzić
A6: Główna tabela | B6: 12 budynków + asset Człowiek; własne bufory producentów, dotychczasowe limity pracy i najnowsze widoki bez podatków. | C6: Budynki
A7: Czasy | B7: Pełny bazowy kurs 5 min; ścieżki przyspieszają kursy i od poziomu 3 zwiększają ładunek. Budynki 2T; latarnia 5T; kaplica 4T/7T/10T. | C7: Czas budowy: 74 warianty (37 etapów × bazowy/kolejka).
A8: Kolejka | B8: Pełny koszt przy zleceniu +10%; dopłata materiałowa zmienia liczbę kursów i czas. | C8: Normalnie L budów + L miejsc kolejki. Czekanie w kolejce jest wyłączone z estymat.
A9: Zatrudnienie | B9: Limit 12 × własny poziom, produkcja 10/12/13/14…, 5 min do pracy. Podatki naliczane bez zmian, ale informacja o nich usunięta z UI. | C9: Czlowiek / Produkcja
A10: Offline | B10: Cała gospodarka działa również offline: podatki, jedzenie, szczęście, populacja, produkcja, transport i budowa. | C10: Transport i priorytety; Czlowiek | E10: Front usunąć znaczki czasu
A11: Koszty | B11: Magazyn/Targ: 300 L każdego zasobu; Port: 400 L; Ratusz/Dom: 500 L; Latarnia: 500 × max(1, L). | C11: Parametry / Czas budowy
A12: Transport | B12: Do trzech trwałych numerowanych priorytetów, w tym Construction. Podział kursów 8/2 losowe, 5/3/2 losowe lub 5/3/2. Ratunkowe Food zachowuje ochronę. | C12: Transport i priorytety / Czlowiek. Ratunkowy próg Food oraz rezerwa 50 × poziom magazynu są potwierdzone w V5.
A13: Ceny | B13: Port: podstawowe 40/50, produkty 140/150 za 100; podwyżki zakupowe +10% liniowo. Ostatnia korekta dotyczy PORTU, nie TARGU. | C13: Przystan; Targ: bez monet, marża 10%.
A14: Terminy | B14: Towar w porcie/targu nieodebrany przez 24 h przepada; portowa opłata 10 monet została zniesiona. | C14: Terminy zegarowe, również offline.
A15: Premie i wizyty | B15: Płatne błogosławieństwo: 100 × poziom kaplicy monet; +50 każdego zasobu i +20 pp na 1 h. Kolejne płatne użycie 4 h od KOŃCA efektu: 12:00–13:00 → następne 17:00. Nie można nakładać aktywnych błogosławieństw. Premie od powrotu: uczestnik 100% na 24 h i blokada ponownej wizyty przez te same 24 h; każda osobno wysłana grupa daje populacji +10 pp przez 6 h. Premie grup sumują się w czasie nakładania. | C15: Czlowiek / Blogoslawienstwa / Decyzje v7 D01–D02, D15.
A16: Premium | B16: 25/50/75/100% pozostałej fazy budowania, bez transportu. Cena = MAX(5, FLOOR(zaoszczędzone sekundy / 60)) monet. Transport jest osobno rozliczany za potrzebne kursy. Pełny zakup budynku od poziomu gracza 4: wszystkie materiały według proporcjonalnych bazowych cen zakupu portu ×1,25 + nominalne monety budynku + natychmiastowy transport (10 monet za każdy potrzebny kurs, także niepełny). Nic nie pobieramy z własnych materiałów. Gotowe po 10 s; bez wymogu rzeczywistych tragarzy. | C16: Premium / trzy kalkulatory / Planowanie Premium. | F16: Front w każdej bnudowli możliwość skrócenia CZASU budowy z kosztem oraz możliwość zakupu budyunku z kosztem
A17: Ludzie i ranking | B17: Najpierw dom i ludzie w drodze; potem największa załoga. Remis: port → targ → tartak → kamieniołom → drwale → farma → młyn → magazyn. Zwiedzający i uczestnicy modlitwy chronieni; jeżeli brak osoby uprawnionej, odejście nie zachodzi. Minimum 6. Ranking = Ratusz × monety, aktualizowany co pełną godzinę. | C17: Czlowiek / Populacja i szczescie. | F17: tu nie ma konfliktu opisałem już zabieraz najpierw z domu, później z miejsca gdzie jesty najwiecej w przypadku remisu kolejność, port, bazar, tartak, kamieniołom drwal, farma młyn transport, musisz kreatywnie chronić produkcji I transportu żywności
A18: Twoje wpisy | B18: Zachowano wszystkie 75 tekstowych różnic, również notatki w komórkach, nie tylko komentarze Excel. | C18: Twoje wpisy v1 / Odpowiedzi i zmiany
A19: Niewybrane szczegóły | B19: D01–D17 zamknięte. Na później: integracje kont/płatności, social, reklamy, docelowy balans ekspedycji, osobna modlitwa i wartości nagród lojalności. | C19: Decyzje v7 / Na pozniej.
A20: Nowe pomysły z repozytorium | B20: Ekspedycje i wyzwania latarni otrzymały nowe reguły; sterowanie labiryntem/piłeczką pozostaje do opisania. | C20: Zadania latarni / Ekspedycje / Zrodlo v3.
A21: Zadania latarni | B21: Zawsze 3 oferty, tylko 1 aktywne zadanie. Podświetlony postęp każdego produktu w obu widokach; pozostałe wyszarzone. Po sukcesie fajerwerki, wibracja telefonu i opcjonalny Share on Facebook za 500 monet. | C21: Zadania latarni / Zadania przyklady / Zadania - zegary / Narracje latarni.
A22: Ekspedycje | B22: 50 monet po pierwszym poziomie; każda dalsza wygrana podwaja pulę, a przegrana ją zeruje. Dodatkowe ruchy/czas: monety lub reklama ≤30 s. | C22: Ekspedycje / Ekspedycje - poziomy.
A23: Social i polecenia | B23: Nagrody społecznościowe: 1000/500 monet; polecenie: 1000 monet oraz 500 wszystkiego w 3. aktywnym dniu; 1000 monet za każdy 3. post na FB. | C23: Social i polecenia / Platformy.
A24: Balans i niejasności | B24: Nagrody skalowane od L3 i przechowywane przy braku miejsca; minimum przyspieszenia 5 monet; ekspedycje podwajają pulę. Duże zadania nadal mogą wymagać wcześniejszych zapasów. | C24: Bilans V3; zamknięte kwestie oznaczono wynikiem.
A25: Nowe koszty V5 | B25: Młyn, drwale, tartak, kamieniołom: koszt ×2; farma bez zmian. Czasy i kolejka +10% przeliczone. | C25: Budynki / Czas budowy
A26: Wymaganie interfejsu | B26: Angielskie etykiety liczb, statusy, ETA transportu i budowy; bez podatków; Resources = zapas lokalny / centralny; zarządzanie budową tylko ratusz, pracownikami tylko dom. | C26: Frontend v8 / Zmiany v8; stare notatki w kolumnach E/F są źródłowe.
A27: Dom i nowe osoby | B27: Pula domu = liczba mieszkańców przy odnowieniu, w pełnych pp, raz na 24 h. Ręczne punkty dodają H; nie kasują kar ani ich liczników. O 23 h 58 min automat rozdaje wyłącznie resztę, po 1 pp najniższemu H; remis losowy. Pula nie jest wydawana drugi raz. Każdy nowy mieszkaniec ma zamrożone 0% szczęścia przez pierwsze 24 h, również podczas premii; później zwykłe naliczanie od 0%. Początkowych 12 osób nie obejmuje zamrożenie. | C27: Czlowiek / Decyzje v7 D03–D04, D13
A28: Pakiet i prognozy | B28: Pakiet: 1000 × poziom ratusza monet za 24 h; +4 aktywne budowy, dowolna kolejka, planowanie dostaw. Dopłata kolejki +10% pozostaje; ponowny zakup przedłuża ważność. W aktywnym pakiecie plan ma koszt kolejki +10% (każdy składnik w górę), plus opłatę 25% bazowej portowej wartości zakupu braków centralnych. Baza 300 kamienia, centrala 200 → wymagane 330, brak 130; bufor producenta nie jest centralą. Materiały muszą rzeczywiście dotrzeć. | C28: Premium / Planowanie Premium
A29: Status wdrożenia | B29: Reguły w V8 są zatwierdzone. Prototyp frontendowy ma lokalny zapis; konta, OAuth, płatności i reklamy nie są integrowane. Końcowy commit, publikację i wyniki testów gry zapisujemy w docs/IMPLEMENTATION-LOG.md. | C29: Szczegóły wdrożenia i testów: docs/IMPLEMENTATION-LOG.md; Na pozniej.
... A34: Archiwum | B34: 36 zakładek źródła zachowanych; dawne rejestry i wpisy źródłowe są historią. Aktualny rejestr poprawiono i rozszerzono. | C34: Rejestr historyczny v7 / Rejestr historyczny v6

Sheet Zmiany v8
A1: ZMIANY V8 • komplet późniejszych uzgodnień
A2: Rozmowa po Excelu 7; zaakceptowany pakiet frontend v11 oraz późniejszy pakiet zatwierdzony „go”. Nowsza decyzja zastępuje poprzednią wersję tego samego widoku. Nowsze usunięcie podatków oraz zapasy lokalne/centralne na kartach Resources zastępują wcześniejsze wersje tych samych elementów.
A5: ID | B5: Obszar | C5: Asset / widok | D5: Ostateczna zasada | E5: Uwagi / źródło
A6: V8-001 | B6: Wersja | C6: Wszystkie | D6: V8 opiera się na niezmienionym pliku V7 i późniejszych uzgodnieniach. 17 decyzji D01–D17 nadal obowiązuje poza jawnymi nowszymi korektami. | E6: Decyzje v 7 są zachowane; źródła historyczne nie są nowymi wymaganiami.
A7: V8-002 | B7: Start | C7: Nowy gracz | D7: Ratusz 1, Dom 1, 12 mieszkańców w domu, 0 pracowników, 0% szczęścia; każdy z 6 zasobów po 100. Ścieżki: wszystkie 100 odcinków na 0. | E7: Normalny start nie przyznaje testowego magazynu ani 10 000 monet.
A8: V8-003 | B8: Start | C8: Podgląd testowy | D8: W dotychczasowym podglądzie jednorazowo uzupełniamy centralę do limitu na rodzaj i łącznie oraz do minimum 10 000 monet; większe saldo i postęp zachowane. | E8: Znacznik zapisu zapobiega ponownemu grantowi po odświeżeniu. To migracja piaskownicy, nie zasada startu.
A9: V8-004 | B9: Start | C9: Oddzielny nowy gracz | D9: Link profile=new-player używa oddzielnego zapisu i normalnych wartości startowych. Nie kasuje bieżącej wyspy; późniejsze otwarcie kontynuuje zapis tego profilu. | E9: Link i stan wdrożenia: docs/IMPLEMENTATION-LOG.md.
A10: V8-005 | B10: Produkcja | C10: Pięciu producentów | D10: Lokalny magazyn = 200 × WŁASNY poziom producenta. Następny poziom ma 200 × (L+1). Wczytanie nie usuwa starszej nadwyżki. | E10: Zastępuje zależność lokalnego bufora od ratusza.
A11: V8-006 | B11: Ludzie | C11: Osiem miejsc pracy | D11: Limit pozostaje 12 × własny poziom zakładu; przydział jest ograniczony wspólną pulą wolnych osób w domu. | E11: Wyświetlanie trzech liczb nie zmienia poziomu wyznaczającego limit.
A12: V8-007 | B12: Frontend | C12: Wszystkie budynki | D12: U góry panelu status odpowiedni do funkcji. Producent: Producing / Waiting for workers / Storage full / Waiting for resources. | E12: Status odświeża się według rzeczywistego stanu.
A13: V8-008 | B13: Frontend | C13: Produkcja | D13: Producing wskazuje produkt, liczbę najbliższych sztuk i czas ich złożenia w lokalnym magazynie. | E13: Uwzględnia rzeczywiste fazy pracy, dojście, głód, surowiec wejściowy i wolne miejsce.
A14: V8-009 | B14: Frontend | C14: Storage | D14: Trzy wartości: In stock / Current cap. / Next level cap. Krótkie podpisy znajdują się pod każdą liczbą. | E14: Np. 50 / 200 / 400; ostatnia liczba oznacza najbliższe ulepszenie, nie końcowy limit gry.
A15: V8-010 | B15: Frontend | C15: Workers | D15: Trzy wartości: Assigned / Free at home / Max workers; małe +/− korzystają z rzeczywistej dostępności mieszkańców. | E15: Np. 5 / 0 / 12. Osoba wracająca lub idąca nie jest wolna w domu.
A16: V8-011 | B16: Frontend | C16: Podatki | D16: Usuń wszystkie informacje o podatkach z interfejsu: nagłówka, ratusza, kart budynków, zarządzania ludźmi i objaśnień. Sam rachunek podatków pozostaje bez zmiany. | E16: Silnik nadal: 1 moneta/os./h po dotarciu, także przy przestoju; kaplica czasowo ×2. Excel dokumentuje tę regułę.
... A53: V8-048 | B53: Stan | C53: Język i zapis | D53: Aktywny interfejs po angielsku. Zachowujemy istniejące zasoby, mieszkańców, budowy, ładunki i zadania; osobne profile nie nadpisują sobie zapisów. | E53: Oryginalny Excel 7 pozostaje niezmieniony. Prawdziwe konta, OAuth, płatności i reklamy nadal wymagają osobnych integracji.

Sheet Frontend v8
A1: FRONTEND V8 • finalne zachowanie interfejsu
A2: Krótkie angielskie podpisy w grze, polski opis zasad. Późniejsza instrukcja usuwa Taxes ze wszystkich widoków i zastępuje dolne free/max na Resources zapasami lokalny/centralny. Rachunek podatków pozostaje bez zmiany.
A5: Widok | B5: Element / podpis | C5: Wartości i zachowanie | D5: Reguła / wyjątek
A6: Panel producenta | B6: Level | C6: Mniejsze pole po lewej. | D6: Pole Taxes zostało usunięte.
A7: Panel producenta | B7: Storage | C7: In stock / Current cap. / Next level cap. | D7: Zapas lokalny / 200 × L / 200 × (L+1).
A8: Miejsce pracy | B8: Workers | C8: Assigned / Free at home / Max workers | D8: Trzy podpisy pod liczbami, np. 5 / 0 / 12.
A9: Miejsce pracy | B9: +/− | C9: Przydział z faktycznie dostępnych osób. | D9: Droga trwa 5 min; brak wolnych osób blokuje plus.
A10: Każdy budynek | B10: Status | C10: Produkcja, blokada albo status odpowiedni do funkcji. | D10: Przy produkcji: produkt, ilość oraz ETA złożenia w lokalnym magazynie.
A11: Wszystkie widoki | B11: Podatki | C11: Bez wyświetlania podatków i ich opisu. | D11: Rachunek i premia kaplicy pozostają bez zmiany.
A12: House | B12: Housing capacity | C12: Populacja / limit ratusza / łóżka / przyrost lub spadek. | D12: Opisy znajdują się pod i.
A13: House | B13: House happiness | C13: Pula i zegar widoczne; opis pod i. | D13: Manage all workers otwierane wyłącznie tutaj.
A14: Town Hall | B14: Construction and queue | C14: Jedyny panel z licznikiem i zarządzaniem kolejką. | D14: Inne budynki zachowują własny Upgrade.
A15: Town Hall | B15: Active effects | C15: Aktywne błogosławieństwa, premie i kary u góry karty. | D15: Źródło, wartość, odbiorcy, czas lub warunek zakończenia; bez podatków.
A16: Producent | B16: Building upgrade | C16: Upgrade, dwa małe czasy i sąsiednia ramka Premium z dwoma przyciskami. | D16: Buy building package / Deliver local stock now. Opisy Coins/Instant pod i.
... A29: New player | B29: profile=new-player | C29: Oddzielny zapis, normalny start po 100 zasobów i 12 osób. | D29: Nie usuwa wyspy testowej; bez grantu 10 000 monet.

Sheet Decyzje v7
A1: DECYZJE V7 • 17 odpowiedzi zamkniętych
A2: Komplet rozstrzygnięć użytkownika z 23.10.2026 po analizie pliku 6. Wszystkie D01–D17 są zaakceptowane. Osobno pozostają jawnie odłożone tematy; nie blokują wydania tego arkusza.
A5: ID | B5: Temat | C5: Zatwierdzona zasada | D5: Źródło / zastosowanie
A6: D01 | B6: Długość premii populacji po latarni | C6: Premie od powrotu: uczestnik 100% na 24 h i blokada ponownej wizyty przez te same 24 h; każda osobno wysłana grupa daje populacji +10 pp przez 6 h. Premie grup sumują się w czasie nakładania. | D6: Odpowiedź użytkownika 23.10.2026; Czlowiek!C31, Blogoslawienstwa!B9, Decyzje i konflikty!G41, rozmowa23.10
A7: D02 | B7: Limit zwiedzania i płatne pakiety | C7: Darmowo 2 × poziom latarni wejść w ruchomych 24 h. Do 3 dodatkowych pakietów/24 h, każdy daje 2L wejść; cena 300 × numer pakietu (2, 3, 4) × L. Pakiet nie zwiększa liczby miejsc jednocześnie. | D7: Odpowiedź użytkownika 23.10.2026; Premium!G27, rozmowa23.10
A8: D03 | B8: Dom: efekt ręcznie rozdawanego szczęścia | C8: Punkty domu dodają pełne pp do H; kary i ich liczniki pozostają. Przykład: −50 +1 = −49%. | D8: Odpowiedź użytkownika 23.10.2026; Budynki!K7
A9: D04 | B9: Dom: pula i automat23h58 | C9: Pula domu = liczba mieszkańców przy odnowieniu, w pełnych pp, raz na 24 h. Ręczne punkty dodają H; nie kasują kar ani ich liczników. O 23 h 58 min automat rozdaje wyłącznie resztę, po 1 pp najniższemu H; remis losowy. Pula nie jest wydawana drugi raz. | D9: Odpowiedź użytkownika 23.10.2026; Budynki!K7
A10: D05 | B10: Zadania: trzy rozmiary czy kolejka dowolnych rozmiarów | C10: Zawsze 3 zadania. Początkowo małe/średnie/duże; kolejne losowego rozmiaru trafiają na koniec FIFO, dopuszczalne 3 małe lub 3 duże. Nowe po sukcesie natychmiast. | D10: Odpowiedź użytkownika 23.10.2026; Zadania latarni!C6, Zadania latarni!G19, Decyzje i konflikty!G33
A11: D06 | B11: Zadania: kotwica zegara i natychmiastowe odnowienie | C11: Trzy niezależne łańcuchy. Początkowy termin 6 h. Pierwsze ukończenie kotwiczy kolejne odnowienia do tej godziny następnego dnia (Europe/Warsaw). Wcześniejszy sukces natychmiast daje następcę z zachowaniem tej samej dobowej kotwicy; termin nie resetuje się do kolejnych 6 h. | D11: Odpowiedź użytkownika 23.10.2026; Zadania latarni!G12, Zadania latarni!G18, Decyzje i konflikty!G35
A12: D07 | B12: Zadania: wzór opłacalnej nagrody | C12: Stare zakresy stanowią bazę na poziomie ratusza 3: małe 100–200, średnie do 400, duże do 600 monet oraz 50–1000 każdego rodzaju towaru. Inne poziomy: współczynnik 12 × L × p(L) / 468; całe ilości w dół, minimum 1. Rodzajów nagrody: 1/2/3 dla małego/średniego/dużego. Mnożnik szybkiej reakcji dopiero od tej bazy. | D12: Odpowiedź użytkownika 23.10.2026; Zadania latarni!G25, Zadania latarni!G13, Zadania przyklady
A13: D08 | B13: Zadania: liczba rodzajów nagrody | C13: Nagroda towarowa małego: 1 rodzaj; średniego: 2 różne; dużego: 3 różne. Zakres dotyczy każdego rodzaju. | D13: Odpowiedź użytkownika 23.10.2026; Zadania latarni!E14, Decyzje i konflikty!G36
A14: D09 | B14: Pakiet budowlany: czas działania | C14: Pakiet: 1000 × poziom ratusza monet za 24 h; +4 aktywne budowy, dowolna kolejka, planowanie dostaw. Dopłata kolejki +10% pozostaje; ponowny zakup przedłuża ważność. | D14: Odpowiedź użytkownika 23.10.2026; Premium!G18, Premium!A18:E22
A15: D10 | B15: Planowanie przyszłej budowy: dopłaty i brakujące materiały | C15: W aktywnym pakiecie plan ma koszt kolejki +10% (każdy składnik w górę), plus opłatę 25% bazowej portowej wartości zakupu braków centralnych. Baza 300 kamienia, centrala 200 → wymagane 330, brak 130; bufor producenta nie jest centralą. Materiały muszą rzeczywiście dotrzeć. | D15: Odpowiedź użytkownika 23.10.2026; Budynki!J6, Premium!G22, Ustalenia - uwagi!V2-016
A16: D11 | B16: Kupno budynku: co kończy się natychmiast | C16: Pełny zakup budynku od poziomu gracza 4: wszystkie materiały według proporcjonalnych bazowych cen zakupu portu ×1,25 + nominalne monety budynku + natychmiastowy transport (10 monet za każdy potrzebny kurs, także niepełny). Nic nie pobieramy z własnych materiałów. Gotowe po 10 s; bez wymogu rzeczywistych tragarzy. | D16: Odpowiedź użytkownika 23.10.2026; Premium!G16, Decyzje i konflikty!G24, Premium!C16
... A22: D17 | B22: Kaplica: cena rozbudowy | C22: Zatwierdzono: nowy poziom N × (180 monet + 20 drewna + 60 kamienia + 10 desek). To koszt rozbudowy, odrębny od ceny użycia błogosławieństwa. | D22: Odpowiedź użytkownika 23.10.2026; Decyzje i konflikty!Q14, Budynki!E16

Sheet Budynki
A1: BUDYNKI V8 • aktualne reguły
A2: 12 budynków + asset Człowiek. Aktualne zasady: V7 + Zmiany v8. Kolumna K i komentarze są zachowaną historią użytkownika. Bufory producentów: 200 × własny poziom. Rachunek podatków zachowany, ich informacje usunięte z interfejsu. Czasy porównawcze zależą od parametrów: transport + budowa, bez zbierania i czekania w kolejce.
A5: Budynek / asset | B5: Po co jest | C5: Ludzie | D5: Co daje rozbudowa | E5: Koszt bazowy | F5: Czas łączny | G5: Stan | H5: Notyfikacje | I5: Uwagi i reguły | J5: Premium | K5: Twoje wpisy źródłowe — historia | L5: Źródło zmian | M5: 1→2 transport+budowa | N5: 2→3 transport+budowa | O5: 3→4 transport+budowa
A6: Ratusz | B6: Wyznacza poziom gry i limity rozwoju; skarbiec monet. U góry karty pokazuje aktywne błogosławieństwa, premie i kary. | C6: Brak własnych pracowników. | D6: Maksymalna populacja 24×L, wyższy limit ulepszeń, L budów + L miejsc kolejki. Lokalny magazyn producenta zależy od jego własnego poziomu, nie od ratusza. | E6: 500×L KAŻDEGO z 6 zasobów | F6: 2T = T transportu + T budowy | G6: Uzgodnione w V8; prototyp frontendowy. Szczegóły bieżącego wdrożenia i testów: docs/IMPLEMENTATION-LOG.md. Backend i integracje: Na pozniej. | H6: ZAWSZE: ukończenie budowy. Wcześniej także zlecenie/start/dostawa. Premie/kary: powiadomienie przy aktywacji, zmianie i końcu oraz aktywna lista u góry Town Hall. | I6: Ranking = poziom ratusza × monety. L budów + L miejsc kolejki; zlecenia zakolejkowane mają koszt wyższy o 10%. Ranking: aktualizacja o każdej pełnej godzinie według zastanego stanu ratusza i monet. | J6: Pakiet: 1000 × poziom ratusza monet za 24 h; +4 aktywne budowy, dowolna kolejka, planowanie dostaw. Dopłata kolejki +10% pozostaje; ponowny zakup przedłuża ważność. W aktywnym pakiecie plan ma koszt kolejki +10% (każdy składnik w górę), plus opłatę 25% bazowej portowej wartości zakupu braków centralnych. Baza 300 kamienia, centrala 200 → wymagane 330, brak 130; bufor producenta nie jest centralą. Materiały muszą rzeczywiście dotrzeć. | K6: Budowa: Ratusz na poziomie 1 daje możliwość 1 rozbudowy w tym samym czasie i (o ile mam surowce) jednej zakolejkowanej, ale na tą zakolejkowaną muszę mieć surowce w momencie zlecania. Ratusz na poziomie 2 daje prawo do 2 budów I dwóch obiektów w kolejce pod tym samym warunkiem. Budynki zakolejkowane są o 10 % droższe niż te budowane bez kolejki. Później dopiszemy co oferuje premium (na pewno jedną z opcji będzie skróć czas budowy) | L6: Budynki!wiersz 6; potwierdzenia w Odpowiedzi i zmiany | M6: =TEXT('Czas budowy'!Y6,"0")&" min bazowo; T="&TEXT('Czas budowy'!V6,"0")&" min; budowa="&TEXT('Czas budowy'!X6,"0")&" min. Kolejka +10%: "&TEXT('Czas budowy'!Y7,"0")&" min (bez czekania)." -> 80 min bazowo; T=40 min; budowa=40 min. Kolejka +10%: 90 min (bez czekania). | N6: =TEXT('Czas budowy'!Y8,"0")&" min bazowo; T="&TEXT('Czas budowy'!V8,"0")&" min; budowa="&TEXT('Czas budowy'!X8,"0")&" min. Kolejka +10%: "&TEXT('Czas budowy'!Y9,"0")&" min (bez czekania)." -> 140 min bazowo; T=70 min; budowa=70 min. Kolejka +10%: 150 min (bez czekania). | O6: =TEXT('Czas budowy'!Y10,"0")&" min bazowo; T="&TEXT('Czas budowy'!V10,"0")&" min; budowa="&TEXT('Czas budowy'!X10,"0")&" min. Kolejka +10%: "&TEXT('Czas budowy'!Y11,"0")&" min (bez czekania)." -> 180 min bazowo; T=90 min; budowa=90 min. Kolejka +10%: 200 min (bez czekania).
A7: Dom | B7: Zapewnia miejsca mieszkalne, osobno od maksymalnego limitu ratusza. | C7: Brak własnych pracowników. | D7: Miejsca: 24 × poziom domu; zmniejszenie kary przeludnienia. Panel pokazuje ludzi i przydziały oraz pozwala wysyłać wizyty do kaplicy i latarni. Manage all workers dostępne wyłącznie z domu. Cztery wskaźniki: populacja, limit ratusza, łóżka, przyrost/spadek; opisy pod i. | E7: 500×L KAŻDEGO z 6 zasobów | F7: 2T = T transportu + T budowy | G7: Uzgodnione w V8; prototyp frontendowy. Szczegóły bieżącego wdrożenia i testów: docs/IMPLEMENTATION-LOG.md. Backend i integracje: Na pozniej. | H7: ZAWSZE: ukończenie budowy. Wcześniej także zlecenie/start/dostawa. NOWE: przeludnienie; proponujemy na zmianę stanu, nie co klatkę. Premie/kary: powiadomienie przy aktywacji, zmianie i końcu oraz aktywna lista u góry Town Hall. | I7: Kara przeludnienia: max(0, P − 24 × poziom domu) pp/h każdej osobie. Nowi mieszkańcy zawsze trafiają do domu. Pula domu = liczba mieszkańców przy odnowieniu, w pełnych pp, raz na 24 h. Ręczne punkty dodają H; nie kasują kar ani ich liczników. O 23 h 58 min automat rozdaje wyłącznie resztę, po 1 pp najniższemu H; remis losowy. Pula nie jest wydawana drugi raz. | J7: Premium od L4: 25/50/75/100% pozostałej fazy budowania, bez transportu. Cena = MAX(5, FLOOR(zaoszczędzone sekundy / 60)) monet. Transport jest osobno rozliczany za potrzebne kursy. Pełny zakup budynku od poziomu gracza 4: wszystkie materiały według proporcjonalnych bazowych cen zakupu portu ×1,25 + nominalne monety budynku + natychmiastowy transport (10 monet za każdy potrzebny kurs, także niepełny). Nic nie pobieramy z własnych materiałów. Gotowe po 10 s; bez wymogu rzeczywistych tragarzy. | K7: Z poziomu domu widzę wszystkich ludzi gdzie są dopisani, mogę ich stąd wysyłać do kaplicy lub na latarnię. Mogę podejrzeć szczęście każdego mieszkańca indywidualnie. Dom dostaje 1 x na 24 h doładowanie szczęscia równe 1 pp x aktualna ilość mieszkańców, z poziomu domu mogę to szczęście dać indywidualnej osobie, czylui jeżeli mam 24 osoby podnieść jej szczęscie z 0 do 24 albo dać wszystkim po 1 pp., automat (tem co nada wszystkim) działa po 23h i 58 min i później przychodzi nowa pula. Doładiowanie szczęscia nadpisuje kary za bezrobocie i wszelkie inne. | L7: Budynki!wiersz 7; potwierdzenia w Odpowiedzi i zmiany | M7: =TEXT('Czas budowy'!Y12,"0")&" min bazowo; T="&TEXT('Czas budowy'!V12,"0")&" min; budowa="&TEXT('Czas budowy'!X12,"0")&" min. Kolejka +10%: "&TEXT('Czas budowy'!Y13,"0")&" min (bez czekania)." -> 80 min bazowo; T=40 min; budowa=40 min. Kolejka +10%: 90 min (bez czekania). | N7: =TEXT('Czas budowy'!Y14,"0")&" min bazowo; T="&TEXT('Czas budowy'!V14,"0")&" min; budowa="&TEXT('Czas budowy'!X14,"0")&" min. Kolejka +10%: "&TEXT('Czas budowy'!Y15,"0")&" min (bez czekania)." -> 140 min bazowo; T=70 min; budowa=70 min. Kolejka +10%: 150 min (bez czekania). | O7: =TEXT('Czas budowy'!Y16,"0")&" min bazowo; T="&TEXT('Czas budowy'!V16,"0")&" min; budowa="&TEXT('Czas budowy'!X16,"0")&" min. Kolejka +10%: "&TEXT('Czas budowy'!Y17,"0")&" min (bez czekania)." -> 180 min bazowo; T=90 min; budowa=90 min. Kolejka +10%: 200 min (bez czekania).
A8: Farma | B8: Produkuje zboże do młyna, budowy i wymiany. | C8: Start: 0; limit 12 × WŁASNY poziom budynku, ograniczony liczbą istniejących dostępnych ludzi. Ratusz tylko ogranicza poziom rozbudowy. | D8: Własny poziom daje limit 12 × L pracowników i wydajność na osobę/h: 10, 12, 13, 14…; L1 = 10, L ≥ 2: L + 10. Bufor lokalny: 200 × własny poziom producenta. | E8: L×(72 drewna+72 kamienia+120 zboża) | F8: 2T = T transportu + T budowy | G8: Uzgodnione w V8; prototyp frontendowy. Szczegóły bieżącego wdrożenia i testów: docs/IMPLEMENTATION-LOG.md. Backend i integracje: Na pozniej. | H8: ZAWSZE: ukończenie budowy. Wcześniej także zlecenie/start/dostawa. Powiadomienie o pełnym magazynie. Premie/kary: powiadomienie przy aktywacji, zmianie i końcu oraz aktywna lista u góry Town Hall. | I8: Przestój: podatek płynie, brak +1 pp/h za pracę i brak dodatkowej kary bezrobocia. Kara −10 od początku, kolejne −10 co 24 h, maksymalnie −50 z samego przestoju. Inne kary mogą obniżyć całe H poniżej −50. Reset licznika w drodze do domu. | J8: Premium od L4: 25/50/75/100% pozostałej fazy budowania, bez transportu. Cena = MAX(5, FLOOR(zaoszczędzone sekundy / 60)) monet. Transport jest osobno rozliczany za potrzebne kursy. Pełny zakup budynku od poziomu gracza 4: wszystkie materiały według proporcjonalnych bazowych cen zakupu portu ×1,25 + nominalne monety budynku + natychmiastowy transport (10 monet za każdy potrzebny kurs, także niepełny). Nic nie pobieramy z własnych materiałów. Gotowe po 10 s; bez wymogu rzeczywistych tragarzy. | K8: Do wszystkich produkcyjnych, zwiększenie levelu zwiększa produkcję na 1 h, dla levelu 1 jest to 10 szt / h dla levelu 2 będzie to 12, dla levelu 3 -13 dla 4 - 14 etc W premium dla wszystkich produkcyjnych możłiwość natychmiastowego transportu do magazynu oneclickiem. | L8: Budynki!wiersz 8; potwierdzenia w Odpowiedzi i zmiany | M8: =TEXT('Czas budowy'!Y18,"0")&" min bazowo; T="&TEXT('Czas budowy'!V18,"0")&" min; budowa="&TEXT('Czas budowy'!X18,"0")&" min. Kolejka +10%: "&TEXT('Czas budowy'!Y19,"0")&" min (bez czekania)." -> 10 min bazowo; T=5 min; budowa=5 min. Kolejka +10%: 20 min (bez czekania). | N8: =TEXT('Czas budowy'!Y20,"0")&" min bazowo; T="&TEXT('Czas budowy'!V20,"0")&" min; budowa="&TEXT('Czas budowy'!X20,"0")&" min. Kolejka +10%: "&TEXT('Czas budowy'!Y21,"0")&" min (bez czekania)." -> 20 min bazowo; T=10 min; budowa=10 min. Kolejka +10%: 20 min (bez czekania). | O8: =TEXT('Czas budowy'!Y22,"0")&" min bazowo; T="&TEXT('Czas budowy'!V22,"0")&" min; budowa="&TEXT('Czas budowy'!X22,"0")&" min. Kolejka +10%: "&TEXT('Czas budowy'!Y23,"0")&" min (bez czekania)." -> 20 min bazowo; T=10 min; budowa=10 min. Kolejka +10%: 30 min (bez czekania).
A9: Młyn | B9: Przetwarza 2 zboża z centrali→1 żywność do lokalnego bufora. | C9: Start: 0; limit 12 × WŁASNY poziom budynku, ograniczony liczbą istniejących dostępnych ludzi. Ratusz tylko ogranicza poziom rozbudowy. | D9: Własny poziom daje limit 12 × L pracowników i wydajność na osobę/h: 10, 12, 13, 14…; L1 = 10, L ≥ 2: L + 10. Bufor lokalny: 200 × własny poziom producenta. | E9: 2L×(72 drewna+72 kamienia+120 żywności) | F9: 2T = T transportu + T budowy | G9: Uzgodnione w V8; prototyp frontendowy. Szczegóły bieżącego wdrożenia i testów: docs/IMPLEMENTATION-LOG.md. Backend i integracje: Na pozniej. | H9: ZAWSZE: ukończenie budowy. Wcześniej także zlecenie/start/dostawa. Powiadomienie o pełnym magazynie. Premie/kary: powiadomienie przy aktywacji, zmianie i końcu oraz aktywna lista u góry Town Hall. | I9: Przestój: podatek płynie, brak +1 pp/h za pracę i brak dodatkowej kary bezrobocia. Kara −10 od początku, kolejne −10 co 24 h, maksymalnie −50 z samego przestoju. Inne kary mogą obniżyć całe H poniżej −50. Reset licznika w drodze do domu. | J9: Premium od L4: 25/50/75/100% pozostałej fazy budowania, bez transportu. Cena = MAX(5, FLOOR(zaoszczędzone sekundy / 60)) monet. Transport jest osobno rozliczany za potrzebne kursy. Pełny zakup budynku od poziomu gracza 4: wszystkie materiały według proporcjonalnych bazowych cen zakupu portu ×1,25 + nominalne monety budynku + natychmiastowy transport (10 monet za każdy potrzebny kurs, także niepełny). Nic nie pobieramy z własnych materiałów. Gotowe po 10 s; bez wymogu rzeczywistych tragarzy. | L9: Budynki!wiersz 9; potwierdzenia w Odpowiedzi i zmiany | M9: =TEXT('Czas budowy'!Y24,"0")&" min bazowo; T="&TEXT('Czas budowy'!V24,"0")&" min; budowa="&TEXT('Czas budowy'!X24,"0")&" min. Kolejka +10%: "&TEXT('Czas budowy'!Y25,"0")&" min (bez czekania)." -> 20 min bazowo; T=10 min; budowa=10 min. Kolejka +10%: 20 min (bez czekania). | N9: =TEXT('Czas budowy'!Y26,"0")&" min bazowo; T="&TEXT('Czas budowy'!V26,"0")&" min; budowa="&TEXT('Czas budowy'!X26,"0")&" min. Kolejka +10%: "&TEXT('Czas budowy'!Y27,"0")&" min (bez czekania)." -> 30 min bazowo; T=15 min; budowa=15 min. Kolejka +10%: 30 min (bez czekania). | O9: =TEXT('Czas budowy'!Y28,"0")&" min bazowo; T="&TEXT('Czas budowy'!V28,"0")&" min; budowa="&TEXT('Czas budowy'!X28,"0")&" min. Kolejka +10%: "&TEXT('Czas budowy'!Y29,"0")&" min (bez czekania)." -> 40 min bazowo; T=20 min; budowa=20 min. Kolejka +10%: 50 min (bez czekania).
A10: Drwale | B10: Produkują drewno do tartaku i budowy. | C10: Start: 0; limit 12 × WŁASNY poziom budynku, ograniczony liczbą istniejących dostępnych ludzi. Ratusz tylko ogranicza poziom rozbudowy. | D10: Własny poziom daje limit 12 × L pracowników i wydajność na osobę/h: 10, 12, 13, 14…; L1 = 10, L ≥ 2: L + 10. Bufor lokalny: 200 × własny poziom producenta. | E10: 2L×(192 drewna+72 kamienia) | F10: 2T = T transportu + T budowy | G10: Uzgodnione w V8; prototyp frontendowy. Szczegóły bieżącego wdrożenia i testów: docs/IMPLEMENTATION-LOG.md. Backend i integracje: Na pozniej. | H10: ZAWSZE: ukończenie budowy. Wcześniej także zlecenie/start/dostawa. Powiadomienie o pełnym magazynie. Premie/kary: powiadomienie przy aktywacji, zmianie i końcu oraz aktywna lista u góry Town Hall. | I10: Przestój: podatek płynie, brak +1 pp/h za pracę i brak dodatkowej kary bezrobocia. Kara −10 od początku, kolejne −10 co 24 h, maksymalnie −50 z samego przestoju. Inne kary mogą obniżyć całe H poniżej −50. Reset licznika w drodze do domu. | J10: Premium od L4: 25/50/75/100% pozostałej fazy budowania, bez transportu. Cena = MAX(5, FLOOR(zaoszczędzone sekundy / 60)) monet. Transport jest osobno rozliczany za potrzebne kursy. Pełny zakup budynku od poziomu gracza 4: wszystkie materiały według proporcjonalnych bazowych cen zakupu portu ×1,25 + nominalne monety budynku + natychmiastowy transport (10 monet za każdy potrzebny kurs, także niepełny). Nic nie pobieramy z własnych materiałów. Gotowe po 10 s; bez wymogu rzeczywistych tragarzy. | L10: Budynki!wiersz 10; potwierdzenia w Odpowiedzi i zmiany | M10: =TEXT('Czas budowy'!Y30,"0")&" min bazowo; T="&TEXT('Czas budowy'!V30,"0")&" min; budowa="&TEXT('Czas budowy'!X30,"0")&" min. Kolejka +10%: "&TEXT('Czas budowy'!Y31,"0")&" min (bez czekania)." -> 20 min bazowo; T=10 min; budowa=10 min. Kolejka +10%: 20 min (bez czekania). | N10: =TEXT('Czas budowy'!Y32,"0")&" min bazowo; T="&TEXT('Czas budowy'!V32,"0")&" min; budowa="&TEXT('Czas budowy'!X32,"0")&" min. Kolejka +10%: "&TEXT('Czas budowy'!Y33,"0")&" min (bez czekania)." -> 30 min bazowo; T=15 min; budowa=15 min. Kolejka +10%: 30 min (bez czekania). | O10: =TEXT('Czas budowy'!Y34,"0")&" min bazowo; T="&TEXT('Czas budowy'!V34,"0")&" min; budowa="&TEXT('Czas budowy'!X34,"0")&" min. Kolejka +10%: "&TEXT('Czas budowy'!Y35,"0")&" min (bez czekania)." -> 40 min bazowo; T=20 min; budowa=20 min. Kolejka +10%: 50 min (bez czekania).
A11: Tartak | B11: Przetwarza 2 drewna z centrali→1 deskę do lokalnego bufora. | C11: Start: 0; limit 12 × WŁASNY poziom budynku, ograniczony liczbą istniejących dostępnych ludzi. Ratusz tylko ogranicza poziom rozbudowy. | D11: Własny poziom daje limit 12 × L pracowników i wydajność na osobę/h: 10, 12, 13, 14…; L1 = 10, L ≥ 2: L + 10. Bufor lokalny: 200 × własny poziom producenta. | E11: 2L×(72 drewna+72 kamienia+120 desek) | F11: 2T = T transportu + T budowy | G11: Uzgodnione w V8; prototyp frontendowy. Szczegóły bieżącego wdrożenia i testów: docs/IMPLEMENTATION-LOG.md. Backend i integracje: Na pozniej. | H11: ZAWSZE: ukończenie budowy. Wcześniej także zlecenie/start/dostawa. Powiadomienie o pełnym magazynie. Premie/kary: powiadomienie przy aktywacji, zmianie i końcu oraz aktywna lista u góry Town Hall. | I11: Przestój: podatek płynie, brak +1 pp/h za pracę i brak dodatkowej kary bezrobocia. Kara −10 od początku, kolejne −10 co 24 h, maksymalnie −50 z samego przestoju. Inne kary mogą obniżyć całe H poniżej −50. Reset licznika w drodze do domu. | J11: Premium od L4: 25/50/75/100% pozostałej fazy budowania, bez transportu. Cena = MAX(5, FLOOR(zaoszczędzone sekundy / 60)) monet. Transport jest osobno rozliczany za potrzebne kursy. Pełny zakup budynku od poziomu gracza 4: wszystkie materiały według proporcjonalnych bazowych cen zakupu portu ×1,25 + nominalne monety budynku + natychmiastowy transport (10 monet za każdy potrzebny kurs, także niepełny). Nic nie pobieramy z własnych materiałów. Gotowe po 10 s; bez wymogu rzeczywistych tragarzy. | L11: Budynki!wiersz 11; potwierdzenia w Odpowiedzi i zmiany | M11: =TEXT('Czas budowy'!Y36,"0")&" min bazowo; T="&TEXT('Czas budowy'!V36,"0")&" min; budowa="&TEXT('Czas budowy'!X36,"0")&" min. Kolejka +10%: "&TEXT('Czas budowy'!Y37,"0")&" min (bez czekania)." -> 20 min bazowo; T=10 min; budowa=10 min. Kolejka +10%: 20 min (bez czekania). | N11: =TEXT('Czas budowy'!Y38,"0")&" min bazowo; T="&TEXT('Czas budowy'!V38,"0")&" min; budowa="&TEXT('Czas budowy'!X38,"0")&" min. Kolejka +10%: "&TEXT('Czas budowy'!Y39,"0")&" min (bez czekania)." -> 30 min bazowo; T=15 min; budowa=15 min. Kolejka +10%: 30 min (bez czekania). | O11: =TEXT('Czas budowy'!Y40,"0")&" min bazowo; T="&TEXT('Czas budowy'!V40,"0")&" min; budowa="&TEXT('Czas budowy'!X40,"0")&" min. Kolejka +10%: "&TEXT('Czas budowy'!Y41,"0")&" min (bez czekania)." -> 40 min bazowo; T=20 min; budowa=20 min. Kolejka +10%: 50 min (bez czekania).
