Workbook

Sheet Start
A1: HARBORLIGHT V5 • plik4 + pomysły + potwierdzenia
A2: Wersja 5 łączy 37 nowych wpisów z pliku 4 z pełną wersją 3, tekstem pomysłów i trzema potwierdzeniami. Oryginał 4 zachowano; wpisy są w Twoje wpisy v4. Doprecyzowania na później wyraźnie oznaczono. Tylko Excel, bez zmian kodu gry.
A5: Obszar | B5: Co zmieniono | C5: Gdzie sprawdzić
A6: Główna tabela | B6: 12 budynków + asset Człowiek; nowe koszty, limity własnego poziomu, efekty rozbudowy i czasy. | C6: Budynki
A7: Czasy | B7: 5 min — pełny kurs, jeden rodzaj towaru, ładunki 60/66/72; Ratusz/Dom 2 T, Latarnia 5 T, Kaplica 4 T/7 T/10 T. | C7: Czas budowy: 74 warianty (37 etapów × bazowy/kolejka).
A8: Kolejka | B8: Pełny koszt przy zleceniu +10%; dopłata materiałowa zmienia liczbę kursów i czas. | C8: Normalnie L budów + L miejsc kolejki. Czekanie w kolejce jest wyłączone z estymat.
A9: Zatrudnienie | B9: Własny limit 12 × poziom; produkcja 10, 12, 13, 14…; 5 min do pracy. Podatek od dotarcia i także podczas przestoju. | C9: Czlowiek / Produkcja
A10: Offline | B10: Cała gospodarka działa również offline: podatki, jedzenie, szczęście, populacja, produkcja, transport i budowa. | C10: Transport i priorytety; Czlowiek
A11: Koszty | B11: Magazyn/Targ: 300 L każdego zasobu; Port: 400 L; Ratusz/Dom: 500 L; Latarnia: 500 × max(1, L). | C11: Parametry / Czas budowy
A12: Transport | B12: Rezerwa i ratunkowy próg Food: 50 × poziom magazynu. Ochrona ostatniego transportera przy brakach żywności; ETA aktualizuje się po zmianie priorytetów. | C12: Transport i priorytety / Czlowiek. Ratunkowy próg Food oraz rezerwa 50 × poziom magazynu są potwierdzone w V5.
A13: Ceny | B13: Port: podstawowe 40/50, produkty 140/150 za 100; podwyżki zakupowe +10% liniowo. Ostatnia korekta dotyczy PORTU, nie TARGU. | C13: Przystan; Targ: bez monet, marża 10%.
A14: Terminy | B14: Towar w porcie/targu nieodebrany przez 24 h przepada; portowa opłata 10 monet została zniesiona. | C14: Terminy zegarowe, również offline.
A15: Premie i wizyty | B15: Płatne błogosławieństwo kaplicy: 100 × poziom kaplicy monet, maksymalnie 1 użycie na 4 h. Zwiedzanie latarni: pobyt 4 h dla maks. 2 × poziom latarni osób z domu; szczęście uczestników 100% przez 24 h i premia dla populacji. | C15: Czlowiek / Blogoslawienstwa; brakujące jednostki i kumulacje opisane jawnie.
A16: Premium | B16: 1 PLN = 10 monet; skrócenie budowy o 25/50/75% za 1 monetę za pełną minutę; transport: 10 monet/kurs; materiały według cen portu ×1,25 plus opłata czasowa. | C16: Premium / trzy kalkulatory Premium.
... A26: Wymaganie interfejsu | B26: Usunąć ikony stop/play/przewijania w prawym górnym rogu. | C26: Zapis projektu; kod gry bez zmian.

Sheet Budynki
A1: BUDYNKI V5 • nowe wpisy i komplet pomysłów
A2: Nowy plik 2; poprzednie pliki 0 i 1 pozostają. Czasy bazowe przy 6 DOSTĘPNYCH tragarzach, ładunki 60/66/72, pełny kurs 5 min. Bez zbierania, karmienia, oczekiwania w kolejce i wcześniejszych rozbudów. Kolejka ma osobne koszty i czasy z +10% w arkuszu Czas budowy. Wszystko działa offline.
A5: Budynek / asset | B5: Po co jest | C5: Ludzie | D5: Co daje rozbudowa | E5: Koszt bazowy | F5: Czas łączny | G5: Stan | H5: Notyfikacje | I5: Uwagi i reguły | J5: Premium | K5: Twoje uwagi3 / doprecyzowania | L5: Źródło zmian | M5: 1→2 transport+budowa | N5: 2→3 transport+budowa | O5: 3→4 transport+budowa
A6: Ratusz | B6: Wyznacza poziom gry i limity rozwoju; jest skarbcem monet i pokazuje podatek/h. | C6: Brak własnych pracowników. | D6: Maksymalna populacja: 24 × L; wyższy poziom innych budynków; L budów + L miejsc kolejki; lokalne bufory producentów: 200 × Ratusz. | E6: 500×L KAŻDEGO z 6 zasobów | F6: 2T = T transportu + T budowy | G6: Zasady uporządkowane; otwarte szczegóły w arkuszu Decyzje i konflikty. | H6: ZAWSZE: ukończenie budowy. Wcześniej także zlecenie/start/dostawa. | I6: Ranking = poziom ratusza × monety. L budów + L miejsc kolejki; zlecenia zakolejkowane mają koszt wyższy o 10%. Ranking: aktualizacja o każdej pełnej godzinie według zastanego stanu ratusza i monet. | J6: Patrz Premium — aktualny cennik oraz kalkulatory kosztów i czasu. Przy transporcie płatny jest także ostatni niepełny kurs. | K6: Budowa: Ratusz na poziomie 1 daje możliwość 1 rozbudowy w tym samym czasie i (o ile mam surowce) jednej zakolejkowanej, ale na tą zakolejkowaną muszę mieć surowce w momencie zlecania. Ratusz na poziomie 2 daje prawo do 2 budów I dwóch obiektów w kolejce pod tym samym warunkiem. Budynki zakolejkowane są o 10 % droższe niż te budowane bez kolejki. Później dopiszemy co oferuje premium (na pewno jedną z opcji będzie skróć czas budowy) | L6: Budynki!wiersz 6; potwierdzenia w Odpowiedzi i zmiany | M6: =TEXT('Czas budowy'!Y6,"0")&" min bazowo; T="&TEXT('Czas budowy'!V6,"0")&" min; budowa="&TEXT('Czas budowy'!X6,"0")&" min. Kolejka +10%: "&TEXT('Czas budowy'!Y7,"0")&" min (bez czekania)." -> 80 min bazowo; T=40 min; budowa=40 min. Kolejka +10%: 90 min (bez czekania). | N6: =TEXT('Czas budowy'!Y8,"0")&" min bazowo; T="&TEXT('Czas budowy'!V8,"0")&" min; budowa="&TEXT('Czas budowy'!X8,"0")&" min. Kolejka +10%: "&TEXT('Czas budowy'!Y9,"0")&" min (bez czekania)." -> 140 min bazowo; T=70 min; budowa=70 min. Kolejka +10%: 150 min (bez czekania). | O6: =TEXT('Czas budowy'!Y10,"0")&" min bazowo; T="&TEXT('Czas budowy'!V10,"0")&" min; budowa="&TEXT('Czas budowy'!X10,"0")&" min. Kolejka +10%: "&TEXT('Czas budowy'!Y11,"0")&" min (bez czekania)." -> 180 min bazowo; T=90 min; budowa=90 min. Kolejka +10%: 200 min (bez czekania).
A7: Dom | B7: Zapewnia miejsca mieszkalne, osobno od maksymalnego limitu ratusza. | C7: Brak własnych pracowników. | D7: Miejsca: 24 × poziom domu; zmniejszenie kary przeludnienia. Panel pokazuje ludzi i przydziały oraz pozwala wysyłać wizyty do kaplicy i latarni. | E7: 500×L KAŻDEGO z 6 zasobów | F7: 2T = T transportu + T budowy | G7: Zasady uporządkowane; otwarte szczegóły w arkuszu Decyzje i konflikty. | H7: ZAWSZE: ukończenie budowy. Wcześniej także zlecenie/start/dostawa. NOWE: przeludnienie; proponujemy na zmianę stanu, nie co klatkę. | I7: Kara przeludnienia: max(0, P − 24 × poziom domu) pp/h każdej osobie. Nowi mieszkańcy zawsze trafiają do domu. | J7: Patrz Premium — aktualny cennik oraz kalkulatory kosztów i czasu. Przy transporcie płatny jest także ostatni niepełny kurs. | K7: Z poziomu domu widzę wszystkich ludzi gdzie są dopisani, mogę ich stąd wysyłać do kaplicy lub na latarnię | L7: Budynki!wiersz 7; potwierdzenia w Odpowiedzi i zmiany | M7: =TEXT('Czas budowy'!Y12,"0")&" min bazowo; T="&TEXT('Czas budowy'!V12,"0")&" min; budowa="&TEXT('Czas budowy'!X12,"0")&" min. Kolejka +10%: "&TEXT('Czas budowy'!Y13,"0")&" min (bez czekania)." -> 80 min bazowo; T=40 min; budowa=40 min. Kolejka +10%: 90 min (bez czekania). | N7: =TEXT('Czas budowy'!Y14,"0")&" min bazowo; T="&TEXT('Czas budowy'!V14,"0")&" min; budowa="&TEXT('Czas budowy'!X14,"0")&" min. Kolejka +10%: "&TEXT('Czas budowy'!Y15,"0")&" min (bez czekania)." -> 140 min bazowo; T=70 min; budowa=70 min. Kolejka +10%: 150 min (bez czekania). | O7: =TEXT('Czas budowy'!Y16,"0")&" min bazowo; T="&TEXT('Czas budowy'!V16,"0")&" min; budowa="&TEXT('Czas budowy'!X16,"0")&" min. Kolejka +10%: "&TEXT('Czas budowy'!Y17,"0")&" min (bez czekania)." -> 180 min bazowo; T=90 min; budowa=90 min. Kolejka +10%: 200 min (bez czekania).
A8: Farma | B8: Produkuje zboże do młyna, budowy i wymiany. | C8: Start: 0; limit 12 × WŁASNY poziom budynku, ograniczony liczbą istniejących dostępnych ludzi. Ratusz tylko ogranicza poziom rozbudowy. | D8: Własny poziom daje limit 12 × L pracowników i wydajność na osobę/h: 10, 12, 13, 14…; L1 = 10, L ≥ 2: L + 10. Bufor lokalny: 200 × Ratusz. | E8: L×(72 drewna+72 kamienia+120 zboża) | F8: 2T = T transportu + T budowy | G8: Zasady uporządkowane; otwarte szczegóły w arkuszu Decyzje i konflikty. | H8: ZAWSZE: ukończenie budowy. Wcześniej także zlecenie/start/dostawa. Powiadomienie o pełnym magazynie. | I8: Przestój z braku wejścia lub miejsca: podatek nadal płynie; jedna kara przestoju −10, następnie −10 co 24 h, maksymalnie −50 z tego tytułu. Dotyczy przypisanych osób i faktycznej blokady. Powrót do domu resetuje licznik przestoju. Bonus +1 pracy podczas postoju pozostaje do doprecyzowania. | J8: Patrz Premium — aktualny cennik oraz kalkulatory kosztów i czasu. Przy transporcie płatny jest także ostatni niepełny kurs. | K8: Do wszystkich produkcyjnych, zwiększenie levelu zwiększa produkcję na 1 h, dla levelu 1 jest to 10 szt / h dla levelu 2 będzie to 12, dla levelu 3 -13 dla 4 - 14 etc W premium dla wszystkich produkcyjnych możłiwość natychmiastowego transportu do magazynu oneclickiem. | L8: Budynki!wiersz 8; potwierdzenia w Odpowiedzi i zmiany | M8: =TEXT('Czas budowy'!Y18,"0")&" min bazowo; T="&TEXT('Czas budowy'!V18,"0")&" min; budowa="&TEXT('Czas budowy'!X18,"0")&" min. Kolejka +10%: "&TEXT('Czas budowy'!Y19,"0")&" min (bez czekania)." -> 10 min bazowo; T=5 min; budowa=5 min. Kolejka +10%: 20 min (bez czekania). | N8: =TEXT('Czas budowy'!Y20,"0")&" min bazowo; T="&TEXT('Czas budowy'!V20,"0")&" min; budowa="&TEXT('Czas budowy'!X20,"0")&" min. Kolejka +10%: "&TEXT('Czas budowy'!Y21,"0")&" min (bez czekania)." -> 20 min bazowo; T=10 min; budowa=10 min. Kolejka +10%: 20 min (bez czekania). | O8: =TEXT('Czas budowy'!Y22,"0")&" min bazowo; T="&TEXT('Czas budowy'!V22,"0")&" min; budowa="&TEXT('Czas budowy'!X22,"0")&" min. Kolejka +10%: "&TEXT('Czas budowy'!Y23,"0")&" min (bez czekania)." -> 20 min bazowo; T=10 min; budowa=10 min. Kolejka +10%: 30 min (bez czekania).
A9: Młyn | B9: Przetwarza 2 zboża z centrali→1 żywność do lokalnego bufora. | C9: Start: 0; limit 12 × WŁASNY poziom budynku, ograniczony liczbą istniejących dostępnych ludzi. Ratusz tylko ogranicza poziom rozbudowy. | D9: Własny poziom daje limit 12 × L pracowników i wydajność na osobę/h: 10, 12, 13, 14…; L1 = 10, L ≥ 2: L + 10. Bufor lokalny: 200 × Ratusz. | E9: 2L×(72 drewna+72 kamienia+120 żywności) | F9: 2T = T transportu + T budowy | G9: Zasady uporządkowane; otwarte szczegóły w arkuszu Decyzje i konflikty. | H9: ZAWSZE: ukończenie budowy. Wcześniej także zlecenie/start/dostawa. Powiadomienie o pełnym magazynie. | I9: Przestój z braku wejścia lub miejsca: podatek nadal płynie; jedna kara przestoju −10, następnie −10 co 24 h, maksymalnie −50 z tego tytułu. Dotyczy przypisanych osób i faktycznej blokady. Powrót do domu resetuje licznik przestoju. Bonus +1 pracy podczas postoju pozostaje do doprecyzowania. | J9: Patrz Premium — aktualny cennik oraz kalkulatory kosztów i czasu. Przy transporcie płatny jest także ostatni niepełny kurs. | L9: Budynki!wiersz 9; potwierdzenia w Odpowiedzi i zmiany | M9: =TEXT('Czas budowy'!Y24,"0")&" min bazowo; T="&TEXT('Czas budowy'!V24,"0")&" min; budowa="&TEXT('Czas budowy'!X24,"0")&" min. Kolejka +10%: "&TEXT('Czas budowy'!Y25,"0")&" min (bez czekania)." -> 20 min bazowo; T=10 min; budowa=10 min. Kolejka +10%: 20 min (bez czekania). | N9: =TEXT('Czas budowy'!Y26,"0")&" min bazowo; T="&TEXT('Czas budowy'!V26,"0")&" min; budowa="&TEXT('Czas budowy'!X26,"0")&" min. Kolejka +10%: "&TEXT('Czas budowy'!Y27,"0")&" min (bez czekania)." -> 30 min bazowo; T=15 min; budowa=15 min. Kolejka +10%: 30 min (bez czekania). | O9: =TEXT('Czas budowy'!Y28,"0")&" min bazowo; T="&TEXT('Czas budowy'!V28,"0")&" min; budowa="&TEXT('Czas budowy'!X28,"0")&" min. Kolejka +10%: "&TEXT('Czas budowy'!Y29,"0")&" min (bez czekania)." -> 40 min bazowo; T=20 min; budowa=20 min. Kolejka +10%: 50 min (bez czekania).
A10: Drwale | B10: Produkują drewno do tartaku i budowy. | C10: Start: 0; limit 12 × WŁASNY poziom budynku, ograniczony liczbą istniejących dostępnych ludzi. Ratusz tylko ogranicza poziom rozbudowy. | D10: Własny poziom daje limit 12 × L pracowników i wydajność na osobę/h: 10, 12, 13, 14…; L1 = 10, L ≥ 2: L + 10. Bufor lokalny: 200 × Ratusz. | E10: 2L×(192 drewna+72 kamienia) | F10: 2T = T transportu + T budowy | G10: Zasady uporządkowane; otwarte szczegóły w arkuszu Decyzje i konflikty. | H10: ZAWSZE: ukończenie budowy. Wcześniej także zlecenie/start/dostawa. Powiadomienie o pełnym magazynie. | I10: Przestój z braku wejścia lub miejsca: podatek nadal płynie; jedna kara przestoju −10, następnie −10 co 24 h, maksymalnie −50 z tego tytułu. Dotyczy przypisanych osób i faktycznej blokady. Powrót do domu resetuje licznik przestoju. Bonus +1 pracy podczas postoju pozostaje do doprecyzowania. | J10: Patrz Premium — aktualny cennik oraz kalkulatory kosztów i czasu. Przy transporcie płatny jest także ostatni niepełny kurs. | L10: Budynki!wiersz 10; potwierdzenia w Odpowiedzi i zmiany | M10: =TEXT('Czas budowy'!Y30,"0")&" min bazowo; T="&TEXT('Czas budowy'!V30,"0")&" min; budowa="&TEXT('Czas budowy'!X30,"0")&" min. Kolejka +10%: "&TEXT('Czas budowy'!Y31,"0")&" min (bez czekania)." -> 20 min bazowo; T=10 min; budowa=10 min. Kolejka +10%: 20 min (bez czekania). | N10: =TEXT('Czas budowy'!Y32,"0")&" min bazowo; T="&TEXT('Czas budowy'!V32,"0")&" min; budowa="&TEXT('Czas budowy'!X32,"0")&" min. Kolejka +10%: "&TEXT('Czas budowy'!Y33,"0")&" min (bez czekania)." -> 30 min bazowo; T=15 min; budowa=15 min. Kolejka +10%: 30 min (bez czekania). | O10: =TEXT('Czas budowy'!Y34,"0")&" min bazowo; T="&TEXT('Czas budowy'!V34,"0")&" min; budowa="&TEXT('Czas budowy'!X34,"0")&" min. Kolejka +10%: "&TEXT('Czas budowy'!Y35,"0")&" min (bez czekania)." -> 40 min bazowo; T=20 min; budowa=20 min. Kolejka +10%: 50 min (bez czekania).
A11: Tartak | B11: Przetwarza 2 drewna z centrali→1 deskę do lokalnego bufora. | C11: Start: 0; limit 12 × WŁASNY poziom budynku, ograniczony liczbą istniejących dostępnych ludzi. Ratusz tylko ogranicza poziom rozbudowy. | D11: Własny poziom daje limit 12 × L pracowników i wydajność na osobę/h: 10, 12, 13, 14…; L1 = 10, L ≥ 2: L + 10. Bufor lokalny: 200 × Ratusz. | E11: 2L×(72 drewna+72 kamienia+120 desek) | F11: 2T = T transportu + T budowy | G11: Zasady uporządkowane; otwarte szczegóły w arkuszu Decyzje i konflikty. | H11: ZAWSZE: ukończenie budowy. Wcześniej także zlecenie/start/dostawa. Powiadomienie o pełnym magazynie. | I11: Przestój z braku wejścia lub miejsca: podatek nadal płynie; jedna kara przestoju −10, następnie −10 co 24 h, maksymalnie −50 z tego tytułu. Dotyczy przypisanych osób i faktycznej blokady. Powrót do domu resetuje licznik przestoju. Bonus +1 pracy podczas postoju pozostaje do doprecyzowania. | J11: Patrz Premium — aktualny cennik oraz kalkulatory kosztów i czasu. Przy transporcie płatny jest także ostatni niepełny kurs. | L11: Budynki!wiersz 11; potwierdzenia w Odpowiedzi i zmiany | M11: =TEXT('Czas budowy'!Y36,"0")&" min bazowo; T="&TEXT('Czas budowy'!V36,"0")&" min; budowa="&TEXT('Czas budowy'!X36,"0")&" min. Kolejka +10%: "&TEXT('Czas budowy'!Y37,"0")&" min (bez czekania)." -> 20 min bazowo; T=10 min; budowa=10 min. Kolejka +10%: 20 min (bez czekania). | N11: =TEXT('Czas budowy'!Y38,"0")&" min bazowo; T="&TEXT('Czas budowy'!V38,"0")&" min; budowa="&TEXT('Czas budowy'!X38,"0")&" min. Kolejka +10%: "&TEXT('Czas budowy'!Y39,"0")&" min (bez czekania)." -> 30 min bazowo; T=15 min; budowa=15 min. Kolejka +10%: 30 min (bez czekania). | O11: =TEXT('Czas budowy'!Y40,"0")&" min bazowo; T="&TEXT('Czas budowy'!V40,"0")&" min; budowa="&TEXT('Czas budowy'!X40,"0")&" min. Kolejka +10%: "&TEXT('Czas budowy'!Y41,"0")&" min (bez czekania)." -> 40 min bazowo; T=20 min; budowa=20 min. Kolejka +10%: 50 min (bez czekania).
A12: Kamieniołom | B12: Produkuje kamień do budowy i wymiany. | C12: Start: 0; limit 12 × WŁASNY poziom budynku, ograniczony liczbą istniejących dostępnych ludzi. Ratusz tylko ogranicza poziom rozbudowy. | D12: Własny poziom daje limit 12 × L pracowników i wydajność na osobę/h: 10, 12, 13, 14…; L1 = 10, L ≥ 2: L + 10. Bufor lokalny: 200 × Ratusz. | E12: 2L×(72 drewna+192 kamienia) | F12: 2T = T transportu + T budowy | G12: Zasady uporządkowane; otwarte szczegóły w arkuszu Decyzje i konflikty. | H12: ZAWSZE: ukończenie budowy. Wcześniej także zlecenie/start/dostawa. Powiadomienie o pełnym magazynie. | I12: Przestój z braku wejścia lub miejsca: podatek nadal płynie; jedna kara przestoju −10, następnie −10 co 24 h, maksymalnie −50 z tego tytułu. Dotyczy przypisanych osób i faktycznej blokady. Powrót do domu resetuje licznik przestoju. Bonus +1 pracy podczas postoju pozostaje do doprecyzowania. | J12: Patrz Premium — aktualny cennik oraz kalkulatory kosztów i czasu. Przy transporcie płatny jest także ostatni niepełny kurs. | L12: Budynki!wiersz 12; potwierdzenia w Odpowiedzi i zmiany | M12: =TEXT('Czas budowy'!Y42,"0")&" min bazowo; T="&TEXT('Czas budowy'!V42,"0")&" min; budowa="&TEXT('Czas budowy'!X42,"0")&" min. Kolejka +10%: "&TEXT('Czas budowy'!Y43,"0")&" min (bez czekania)." -> 20 min bazowo; T=10 min; budowa=10 min. Kolejka +10%: 20 min (bez czekania). | N12: =TEXT('Czas budowy'!Y44,"0")&" min bazowo; T="&TEXT('Czas budowy'!V44,"0")&" min; budowa="&TEXT('Czas budowy'!X44,"0")&" min. Kolejka +10%: "&TEXT('Czas budowy'!Y45,"0")&" min (bez czekania)." -> 30 min bazowo; T=15 min; budowa=15 min. Kolejka +10%: 30 min (bez czekania). | O12: =TEXT('Czas budowy'!Y46,"0")&" min bazowo; T="&TEXT('Czas budowy'!V46,"0")&" min; budowa="&TEXT('Czas budowy'!X46,"0")&" min. Kolejka +10%: "&TEXT('Czas budowy'!Y47,"0")&" min (bez czekania)." -> 40 min bazowo; T=20 min; budowa=20 min. Kolejka +10%: 50 min (bez czekania).
A13: Magazyn | B13: Przechowuje materiały; własna załoga nosi produkcję do centrali i materiały na budowy. Ludzie jedzą z centrali automatycznie. | C13: Start: 0; limit 12 × WŁASNY poziom budynku, ograniczony liczbą istniejących dostępnych ludzi. Ratusz tylko ogranicza poziom rozbudowy. | D13: Limit załogi: 12 × własny L; ładunek na kurs +10%/poziom. Pojemność ×1.5/poziom; magazyn/port: 1000 na rodzaj i 4000 łącznie na poziomie 1; targ: 1000 łącznie na poziomie 1. | E13: 300 × L każdego z 6 zasobów; w kolejce ×1,1. | F13: 2T = T transportu + T budowy | G13: Zasady uporządkowane; otwarte szczegóły w arkuszu Decyzje i konflikty. | H13: ZAWSZE: ukończenie budowy. Wcześniej także zlecenie/start/dostawa. Powiadomienie o pełnym magazynie. | I13: Rezerwa i próg ratunkowego Food: 50 × poziom magazynu. Gdy Food jest poniżej minimum, a czeka w młynie, nie można ręcznie wycofać całej obsady transportu. ETA budowy przeliczamy po zmianie priorytetów. | J13: Patrz Premium — aktualny cennik oraz kalkulatory kosztów i czasu. Przy transporcie płatny jest także ostatni niepełny kurs. | K13: Transport. Nie rozróżniamy odległości, transport produków zawsze trwa 5 min z/do magazynu x capacity tragarza czyli jeżeli tragarz bierze 60 a potrzebuje przenieść 100 to I tak musi wykonać 2 kursy w jednym bierze 60 w drugim 40, tragarz nie może brać 2 produktow na raz, nie może czekać na towar. Jak klikam rozbudowa np drwala podświetla sie napis ile potrzeba surowców a ile zostało już dostarczonych np 60 /100 i estymowany czas zakońćzenia budowy czyli suma czasu transportu przy aktualnych ustawieniach priorytetów, i budowy. Z poziomu magazynu domyślne prirytety jest najpierw zaopatrz magazyn pózniej budowy, można je zmieniać, dodatkowo też można zmienić ustalić prio na konkretne gospodarstwo bądz konretną budowę, 1 tragarz zawsze będzie nosił żywność o ile jest wyprodukowana a w magazynie jest mniej niż 50 Premium szybszy transport do puntu odbioru | L13: Budynki!wiersz 13; potwierdzenia w Odpowiedzi i zmiany | M13: =TEXT('Czas budowy'!Y48,"0")&" min bazowo; T="&TEXT('Czas budowy'!V48,"0")&" min; budowa="&TEXT('Czas budowy'!X48,"0")&" min. Kolejka +10%: "&TEXT('Czas budowy'!Y49,"0")&" min (bez czekania)." -> 50 min bazowo; T=25 min; budowa=25 min. Kolejka +10%: 50 min (bez czekania). | N13: =TEXT('Czas budowy'!Y50,"0")&" min bazowo; T="&TEXT('Czas budowy'!V50,"0")&" min; budowa="&TEXT('Czas budowy'!X50,"0")&" min. Kolejka +10%: "&TEXT('Czas budowy'!Y51,"0")&" min (bez czekania)." -> 90 min bazowo; T=45 min; budowa=45 min. Kolejka +10%: 90 min (bez czekania). | O13: =TEXT('Czas budowy'!Y52,"0")&" min bazowo; T="&TEXT('Czas budowy'!V52,"0")&" min; budowa="&TEXT('Czas budowy'!X52,"0")&" min. Kolejka +10%: "&TEXT('Czas budowy'!Y53,"0")&" min (bez czekania)." -> 110 min bazowo; T=55 min; budowa=55 min. Kolejka +10%: 120 min (bez czekania).
A14: Targ | B14: Od poziomu gracza 2: wymiana w grupach drewno/kamień/zboże lub deski/żywność, nominalnie 1:1 z marżą 10%. Bez kupowania za monety. | C14: Start: 0; limit 12 × WŁASNY poziom budynku, ograniczony liczbą istniejących dostępnych ludzi. Ratusz tylko ogranicza poziom rozbudowy. | D14: Limit załogi: 12 × własny L; ładunek na kurs +10%/poziom. Pojemność ×1.5/poziom; magazyn/port: 1000 na rodzaj i 4000 łącznie na poziomie 1; targ: 1000 łącznie na poziomie 1. | E14: 300 × L każdego z 6 zasobów; w kolejce ×1,1. | F14: 2T = T transportu + T budowy | G14: Zasady uporządkowane; otwarte szczegóły w arkuszu Decyzje i konflikty. | H14: ZAWSZE: ukończenie budowy. Wcześniej także zlecenie/start/dostawa. Powiadomienie o pełnym magazynie. | I14: Własna załoga w obu kierunkach. Barter w 2 grupach, marża 10%, bez monet. Pozostaje blokada dostaw 1 h; zapas przepada po 24 h od przyniesienia/wymiany. | J14: Patrz Premium — aktualny cennik oraz kalkulatory kosztów i czasu. Przy transporcie płatny jest także ostatni niepełny kurs. | K14: Premium transport oneclick Ceny grupa 2 140/150 | L14: Budynki!wiersz 14; potwierdzenia w Odpowiedzi i zmiany | M14: =TEXT('Czas budowy'!Y54,"0")&" min bazowo; T="&TEXT('Czas budowy'!V54,"0")&" min; budowa="&TEXT('Czas budowy'!X54,"0")&" min. Kolejka +10%: "&TEXT('Czas budowy'!Y55,"0")&" min (bez czekania)." -> 50 min bazowo; T=25 min; budowa=25 min. Kolejka +10%: 50 min (bez czekania). | N14: =TEXT('Czas budowy'!Y56,"0")&" min bazowo; T="&TEXT('Czas budowy'!V56,"0")&" min; budowa="&TEXT('Czas budowy'!X56,"0")&" min. Kolejka +10%: "&TEXT('Czas budowy'!Y57,"0")&" min (bez czekania)." -> 90 min bazowo; T=45 min; budowa=45 min. Kolejka +10%: 90 min (bez czekania). | O14: =TEXT('Czas budowy'!Y58,"0")&" min bazowo; T="&TEXT('Czas budowy'!V58,"0")&" min; budowa="&TEXT('Czas budowy'!X58,"0")&" min. Kolejka +10%: "&TEXT('Czas budowy'!Y59,"0")&" min (bez czekania)." -> 110 min bazowo; T=55 min; budowa=55 min. Kolejka +10%: 120 min (bez czekania).
A15: Przystań | B15: Od poziomu gracza 4: kupno i sprzedaż pięciu materiałów za monety. Wyłącznie pełne paczki 100. Monety są środkiem płatności, nie osobnym towarem. | C15: Start: 0; limit 12 × WŁASNY poziom budynku, ograniczony liczbą istniejących dostępnych ludzi. Ratusz tylko ogranicza poziom rozbudowy. | D15: Limit załogi: 12 × własny L; ładunek na kurs +10%/poziom. Pojemność ×1.5/poziom; magazyn/port: 1000 na rodzaj i 4000 łącznie na poziomie 1; targ: 1000 łącznie na poziomie 1. | E15: 400 × L każdego z 6 zasobów; w kolejce ×1,1. | F15: 2T = T transportu + T budowy | G15: Zasady uporządkowane; otwarte szczegóły w arkuszu Decyzje i konflikty. | H15: ZAWSZE: ukończenie budowy. Wcześniej także zlecenie/start/dostawa. Powiadomienie o pełnym magazynie. | I15: Rejs zawsze 5 min. Zakup: monety pobierane w momencie transakcji; dokładny punkt zatwierdzenia opisano jako szczegół. Własna załoga, towary przez centralę; pełne paczki po 100 dla zwykłego handlu, ceny podstawowe 40/50, przetworzone 140/150. Towar nieodebrany przez 24 h przepada. | J15: Patrz Premium — aktualny cennik oraz kalkulatory kosztów i czasu. Przy transporcie płatny jest także ostatni niepełny kurs. | K15: Tempo załogi jak w magazynie, premium jak w magazynie | L15: Budynki!wiersz 15; potwierdzenia w Odpowiedzi i zmiany | M15: =TEXT('Czas budowy'!Y60,"0")&" min bazowo; T="&TEXT('Czas budowy'!V60,"0")&" min; budowa="&TEXT('Czas budowy'!X60,"0")&" min. Kolejka +10%: "&TEXT('Czas budowy'!Y61,"0")&" min (bez czekania)." -> 60 min bazowo; T=30 min; budowa=30 min. Kolejka +10%: 70 min (bez czekania). | N15: =TEXT('Czas budowy'!Y62,"0")&" min bazowo; T="&TEXT('Czas budowy'!V62,"0")&" min; budowa="&TEXT('Czas budowy'!X62,"0")&" min. Kolejka +10%: "&TEXT('Czas budowy'!Y63,"0")&" min (bez czekania)." -> 110 min bazowo; T=55 min; budowa=55 min. Kolejka +10%: 120 min (bez czekania). | O15: =TEXT('Czas budowy'!Y64,"0")&" min bazowo; T="&TEXT('Czas budowy'!V64,"0")&" min; budowa="&TEXT('Czas budowy'!X64,"0")&" min. Kolejka +10%: "&TEXT('Czas budowy'!Y65,"0")&" min (bez czekania)." -> 150 min bazowo; T=75 min; budowa=75 min. Kolejka +10%: 160 min (bez czekania).
A16: Kaplica | B16: Daje premie szczęścia i podatków po rozbudowie; dotychczas była miejscem ręcznych błogosławieństw. | C16: Brak etatów; wizyty nie są zatrudnieniem. | D16: +1 użycie dotychczasowego błogosławieństwa; rozbudowa do N: +10 × N szczęścia, podatki ×2 na 10 h. Kaplica = błogosławieństwo. | E16: TYMCZASOWO:N×(180 monet+20 drewna+60 kamienia+10 desek). N=nowy poziom. | F16: T transportu + 3T × (N − 1) budowy; N = nowy poziom. Łącznie: 4T, 7T, 10T… | G16: Zasady uporządkowane; otwarte szczegóły w arkuszu Decyzje i konflikty. | H16: ZAWSZE: ukończenie budowy. Wcześniej także zlecenie/start/dostawa. Uruchomienie premii i ręczne błogosławieństwo. | I16: Płatne błogosławieństwo: 100 × poziom kaplicy monet, maksymalnie jedno na 4 h. Efekt jak dotychczas: +50 każdego zasobu, +20 szczęścia wszystkim na 1 h. Zakaz nakładania aktywnych błogosławieństw pozostaje; cena dotyczy użycia, nie rozbudowy. | J16: Patrz Premium — aktualny cennik oraz kalkulatory kosztów i czasu. Przy transporcie płatny jest także ostatni niepełny kurs. | L16: Budynki!wiersz 16; potwierdzenia w Odpowiedzi i zmiany | M16: =TEXT('Czas budowy'!Y66,"0")&" min bazowo; T="&TEXT('Czas budowy'!V66,"0")&" min; budowa="&TEXT('Czas budowy'!X66,"0")&" min. Kolejka +10%: "&TEXT('Czas budowy'!Y67,"0")&" min (bez czekania)." -> 20 min bazowo; T=5 min; budowa=15 min. Kolejka +10%: 20 min (bez czekania). | N16: =TEXT('Czas budowy'!Y68,"0")&" min bazowo; T="&TEXT('Czas budowy'!V68,"0")&" min; budowa="&TEXT('Czas budowy'!X68,"0")&" min. Kolejka +10%: "&TEXT('Czas budowy'!Y69,"0")&" min (bez czekania)." -> 35 min bazowo; T=5 min; budowa=30 min. Kolejka +10%: 35 min (bez czekania). | O16: =TEXT('Czas budowy'!Y70,"0")&" min bazowo; T="&TEXT('Czas budowy'!V70,"0")&" min; budowa="&TEXT('Czas budowy'!X70,"0")&" min. Kolejka +10%: "&TEXT('Czas budowy'!Y71,"0")&" min (bez czekania)." -> 100 min bazowo; T=10 min; budowa=90 min. Kolejka +10%: 100 min (bez czekania).
A17: Latarnia | B17: Daje premie szczęścia i produkcji po ukończeniu poziomu. | C17: Brak etatów; wizyty nie są zatrudnieniem. | D17: Rozbudowa: 100% szczęścia i produkcja ×2 przez 24 h × nowy poziom. Zwiedzanie: pobyt 4 h, do 2 × poziom latarni wolnych osób z domu; osobiste 100% przez 24 h i premia populacji +10 przez 6 h (jednostka 6 h jest interpretacją wpisu). | E17: 500×max(1, L) KAŻDEGO z 6 zasobów. Pierwsza budowa 0→1:500 każdego. | F17: 5T = T transportu + 4T budowy | G17: Zasady uporządkowane; otwarte szczegóły w arkuszu Decyzje i konflikty. | H17: ZAWSZE: ukończenie budowy. Wcześniej także zlecenie/start/dostawa. Uruchomienie premii latarni. | I17: Po zakończeniu premii latarni przywracamy stan szczęścia sprzed premii. Zwiedzający nie produkują i nie płacą podatku, jedzą normalnie. Początek i kumulacja premii wizyt pozostają do doprecyzowania. Osobne zadania latarni zachowują reguły V3 i niezależne 6 h terminy. | J17: Patrz Premium — aktualny cennik oraz kalkulatory kosztów i czasu. Przy transporcie płatny jest także ostatni niepełny kurs. | K17: Nowe błogosławieństwo: kasa/challenge/udostępnienie/reklama. Zgodnie z decyzją użytkownika szczegóły ODŁOŻONE. Brak cen ani zatwierdzonej integracji. | L17: Budynki!wiersz 17; potwierdzenia w Odpowiedzi i zmiany | M17: =TEXT('Czas budowy'!Y72,"0")&" min bazowo; T="&TEXT('Czas budowy'!V72,"0")&" min; budowa="&TEXT('Czas budowy'!X72,"0")&" min. Kolejka +10%: "&TEXT('Czas budowy'!Y73,"0")&" min (bez czekania)." -> 200 min bazowo; T=40 min; budowa=160 min. Kolejka +10%: 225 min (bez czekania). | N17: =TEXT('Czas budowy'!Y74,"0")&" min bazowo; T="&TEXT('Czas budowy'!V74,"0")&" min; budowa="&TEXT('Czas budowy'!X74,"0")&" min. Kolejka +10%: "&TEXT('Czas budowy'!Y75,"0")&" min (bez czekania)." -> 350 min bazowo; T=70 min; budowa=280 min. Kolejka +10%: 375 min (bez czekania). | O17: =TEXT('Czas budowy'!Y76,"0")&" min bazowo; T="&TEXT('Czas budowy'!V76,"0")&" min; budowa="&TEXT('Czas budowy'!X76,"0")&" min. Kolejka +10%: "&TEXT('Czas budowy'!Y77,"0")&" min (bez czekania)." -> 450 min bazowo; T=90 min; budowa=360 min. Kolejka +10%: 500 min (bez czekania).
A18: CZŁOWIEK — ASSET | B18: Je, pracuje, produkuje/nosi, płaci podatki; własna historia szczęścia. | C18: 12 na starcie w domu; min. 6, max. 24 × Ratusz; jedno zatrudnienie, limit 12 × własny poziom budynku. | D18: Nie ulepsza się osoby poziomem; zmieniają się warunki życia i pracy. | E18: Utrzymanie: 1 Food/os./h; kupowania ludzi nie ustalono. | F18: Demografia zależy od średniego H, liczona zegarowo także offline. | G18: Karta Czlowiek zaktualizowana. | H18: Odejście, nigdy śmierć; nowy mieszkaniec zawsze w domu. | I18: +1 za jedzenie, +1 za pracę; po 12 h braku danego warunku −5; oba braki −10/h. Przeludnienie i osobne kary pełnego bufora. Podatki 1/h; wizyty po zdefiniowaniu. | J18: Brak oferty sprzedaży osób. | K18: Odejścia:najpierwDom,potemnajwiększazałoga;remisywgpriorytetów;patrzCzlowiek. | L18: Czlowiek/Ustalenia/Populacja; potwierdzeniaoffline. | M18: Nie dotyczy. | N18: Nie dotyczy. | O18: Nie dotyczy.

Sheet Czlowiek
A1: CZŁOWIEK • zaktualizowany asset
A2: Wersja 5: nowe notatki z pliku 4, własny limit budynku 12 × L, gospodarka offline, podatek od dojścia i podczas postoju, jedna kara przestoju, ochrona transportu Food, płatna kaplica, czterogodzinne zwiedzanie i ranking co pełną godzinę. Pozostałe szczegóły są oznaczone osobno.
A5: Stan / obszar | B5: Zasada | C5: Wzór / liczby | D5: Konsekwencje | E5: Status
A6: Rola assetu | B6: Każda osoba ma trwałe ID, własne szczęście, stan pracy/pobytu i niezależne liczniki głodu oraz bezrobocia. | C6: 12 na starcie; minimum 6; maksimum 24 × poziom ratusza. | D6: Nowe osoby trafiają do domu. Ubytek oznacza odejście, nie śmierć. | E6: UZGODNIONE; NOWE DOPRECYZOWANIA
A7: Start i dom | B7: Na starcie wszyscy ludzie są w domu, bez przypisania do gospodarki. Z domu widać ich przydziały; można kierować do kaplicy i latarni. | C7: 12 w domu, 0 pracowników we wszystkich budynkach; każdy zasób na starcie 100. | D7: Przed pierwszym przydziałem nie ma produkcji ani podatków, ale ludzie jedzą. | E7: UZGODNIONE / NOWE
A8: Limit miejsca pracy | B8: Limit zależy od poziomu konkretnego miejsca pracy, nie samego ratusza. Jedna wspólna pula wolnych ludzi. | C8: 0…12 × poziom budynku; nowy przydział ograniczony faktycznie wolnymi osobami w domu. | D8: Ratusz 2 i drwale 1: limit drwali nadal 12. Drwale 2: limit 24, jeżeli tylu wolnych istnieje. Nie wolno ulepszyć ponad ratusz. | E8: ZMIENIONE I WYJAŚNIONE
A9: Jedzenie | B9: Każdy je automatycznie wyłącznie z magazynu centralnego, niezależnie od pracy lub drogi. | C9: 1 Food/os./h zegarowej. | D9: Lokalny młyn, targ i port nie karmią bez przewiezienia do centrali. Rezerwę można zjadać. | E9: UZGODNIONE; CZAS ZEGAROWY
A10: Rezerwa jedzenia | B10: Rezerwa na żywienie rośnie z poziomem magazynu. Operacje nieżywieniowe mają ją zachować. | C10: Minimum Food = 50 × poziom magazynu. | D10: Potwierdzone minimum i próg ratunkowego transportu:50 × poziom magazynu. Przy gotowym Food w młynie nie można ręcznie wycofać wszystkich magazynierów, gdy centrala jest poniżej minimum. | E10: ROZSTRZYGNIĘTE V5
A11: Praca producenta | B11: Wydajność na osobę wynika z własnego poziomu producenta. | C11: Poziomy 1,2,3,4: dokładnie 10,12,13,14 szt./h; dalej +1 szt./h na poziom. | D11: Wybrany dosłowny ciąg zastępuje sprzeczny ogólny zapis +10%. Głód ×0,5, premia latarni ×2. | E11: POTWIERDZONE W ODPOWIEDZI
A12: Całe sztuki | B12: Każdy pracownik nalicza własny postęp; niedokończone części różnych osób nie łączą się. Zwolnienie odrzuca jego niedokończoną sztukę. | C12: Na poziomie 1: jedna sztuka/6 min; po 7 min 1, po 13 min 2. Na wyższych poziomach odstęp = 3600 / wydajność sekund. | D12: Gotowy produkt zostaje w lokalnym buforze i wymaga transportu. | E12: UZGODNIONE; DOSTOSOWANE DO WYDAJNOŚCI
A13: Przeróbka | B13: Młyn i tartak zużywają surowce centralne; zboże i drewno idą przez magazyn. | C13: 2 zboża → 1 Food; 2 drewna → 1 deska. | D13: Brak wejścia lub miejsca powoduje przestój i karę według reguły przestoju; przypisani pracownicy nadal płacą podatek. Nie dokładamy drugiej kary bezrobocia za tę samą blokadę. | E13: DOPRECYZOWANE V5
A14: Transport | B14: Tragarz wiezie jeden rodzaj towaru, nie czeka na pełne obłożenie. Pojemność to ładunek na kurs, nie sztuki na godzinę. | C14: Poziom 1: 60 szt./kurs; pełny kurs z powrotem 5 min; pojemność rośnie o 10% na poziom miejsca pracy. | D14: 100 jednego towaru wymaga dwóch kursów: 60 i 40. Magazyn, targ i port stosują takie same bazowe zasady; własne załogi. | E14: POTWIERDZONE; ZAOKRĄGLENIE POJEMNOŚCI DO DECYZJI
A15: Podatek przy pracy | B15: Podatek zaczyna się po dojściu do zakładu i płynie także podczas przestoju, dopóki osoba pozostaje przypisana. Bezrobotny, idący do pracy, wracający i zwiedzający nie płaci. | C15: 1 moneta/os./h zegarowej; podczas premii kaplicy 2. | D15: Brak surowca lub miejsca nie zatrzymuje podatku. Kara przestoju obniża szczęście przypisanych osób. Premia kaplicy nadal podwaja podatek. | E15: POTWIERDZONE V5
A16: Je i pracuje | B16: Sumują się bonus jedzenia i bonus pracy. | C16: +1 pp/h za jedzenie +1 pp/h za pracę = +2 pp/h. | D16: Od osobistego 0% po 10 h takiego stanu ma 20%. | E16: UZGODNIONE
... A37: Ranking | B37: Ranking w ustawieniach według poziomu i posiadanych monet. | C37: Wynik = poziom ratusza × ilość złota. | D37: Aktualizacja o każdej pełnej godzinie zegarowej według zastanego stanu. Remisy nie są opisane. | E37: CZĘSTOTLIWOŚĆ POTWIERDZONA V5

Sheet Premium
A1: PREMIUM V3 • ceny i warunki
A2: 1 PLN = 10 monet. Nowe stawki zastępują brak cennika z wersji 2. Kalkulatory rozdzielają uzgodnione ceny od roboczych interpretacji. Nie dodano sprzedaży ani płatności do gry.
A5: Akcja | B5: Zasada | C5: Wzór / stawka | D5: Uwagi | E5: Status
A6: Przelicznik płatności | B6: 1 PLN = 10 monet. | C6: Cena w PLN = cena w monetach / 10. | D6: Ustalono przelicznik; nie zdefiniowano wypłaty monet na PLN. | E6: POTWIERDZONE
A7: Waluta | B7: Monety służą do Premium; użytkownik używa także nazwy złoto. | C7: W gospodarce istnieją już monety z podatków i portu. | D7: Nie określono, czy złoto, monety zarobione i monety kupione to ta sama pula. Kalkulator roboczo pokazuje jedną monetę, bez nowego tokena. | E7: DO DOPRECYZOWANIA
A8: Przyspieszenie 25% | B8: Skrócenie o 25% pozostałego czasu budowy. | C8: Cena = pełne minuty zaoszczędzonego czasu × 1 moneta. | D8: Roboczo FLOOR(pozostałe sekundy × 0,25 / 60). Wybranie pozostałego czasu zamiast czasu początkowego jest interpretacją. | E8: STAWKA POTWIERDZONA; PODSTAWA DO DOPRECYZOWANIA
A9: Przyspieszenie 50% | B9: Skrócenie o 50% pozostałego czasu budowy. | C9: Cena = FLOOR(pozostałe sekundy × 0,50 / 60) monet. | D9: Należy wyświetlać czas skrócenia i cenę przed zatwierdzeniem. | E9: STAWKA POTWIERDZONA; WZÓR MODELOWY
A10: Przyspieszenie 75% | B10: Skrócenie o 75% pozostałego czasu budowy. | C10: Cena = FLOOR(pozostałe sekundy × 0,75 / 60) monet. | D10: Nie ustalono limitu kolejnych przyspieszeń ani minimalnej ceny. | E10: STAWKA POTWIERDZONA; WZÓR MODELOWY
A11: Budowa natychmiast z zasobami | B11: Dotychczasowa oferta została zachowana; nowy cennik podaje tylko skrócenia 25%, 50%, 75%. | C11: Cena skrócenia 100% nie została potwierdzona. | D11: Nie oznaczać automatycznie ceny 100% jako ustalonej. Nie wiadomo także, czy można przyspieszać transport i budowanie łącznie. | E11: DO DOPRECYZOWANIA
A12: Transport całego bufora producenta | B12: Natychmiastowe wysłanie całego gotowego lokalnego zapasu do centrali. | C12: 10 monet × liczba kursów potrzebnych do przewozu. | D12: Potwierdzone: kursy = ROUNDUP(ilość / ładunek, 0). Ostatni niepełny kurs jest płatny. Dla 100 sztuk i ładunku 60 potrzeba 2 kursów, więc cena wynosi 20 monet. | E12: POTWIERDZONE
A13: Magazyn → budowa | B13: Natychmiastowy przewóz materiałów centralnych na konkretną budowę. | C13: 10 monet × SUMA CEILING(ilość każdego materiału / ładunek). | D13: Każdy materiał liczy się osobno. Monety nie wymagają transportu. Nie ustalono, czy jedno kliknięcie obejmuje wszystkie brakujące materiały. | E13: POTWIERDZONE; ZAKRES KLIKNIĘCIA DO DOPRECYZOWANIA
A14: Magazyn ↔ targ | B14: Takie samo rozliczenie transportu towarów w obu kierunkach. | C14: 10 monet za potrzebny kurs właściwej załogi, osobno dla każdego materiału. | D14: Premium nie tworzy towaru ani wolnej pojemności. Wpływ na blokadę 1 h i termin wygaśnięcia 24 h nadal nieustalony. | E14: STAWKA POTWIERDZONA
A15: Magazyn ↔ port | B15: Takie samo rozliczenie transportu towarów w obu kierunkach. | C15: 10 monet za potrzebny kurs właściwej załogi, osobno dla każdego materiału. | D15: Nie ustalono, czy opłata obejmuje również osobny etap port ↔ statek. Zachować rozróżnienie dwóch etapów portowych. | E15: STAWKA POTWIERDZONA; ETAP STATKU DO DOPRECYZOWANIA
A16: Kup budynek bez surowców | B16: Proporcjonalna bazowa cena zakupu materiałów w porcie ×1,25, plus nominalny koszt monet budynku oraz opłata za skrócenie czasu. | C16: Cena = 1,25 × bazowa portowa wartość materiałów + monety wymagane przez budynek + opłata czasowa. | D16: Potwierdzone: bez zaokrąglania materiałów do paczek po 100; używamy bazowych cen zakupu, a dopłata 25% obejmuje tylko materiały. Do ustalenia pozostaje pełny koszt czy tylko brakujące materiały oraz końcowe zaokrąglenie ceny. | E16: WYCENA POTWIERDZONA; ZAKRES MATERIAŁÓW DO USTALENIA
... A27: Premia za zwiedzanie | B27: Wizyta4 h dla do 2 × poziom latarni osób z domu; nie ustalono opłaty za samą wizytę. | C27: Osobiste100% przez 24 h; populacja +10 przez 6 h (jednostki jako interpretacja). | D27: Zwiedzający nie płacą podatku, jedzą normalnie. Nie utożsamiamy wizyty z premią rozbudowy latarni. | E27: WIZYTA OPISANA V5; CENA NIEOKREŚLONA

Sheet Premium - czas
A1: PRZYSPIESZENIA • kalkulator ceny
A2: Model: procent od POZOSTAŁEJ FAZY BUDOWANIA, bez transportu; opłata za pełne zaoszczędzone minuty, zaokrąglenie w dół. Te interpretacje i ewentualna cena minimalna nie są jeszcze rozstrzygnięte. Niebieskie pola są edytowalne.
A5: Pozostała budowa [min] | B5: Skrócenie | C5: Zaoszczędzony czas [min] | D5: Pozostało [min] | E5: Cena [monety] | F5: Cena zakupu monet [PLN] | G5: Uwagi
A6: 1.5 | B6: 0.25 | C6: =A6*B6 -> 0.375 | D6: =A6-C6 -> 1.125 | E6: =ROUNDDOWN(C6,0)*Parametry!$C$42 -> 0 | F6: =E6/Parametry!$C$41 -> 0 | G6: Jeśli cena wynosi 0, obliczenie ujawnia lukę przy niepełnej minucie. Brak zatwierdzonej minimalnej ceny; przykład nie ustanawia darmowych skróceń jako gotowej oferty.
A7: 1.5 | B7: 0.5 | C7: =A7*B7 -> 0.75 | D7: =A7-C7 -> 0.75 | E7: =ROUNDDOWN(C7,0)*Parametry!$C$42 -> 0 | F7: =E7/Parametry!$C$41 -> 0 | G7: Jeśli cena wynosi 0, obliczenie ujawnia lukę przy niepełnej minucie. Brak zatwierdzonej minimalnej ceny; przykład nie ustanawia darmowych skróceń jako gotowej oferty.
A8: 1.5 | B8: 0.75 | C8: =A8*B8 -> 1.125 | D8: =A8-C8 -> 0.375 | E8: =ROUNDDOWN(C8,0)*Parametry!$C$42 -> 1 | F8: =E8/Parametry!$C$41 -> 0.1 | G8: Jeśli cena wynosi 0, obliczenie ujawnia lukę przy niepełnej minucie. Brak zatwierdzonej minimalnej ceny; przykład nie ustanawia darmowych skróceń jako gotowej oferty.
A9: 10 | B9: 0.25 | C9: =A9*B9 -> 2.5 | D9: =A9-C9 -> 7.5 | E9: =ROUNDDOWN(C9,0)*Parametry!$C$42 -> 2 | F9: =E9/Parametry!$C$41 -> 0.2 | G9: Jeśli cena wynosi 0, obliczenie ujawnia lukę przy niepełnej minucie. Brak zatwierdzonej minimalnej ceny; przykład nie ustanawia darmowych skróceń jako gotowej oferty.
A10: 10 | B10: 0.5 | C10: =A10*B10 -> 5 | D10: =A10-C10 -> 5 | E10: =ROUNDDOWN(C10,0)*Parametry!$C$42 -> 5 | F10: =E10/Parametry!$C$41 -> 0.5 | G10: Jeśli cena wynosi 0, obliczenie ujawnia lukę przy niepełnej minucie. Brak zatwierdzonej minimalnej ceny; przykład nie ustanawia darmowych skróceń jako gotowej oferty.
A11: 10 | B11: 0.75 | C11: =A11*B11 -> 7.5 | D11: =A11-C11 -> 2.5 | E11: =ROUNDDOWN(C11,0)*Parametry!$C$42 -> 7 | F11: =E11/Parametry!$C$41 -> 0.7 | G11: Jeśli cena wynosi 0, obliczenie ujawnia lukę przy niepełnej minucie. Brak zatwierdzonej minimalnej ceny; przykład nie ustanawia darmowych skróceń jako gotowej oferty.
A12: 25 | B12: 0.25 | C12: =A12*B12 -> 6.25 | D12: =A12-C12 -> 18.75 | E12: =ROUNDDOWN(C12,0)*Parametry!$C$42 -> 6 | F12: =E12/Parametry!$C$41 -> 0.6 | G12: Jeśli cena wynosi 0, obliczenie ujawnia lukę przy niepełnej minucie. Brak zatwierdzonej minimalnej ceny; przykład nie ustanawia darmowych skróceń jako gotowej oferty.
A13: 25 | B13: 0.5 | C13: =A13*B13 -> 12.5 | D13: =A13-C13 -> 12.5 | E13: =ROUNDDOWN(C13,0)*Parametry!$C$42 -> 12 | F13: =E13/Parametry!$C$41 -> 1.2 | G13: Jeśli cena wynosi 0, obliczenie ujawnia lukę przy niepełnej minucie. Brak zatwierdzonej minimalnej ceny; przykład nie ustanawia darmowych skróceń jako gotowej oferty.
A14: 25 | B14: 0.75 | C14: =A14*B14 -> 18.75 | D14: =A14-C14 -> 6.25 | E14: =ROUNDDOWN(C14,0)*Parametry!$C$42 -> 18 | F14: =E14/Parametry!$C$41 -> 1.8 | G14: Jeśli cena wynosi 0, obliczenie ujawnia lukę przy niepełnej minucie. Brak zatwierdzonej minimalnej ceny; przykład nie ustanawia darmowych skróceń jako gotowej oferty.
A15: 60 | B15: 0.25 | C15: =A15*B15 -> 15 | D15: =A15-C15 -> 45 | E15: =ROUNDDOWN(C15,0)*Parametry!$C$42 -> 15 | F15: =E15/Parametry!$C$41 -> 1.5 | G15: Jeśli cena wynosi 0, obliczenie ujawnia lukę przy niepełnej minucie. Brak zatwierdzonej minimalnej ceny; przykład nie ustanawia darmowych skróceń jako gotowej oferty.
A16: 60 | B16: 0.5 | C16: =A16*B16 -> 30 | D16: =A16-C16 -> 30 | E16: =ROUNDDOWN(C16,0)*Parametry!$C$42 -> 30 | F16: =E16/Parametry!$C$41 -> 3 | G16: Jeśli cena wynosi 0, obliczenie ujawnia lukę przy niepełnej minucie. Brak zatwierdzonej minimalnej ceny; przykład nie ustanawia darmowych skróceń jako gotowej oferty.
A17: 60 | B17: 0.75 | C17: =A17*B17 -> 45 | D17: =A17-C17 -> 15 | E17: =ROUNDDOWN(C17,0)*Parametry!$C$42 -> 45 | F17: =E17/Parametry!$C$41 -> 4.5 | G17: Jeśli cena wynosi 0, obliczenie ujawnia lukę przy niepełnej minucie. Brak zatwierdzonej minimalnej ceny; przykład nie ustanawia darmowych skróceń jako gotowej oferty.
... A20: 120 | B20: 0.75 | C20: =A20*B20 -> 90 | D20: =A20-C20 -> 30 | E20: =ROUNDDOWN(C20,0)*Parametry!$C$42 -> 90 | F20: =E20/Parametry!$C$41 -> 9 | G20: Jeśli cena wynosi 0, obliczenie ujawnia lukę przy niepełnej minucie. Brak zatwierdzonej minimalnej ceny; przykład nie ustanawia darmowych skróceń jako gotowej oferty.

Sheet Premium - transport
A1: TRANSPORT PREMIUM • kursy i cena
A2: Potwierdzone: każdy potrzebny kurs jest płatny, również ostatni niepełny. Cena = SUMA(ROUNDUP(ilość rodzaju / ładunek)) × liczba odcinków × 10 monet. Dwa rodzaje nie dzielą kursu. Liczba pracowników zmienia czas, a nie liczbę płatnych kursów. Zakres jednego kliknięcia i etapu port–statek pozostaje otwarty.
A5: Trasa / przykład | B5: Towar A [szt.] | C5: Towar B [szt.] | D5: Ładunek/kurs | E5: Liczba odcinków | F5: Kursy A | G5: Kursy B | H5: Kursy razem | I5: Monety | J5: Cena zakupu monet [PLN] | K5: Uwagi
A6: Produkcja → magazyn: 40 | B6: 40 | C6: 0 | D6: 60 | E6: 1 | F6: =ROUNDUP(B6/D6,0) -> 1 | G6: =ROUNDUP(C6/D6,0) -> 0 | H6: =(F6+G6)*E6 -> 1 | I6: =H6*Parametry!$C$43 -> 10 | J6: =I6/Parametry!$C$41 -> 1 | K6: Cena zależy od potrzebnych kursów. Przykład 2 odcinków nie przesądza zakresu jednego kliknięcia portowego; doprecyzować załadunek i rozładunek.
A7: Produkcja → magazyn: 60 | B7: 60 | C7: 0 | D7: 60 | E7: 1 | F7: =ROUNDUP(B7/D7,0) -> 1 | G7: =ROUNDUP(C7/D7,0) -> 0 | H7: =(F7+G7)*E7 -> 1 | I7: =H7*Parametry!$C$43 -> 10 | J7: =I7/Parametry!$C$41 -> 1 | K7: Cena zależy od potrzebnych kursów. Przykład 2 odcinków nie przesądza zakresu jednego kliknięcia portowego; doprecyzować załadunek i rozładunek.
A8: Produkcja → magazyn: 100 | B8: 100 | C8: 0 | D8: 60 | E8: 1 | F8: =ROUNDUP(B8/D8,0) -> 2 | G8: =ROUNDUP(C8/D8,0) -> 0 | H8: =(F8+G8)*E8 -> 2 | I8: =H8*Parametry!$C$43 -> 20 | J8: =I8/Parametry!$C$41 -> 2 | K8: Cena zależy od potrzebnych kursów. Przykład 2 odcinków nie przesądza zakresu jednego kliknięcia portowego; doprecyzować załadunek i rozładunek.
A9: Magazyn → budowa: 180 | B9: 180 | C9: 0 | D9: 60 | E9: 1 | F9: =ROUNDUP(B9/D9,0) -> 3 | G9: =ROUNDUP(C9/D9,0) -> 0 | H9: =(F9+G9)*E9 -> 3 | I9: =H9*Parametry!$C$43 -> 30 | J9: =I9/Parametry!$C$41 -> 3 | K9: Cena zależy od potrzebnych kursów. Przykład 2 odcinków nie przesądza zakresu jednego kliknięcia portowego; doprecyzować załadunek i rozładunek.
A10: Magazyn → budowa: 181 | B10: 181 | C10: 0 | D10: 60 | E10: 1 | F10: =ROUNDUP(B10/D10,0) -> 4 | G10: =ROUNDUP(C10/D10,0) -> 0 | H10: =(F10+G10)*E10 -> 4 | I10: =H10*Parametry!$C$43 -> 40 | J10: =I10/Parametry!$C$41 -> 4 | K10: Cena zależy od potrzebnych kursów. Przykład 2 odcinków nie przesądza zakresu jednego kliknięcia portowego; doprecyzować załadunek i rozładunek.
A11: Dwa rodzaje po 100 | B11: 100 | C11: 100 | D11: 60 | E11: 1 | F11: =ROUNDUP(B11/D11,0) -> 2 | G11: =ROUNDUP(C11/D11,0) -> 2 | H11: =(F11+G11)*E11 -> 4 | I11: =H11*Parametry!$C$43 -> 40 | J11: =I11/Parametry!$C$41 -> 4 | K11: Cena zależy od potrzebnych kursów. Przykład 2 odcinków nie przesądza zakresu jednego kliknięcia portowego; doprecyzować załadunek i rozładunek.
A12: Magazyn → targ | B12: 200 | C12: 0 | D12: 60 | E12: 1 | F12: =ROUNDUP(B12/D12,0) -> 4 | G12: =ROUNDUP(C12/D12,0) -> 0 | H12: =(F12+G12)*E12 -> 4 | I12: =H12*Parametry!$C$43 -> 40 | J12: =I12/Parametry!$C$41 -> 4 | K12: Cena zależy od potrzebnych kursów. Przykład 2 odcinków nie przesądza zakresu jednego kliknięcia portowego; doprecyzować załadunek i rozładunek.
A13: Targ → magazyn | B13: 200 | C13: 0 | D13: 60 | E13: 1 | F13: =ROUNDUP(B13/D13,0) -> 4 | G13: =ROUNDUP(C13/D13,0) -> 0 | H13: =(F13+G13)*E13 -> 4 | I13: =H13*Parametry!$C$43 -> 40 | J13: =I13/Parametry!$C$41 -> 4 | K13: Cena zależy od potrzebnych kursów. Przykład 2 odcinków nie przesądza zakresu jednego kliknięcia portowego; doprecyzować załadunek i rozładunek.
A14: Magazyn → port | B14: 200 | C14: 0 | D14: 60 | E14: 1 | F14: =ROUNDUP(B14/D14,0) -> 4 | G14: =ROUNDUP(C14/D14,0) -> 0 | H14: =(F14+G14)*E14 -> 4 | I14: =H14*Parametry!$C$43 -> 40 | J14: =I14/Parametry!$C$41 -> 4 | K14: Cena zależy od potrzebnych kursów. Przykład 2 odcinków nie przesądza zakresu jednego kliknięcia portowego; doprecyzować załadunek i rozładunek.
A15: Port → magazyn | B15: 200 | C15: 0 | D15: 60 | E15: 1 | F15: =ROUNDUP(B15/D15,0) -> 4 | G15: =ROUNDUP(C15/D15,0) -> 0 | H15: =(F15+G15)*E15 -> 4 | I15: =H15*Parametry!$C$43 -> 40 | J15: =I15/Parametry!$C$41 -> 4 | K15: Cena zależy od potrzebnych kursów. Przykład 2 odcinków nie przesądza zakresu jednego kliknięcia portowego; doprecyzować załadunek i rozładunek.
A16: Dwa odcinki portowe — model | B16: 100 | C16: 0 | D16: 60 | E16: 2 | F16: =ROUNDUP(B16/D16,0) -> 2 | G16: =ROUNDUP(C16/D16,0) -> 0 | H16: =(F16+G16)*E16 -> 4 | I16: =H16*Parametry!$C$43 -> 40 | J16: =I16/Parametry!$C$41 -> 4 | K16: Cena zależy od potrzebnych kursów. Przykład 2 odcinków nie przesądza zakresu jednego kliknięcia portowego; doprecyzować załadunek i rozładunek.
A17: Ładunek wyższego poziomu | B17: 200 | C17: 0 | D17: 66 | E17: 1 | F17: =ROUNDUP(B17/D17,0) -> 4 | G17: =ROUNDUP(C17/D17,0) -> 0 | H17: =(F17+G17)*E17 -> 4 | I17: =H17*Parametry!$C$43 -> 40 | J17: =I17/Parametry!$C$41 -> 4 | K17: Cena zależy od potrzebnych kursów. Przykład 2 odcinków nie przesądza zakresu jednego kliknięcia portowego; doprecyzować załadunek i rozładunek.
A18: Brak towaru | B18: 0 | C18: 0 | D18: 60 | E18: 1 | F18: =ROUNDUP(B18/D18,0) -> 0 | G18: =ROUNDUP(C18/D18,0) -> 0 | H18: =(F18+G18)*E18 -> 0 | I18: =H18*Parametry!$C$43 -> 0 | J18: =I18/Parametry!$C$41 -> 0 | K18: Cena zależy od potrzebnych kursów. Przykład 2 odcinków nie przesądza zakresu jednego kliknięcia portowego; doprecyzować załadunek i rozładunek.

Sheet Premium - budynek
A1: BUDYNEK PREMIUM • potwierdzona wycena materiałów
A2: Potwierdzone: bazowe ceny zakupu portowego liczymy proporcjonalnie do ilości, bez paczek po 100. Materiały ×1,25; wymagane monety nominalnie osobno; opłata czasowa osobno. N/P to aktualny wariant. I/O zachowano jako odrzucone porównanie. Zaokrąglenie końcowej ceny w górę i zakres skracanego czasu pozostają założeniami kalkulatora.
A5: Przykład | B5: Monety w koszcie | C5: Drewno | D5: Kamień | E5: Zboże | F5: Food | G5: Deski | H5: Port: wycena proporcjonalna — aktualna | I5: Paczki 100 — wariant odrzucony | J5: Materiały +25% — zatwierdzone | K5: Pozostała budowa [min] | L5: Skrócenie | M5: Cena czasu | N5: Razem — aktualna wycena | O5: Razem — odrzucone paczki 100 | P5: PLN — aktualna wycena | Q5: Uwagi
A6: 100 drewna +100 Food | B6: 0 | C6: 100 | D6: 0 | E6: 0 | F6: 100 | G6: 0 | H6: =(C6+D6+E6)*Parametry!$C$32/100+(F6+G6)*Parametry!$C$34/100 -> 200 | I6: =(ROUNDUP(C6/100,0)+ROUNDUP(D6/100,0)+ROUNDUP(E6/100,0))*Parametry!$C$32+(ROUNDUP(F6/100,0)+ROUNDUP(G6/100,0))*Parametry!$C$34 -> 200 | J6: =H6*Parametry!$C$44 -> 250 | K6: 120 | L6: 0.5 | M6: =ROUNDDOWN(K6*L6,0)*Parametry!$C$42 -> 60 | N6: =ROUNDUP(B6+J6+M6,0) -> 310 | O6: =ROUNDUP(B6+I6*Parametry!$C$44+M6,0) -> 310 | P6: =N6/Parametry!$C$41 -> 31 | Q6: Potwierdzona wycena: 100 drewna = 50 monet, 100 Food = 150; materiały z dopłatą = 250. Przykładowe skrócenie 120 min o 50% kosztuje 60 monet, razem 310. Zakres czasu i końcowe zaokrąglenie nie zostały osobno zatwierdzone.
A7: Farma 1→2 | B7: 0 | C7: 72 | D7: 72 | E7: 120 | F7: 0 | G7: 0 | H7: =(C7+D7+E7)*Parametry!$C$32/100+(F7+G7)*Parametry!$C$34/100 -> 132 | I7: =(ROUNDUP(C7/100,0)+ROUNDUP(D7/100,0)+ROUNDUP(E7/100,0))*Parametry!$C$32+(ROUNDUP(F7/100,0)+ROUNDUP(G7/100,0))*Parametry!$C$34 -> 200 | J7: =H7*Parametry!$C$44 -> 165 | K7: ='Czas budowy'!X18 -> 5 | L7: 0.5 | M7: =ROUNDDOWN(K7*L7,0)*Parametry!$C$42 -> 2 | N7: =ROUNDUP(B7+J7+M7,0) -> 167 | O7: =ROUNDUP(B7+I7*Parametry!$C$44+M7,0) -> 252 | P7: =N7/Parametry!$C$41 -> 16.7 | Q7: Farma 1→2: materiały według cen proporcjonalnych z dopłatą kosztują 165 monet. Przykładowa faza budowy 5 min skrócona o 50% daje opłatę 2 monet za pełne minuty, razem 167. Odrzucone paczki po 100 dałyby 252. Zakres czasu i zaokrąglenia pozostają założeniami.
A8: Ratusz 1→2 | B8: 500 | C8: 500 | D8: 500 | E8: 500 | F8: 500 | G8: 500 | H8: =(C8+D8+E8)*Parametry!$C$32/100+(F8+G8)*Parametry!$C$34/100 -> 2250 | I8: =(ROUNDUP(C8/100,0)+ROUNDUP(D8/100,0)+ROUNDUP(E8/100,0))*Parametry!$C$32+(ROUNDUP(F8/100,0)+ROUNDUP(G8/100,0))*Parametry!$C$34 -> 2250 | J8: =H8*Parametry!$C$44 -> 2812.5 | K8: ='Czas budowy'!X6 -> 40 | L8: 0.5 | M8: =ROUNDDOWN(K8*L8,0)*Parametry!$C$42 -> 20 | N8: =ROUNDUP(B8+J8+M8,0) -> 3333 | O8: =ROUNDUP(B8+I8*Parametry!$C$44+M8,0) -> 3333 | P8: =N8/Parametry!$C$41 -> 333.3 | Q8: Ratusz 1→2: portowa wartość materiałów 2250 ×1,25 = 2812,5; doliczamy osobno 500 monet. Przykładowa opłata czasowa 20 daje 3332,5; kalkulator roboczo zaokrągla do 3333. Samo końcowe zaokrąglenie nie jest jeszcze uzgodnione.

Sheet Social i polecenia
A1: NAGRODY SPOŁECZNOŚCIOWE • kwoty i warunki
A2: Kwoty zapisane według użytkownika. Limity, potwierdzanie publikacji i nakładanie nagród nie są zdefiniowane. Przeliczenie na PLN pokazuje cenę zakupu takiej liczby monet, nie możliwość ich wypłaty. Platformy mają osobną zakładkę.
A5: Akcja | B5: Nagroda | C5: Warunek | D5: Otwarte szczegóły | E5: Wartość zakupu monet [PLN]
A6: Pochwalenie się, że gram | B6: 1000 | C6: Publikacja informująca o grze. | D6: Nie ustalono kanałów, limitu na konto, powtórzeń ani sposobu potwierdzania publikacji. | E6: =B6/Parametry!$C$41 -> 100
A7: Informacja o następnym poziomie | B7: 500 | C7: Publikacja po rzeczywistym osiągnięciu kolejnego poziomu ratusza. | D7: Jedna nagroda na osiągnięty poziom jest propozycją; zasady wielu platform i usuwania postów są nieustalone. | E7: =B7/Parametry!$C$41 -> 50
A8: Polecenie: nowe logowanie | B8: 1000 | C8: Polecona osoba rzeczywiście się zaloguje. | D8: Nie określono, czy nagrodę dostaje tylko polecający czy także polecony; źródłowo roboczo zapisano nagrodę polecającego. Kryterium nowego konta i limit poleceń nieustalone. | E8: =B8/Parametry!$C$41 -> 100
A9: Polecenie: trzeci aktywny dzień | B9: 500 każdego zasobu | C9: Polecona osoba jest aktywna w trzecim dniu. | D9: Do ustalenia: trzeci dzień od rejestracji czy trzy dni aktywności, minimalna aktywność, odbiorca premii, czy „każdy zasób” obejmuje monety oraz jak przyjąć materiały przy pełnej centrali. | E9: Zależne od zakresu „wszystkiego”
A10: Każdy trzeci post na Facebooku | B10: 1000 | C10: Nagroda za trzeci, szósty, dziewiąty itd. kwalifikowany post. | D10: Nie określono okresu, limitu, wymagań treści ani tego, czy posty „gram” i „kolejny poziom” liczą się do tej samej serii. Zgodność konkretnej akcji z regulaminem platformy wymaga weryfikacji. | E10: =B10/Parametry!$C$41 -> 100

Sheet Platformy
A1: PLATFORMY • kandydaci do publikacji graczy
A2: Lista serwisów podobnych lub uzupełniających Facebooka. Nie potwierdzono aktualnego brzmienia ich zasad: dostęp do próbowanych oficjalnych źródeł blokowało HTTP 403. Adresy służą do późniejszej weryfikacji programu nagród, nie stanowią potwierdzenia jego dopuszczalności.
A5: Platforma | B5: Pasujący format | C5: Zastosowanie | D5: Istotna zasada / kwestia do sprawdzenia | E5: Oficjalne adresy | F5: Status źródła | G5: Uwagi o nagrodach
A6: Facebook | B6: Post, informacja o poziomie, polecenie z linkiem. | C6: Nie dopisujemy automatycznych masowych publikacji ani publikacji do cudzych grup. | D6: Reguły promocji Facebooka znane z dotychczasowej dokumentacji ograniczają użycie prywatnych osi czasu i znajomych do udziału w promocjach, np. „udostępnij, aby dostać nagrodę”. Wymaga sprawdzenia aktualnych warunków przed wdrożeniem nagrody za post. | E6: https://www.facebook.com/policies_center/pages_groups_events | F6: Aktualne warunki niepotwierdzone online. Dostęp do próbowanych źródeł blokowało HTTP 403; nie wszystkie adresy odpytywano oddzielnie. | G6: Kwoty 1000 / 500 / 1000 za każdy 3. post są propozycją ekonomii gry; wykonalność programu promocyjnego nie została potwierdzona.
A7: Instagram | B7: Grafika wyspy, post, relacja lub krótki film Reels. | C7: Kandydat do ręcznego udostępnienia przez gracza. | D7: Sprawdzić wytyczne promocji, prawidłowe oznaczanie i zasady przeciw sztucznemu pozyskiwaniu aktywności. Nie zakładać, że polubienia lub obserwacje mogą być obowiązkowym warunkiem. | E7: https://help.instagram.com/179379842258600 | F7: Aktualne warunki niepotwierdzone online. Dostęp do próbowanych źródeł blokowało HTTP 403; nie wszystkie adresy odpytywano oddzielnie. | G7: Nagrody dla tej platformy i sposób weryfikacji do ustalenia.
A8: Threads | B8: Krótki wpis i zrzut wyspy; link polecający. | C8: Kandydat do dobrowolnej publikacji. | D8: Obowiązują zasady Meta przeciw spamowi; sprawdzić aktualną możliwość i zasady nagradzania publikacji. | E8: https://transparency.meta.com/policies/community-standards/spam/ | F8: Aktualne warunki niepotwierdzone online. Dostęp do próbowanych źródeł blokowało HTTP 403; nie wszystkie adresy odpytywano oddzielnie. | G8: Nagrody nie zostały automatycznie skopiowane z Facebooka.
A9: TikTok | B9: Krótki film z wyspą, budową albo ekspedycją. | C9: Kandydat do treści tworzonych przez graczy. | D9: Wytyczne integralności i autentyczności obejmują sztuczną aktywność. Zasady nagradzanych filmów oraz oznaczania zachęt wymagają weryfikacji. | E9: https://www.tiktok.com/community-guidelines/en/integrity-authenticity/ | F9: Aktualne warunki niepotwierdzone online. Dostęp do próbowanych źródeł blokowało HTTP 403; nie wszystkie adresy odpytywano oddzielnie. | G9: Nie uzależniać nagrody od liczby sztucznych wyświetleń, komentarzy czy obserwujących.
A10: YouTube / Shorts | B10: Krótki film lub dłuższy pokaz gry. | C10: Kandydat do materiałów graczy. | D10: YouTube ma odrębne zasady fake engagement oraz konkursów. Wynagradzanie za manipulowanie wyświetleniami, polubieniami lub innymi wskaźnikami jest ryzykowne; sprawdzić aktualne warunki konkretnego programu. | E10: https://support.google.com/youtube/answer/3399767?hl=en https://support.google.com/youtube/answer/1620498?hl=en | F10: Aktualne warunki niepotwierdzone online. Dostęp do próbowanych źródeł blokowało HTTP 403; nie wszystkie adresy odpytywano oddzielnie. | G10: Treść i dobrowolne polecenie odróżnić od kupowania aktywności.
A11: Discord | B11: Własny serwer gry i kanał do pokazywania wysp. | C11: Dobry kandydat do społeczności gry. | D11: Zasady Discorda zabraniają spamu i manipulowania platformą. Publikacja tylko w przeznaczonych do tego kanałach oraz zgodnie z zasadami konkretnego serwera. | E11: https://discord.com/guidelines | F11: Aktualne warunki niepotwierdzone online. Dostęp do próbowanych źródeł blokowało HTTP 403; nie wszystkie adresy odpytywano oddzielnie. | G11: Bez masowych wiadomości prywatnych lub botów rozsyłających polecenia.
A12: Reddit | B12: Wpisy o postępach gry, grafice i dziennik rozwoju. | C12: Kandydat warunkowy: właściwy subreddit i zgoda moderatorów. | D12: Reddit i poszczególne subreddity mają zasady dotyczące spamu, autopromocji oraz manipulacji głosami. Nagroda za powielane wpisy promocyjne wymaga szczególnej weryfikacji. | E12: https://support.reddithelp.com/hc/en-us/articles/360043504051-Spam | F12: Aktualne warunki niepotwierdzone online. Dostęp do próbowanych źródeł blokowało HTTP 403; nie wszystkie adresy odpytywano oddzielnie. | G12: Nie zakładać prawa do reklamowania gry w dowolnej społeczności.
A13: X | B13: Krótki post, obraz wyspy i link polecający. | C13: Kandydat do dobrowolnego udostępniania. | D13: Sprawdzić zasady promocji i manipulacji platformą; powtarzane identyczne wpisy oraz zduplikowane konta nie powinny generować nagród. | E13: https://help.x.com/en/rules-and-policies/platform-manipulation https://help.x.com/en/rules-and-policies/x-contest-rules | F13: Aktualne warunki niepotwierdzone online. Dostęp do próbowanych źródeł blokowało HTTP 403; nie wszystkie adresy odpytywano oddzielnie. | G13: Próg i ewentualny limit nagrody do ustalenia.
A14: Bluesky | B14: Post z obrazem wyspy i linkiem. | C14: Kandydat do dobrowolnego udostępniania. | D14: Wytyczne społeczności obejmują spam i zakłócanie działania. Sprawdzić zasady promocji przed uruchomieniem programu nagród. | E14: https://bsky.social/about/support/community-guidelines | F14: Aktualne warunki niepotwierdzone online. Dostęp do próbowanych źródeł blokowało HTTP 403; nie wszystkie adresy odpytywano oddzielnie. | G14: Nie zakładać automatycznej weryfikacji publikacji bez osobnego projektu.
A15: Mastodon | B15: Post z wyspą na wybranym serwerze. | C15: Kandydat warunkowy: reguły wybranego serwera. | D15: Mastodon jest siecią wielu serwerów. Zasady reklamy, promocji i spamu zależą od instancji; nie ma jednego zezwolenia obejmującego całą sieć. | E15: https://joinmastodon.org/ https://joinmastodon.org/covenant | F15: Aktualne warunki niepotwierdzone online. Dostęp do próbowanych źródeł blokowało HTTP 403; nie wszystkie adresy odpytywano oddzielnie. | G15: Nagrody i dopuszczalne serwery do ustalenia.
A16: Snapchat | B16: Dobrowolna relacja lub krótki film o grze. | C16: Kandydat do wizualnej prezentacji postępu. | D16: Sprawdzić wytyczne społeczności, zasady promocji i treści sponsorowanych; nie zakładać, że masowe rozsyłanie zaproszeń będzie dozwolone. | E16: https://values.snap.com/policy/policy-community-guidelines | F16: Aktualne warunki niepotwierdzone online. Dostęp do próbowanych źródeł blokowało HTTP 403; nie wszystkie adresy odpytywano oddzielnie. | G16: Kwoty oraz sposób weryfikacji relacji do ustalenia.

Sheet Zadania latarni
A1: LATARNIA • zasady zadań
A2: Zadania to dostawy dla latarni, odrębne od rozbudowy i zwiedzania. Zachowano Twoje reguły, a brakujące szczegóły wyraźnie oznaczono. W przykładach losowanie jest zamrożone; ponowne otwarcie pliku nie zmienia nagród ani kosztów.
A5: Obszar | B5: Status | C5: Zasada | D5: Wzór / liczby | E5: Uwagi
