Workbook

Sheet Start
A1: HARBORLIGHT V8 • pełne zasady i zmiany interfejsu
A2: Źródło: niezmieniony HARBORLIGHT7-zasady.xlsx, 17 decyzji D01–D17 oraz WSZYSTKIE późniejsze zaakceptowane zmiany frontendu i gospodarki. Nowe arkusze: Zmiany v8, Frontend v8, Atrakcje, Atrakcje - kalkulator, Sciezki, Sciezki - transport, Efekty i notyfikacje, Sprawdzenia v8. Archiwalne źródła i 48 komentarzy użytkownika zachowano. Nowsze decyzje w Zmiany v8 mają pierwszeństwo.
A5: Obszar | B5: Co zmieniono | C5: Gdzie sprawdzić
A6: Główna tabela | B6: 12 budynków + asset Człowiek; własne bufory producentów, dotychczasowe limity pracy i najnowsze widoki bez podatków. | C6: Budynki
A7: Czasy | B7: Pełny bazowy kurs 5 min; ścieżki przyspieszają kursy i od poziomu 3 zwiększają ładunek. Budynki 2T; latarnia 5T; kaplica 4T/7T/10T. | C7: Czas budowy: 74 warianty (37 etapów × bazowy/kolejka).
A8: Kolejka | B8: Pełny koszt przy zleceniu +10%; dopłata materiałowa zmienia liczbę kursów i czas. | C8: Normalnie L budów + L miejsc kolejki. Czekanie w kolejce jest wyłączone z estymat.
A9: Zatrudnienie | B9: Limit 12 × własny poziom, produkcja 10/12/13/14…, 5 min do pracy. Podatki naliczane bez zmian, ale informacja o nich usunięta z UI. | C9: Czlowiek / Produkcja
A10: Offline | B10: Cała gospodarka działa również offline: podatki, jedzenie, szczęście, populacja, produkcja, transport i budowa. | C10: Transport i priorytety; Czlowiek | E10: Front usunąć znaczki czasu
A11: Koszty | B11: Magazyn/Targ: 300 L każdego zasobu; Port: 400 L; Ratusz/Dom: 500 L; Latarnia: 500 × max(1, L). | C11: Parametry / Czas budowy
A12: Transport | B12: Do trzech trwałych numerowanych priorytetów, w tym Construction. Podział kursów 8/2 losowe, 5/3/2 losowe lub 5/3/2. Ratunkowe Food zachowuje ochronę. | C12: Transport i priorytety / Czlowiek. Ratunkowy próg Food oraz rezerwa 50 × poziom magazynu są potwierdzone w V5.
A13: Ceny | B13: Port: podstawowe 40/50, produkty 140/150 za 100; podwyżki zakupowe +10% liniowo. Ostatnia korekta dotyczy PORTU, nie TARGU. | C13: Przystan; Targ: bez monet, marża 10%.
A14: Terminy | B14: Towar w porcie/targu nieodebrany przez 24 h przepada; portowa opłata 10 monet została zniesiona. | C14: Terminy zegarowe, również offline.
A15: Premie i wizyty | B15: Płatne błogosławieństwo: 100 × poziom kaplicy monet; +50 każdego zasobu i +20 pp na 1 h. Kolejne płatne użycie 4 h od KOŃCA efektu: 12:00–13:00 → następne 17:00. Nie można nakładać aktywnych błogosławieństw. Premie od powrotu: uczestnik 100% na 24 h i blokada ponownej wizyty przez te same 24 h; każda osobno wysłana grupa daje populacji +10 pp przez 6 h. Premie grup sumują się w czasie nakładania. | C15: Czlowiek / Blogoslawienstwa / Decyzje v7 D01–D02, D15.
A16: Premium | B16: 25/50/75/100% pozostałej fazy budowania, bez transportu. Cena = MAX(5, FLOOR(zaoszczędzone sekundy / 60)) monet. Transport jest osobno rozliczany za potrzebne kursy. Pełny zakup budynku od poziomu gracza 4: wszystkie materiały według proporcjonalnych bazowych cen zakupu portu ×1,25 + nominalne monety budynku + natychmiastowy transport (10 monet za każdy potrzebny kurs, także niepełny). Nic nie pobieramy z własnych materiałów. Gotowe po 10 s; bez wymogu rzeczywistych tragarzy. | C16: Premium / trzy kalkulatory / Planowanie Premium. | F16: Front w każdej bnudowli możliwość skrócenia CZASU budowy z kosztem oraz możliwość zakupu budyunku z kosztem
A17: Ludzie i ranking | B17: Najpierw dom i ludzie w drodze; potem największa załoga. Remis: port → targ → tartak → kamieniołom → drwale → farma → młyn → magazyn. Zwiedzający i uczestnicy modlitwy chronieni; jeżeli brak osoby uprawnionej, odejście nie zachodzi. Minimum 6. Ranking = Ratusz × monety, aktualizowany co pełną godzinę. | C17: Czlowiek / Populacja i szczescie. | F17: tu nie ma konfliktu opisałem już zabieraz najpierw z domu, później z miejsca gdzie jesty najwiecej w przypadku remisu kolejność, port, bazar, tartak, kamieniołom drwal, farma młyn transport, musisz kreatywnie chronić produkcji I transportu żywności
A18: Twoje wpisy | B18: Zachowano wszystkie 75 tekstowych różnic, również notatki w komórkach, nie tylko komentarze Excel. | C18: Twoje wpisy v1 / Odpowiedzi i zmiany
A19: Niewybrane szczegóły | B19: D01–D17 zamknięte. Na później: integracje kont/płatności, social, reklamy, docelowy balans ekspedycji, osobna modlitwa i wartości nagród lojalności. | C19: Decyzje v7 / Na pozniej.
A20: Nowe pomysły z repozytorium | B20: Ekspedycje i wyzwania latarni otrzymały nowe reguły; sterowanie labiryntem/piłeczką pozostaje do opisania. | C20: Zadania latarni / Ekspedycje / Zrodlo v3.
A21: Zadania latarni | B21: Zawsze 3 oferty, tylko 1 aktywne zadanie. Podświetlony postęp każdego produktu w obu widokach; pozostałe wyszarzone. Po sukcesie fajerwerki, wibracja telefonu i opcjonalny Share on Facebook za 500 monet. | C21: Zadania latarni / Zadania przyklady / Zadania - zegary / Narracje latarni.
A22: Ekspedycje | B22: 50 monet po pierwszym poziomie; każda dalsza wygrana podwaja pulę, a przegrana ją zeruje. Dodatkowe ruchy/czas: monety lub reklama ≤30 s. | C22: Ekspedycje / Ekspedycje - poziomy.
A23: Social i polecenia | B23: Nagrody społecznościowe: 1000/500 monet; polecenie: 1000 monet oraz 500 wszystkiego w 3. aktywnym dniu; 1000 monet za każdy 3. post na FB. | C23: Social i polecenia / Platformy.
A24: Balans i niejasności | B24: Nagrody skalowane od L3 i przechowywane przy braku miejsca; minimum przyspieszenia 5 monet; ekspedycje podwajają pulę. Duże zadania nadal mogą wymagać wcześniejszych zapasów. | C24: Bilans V3; zamknięte kwestie oznaczono wynikiem.
A25: Nowe koszty V5 | B25: Młyn, drwale, tartak, kamieniołom: koszt ×2; farma bez zmian. Czasy i kolejka +10% przeliczone. | C25: Budynki / Czas budowy
A26: Wymaganie interfejsu | B26: Angielskie etykiety liczb, statusy, ETA transportu i budowy; bez podatków; Resources = zapas lokalny / centralny; zarządzanie budową tylko ratusz, pracownikami tylko dom. | C26: Frontend v8 / Zmiany v8; stare notatki w kolumnach E/F są źródłowe.
A27: Dom i nowe osoby | B27: Pula domu = liczba mieszkańców przy odnowieniu, w pełnych pp, raz na 24 h. Ręczne punkty dodają H; nie kasują kar ani ich liczników. O 23 h 58 min automat rozdaje wyłącznie resztę, po 1 pp najniższemu H; remis losowy. Pula nie jest wydawana drugi raz. Każdy nowy mieszkaniec ma zamrożone 0% szczęścia przez pierwsze 24 h, również podczas premii; później zwykłe naliczanie od 0%. Początkowych 12 osób nie obejmuje zamrożenie. | C27: Czlowiek / Decyzje v7 D03–D04, D13
A28: Pakiet i prognozy | B28: Pakiet: 1000 × poziom ratusza monet za 24 h; +4 aktywne budowy, dowolna kolejka, planowanie dostaw. Dopłata kolejki +10% pozostaje; ponowny zakup przedłuża ważność. W aktywnym pakiecie plan ma koszt kolejki +10% (każdy składnik w górę), plus opłatę 25% bazowej portowej wartości zakupu braków centralnych. Baza 300 kamienia, centrala 200 → wymagane 330, brak 130; bufor producenta nie jest centralą. Materiały muszą rzeczywiście dotrzeć. | C28: Premium / Planowanie Premium
A29: Status wdrożenia | B29: Reguły w V8 są zatwierdzone. Prototyp frontendowy ma lokalny zapis; konta, OAuth, płatności i reklamy nie są integrowane. Końcowy commit, publikację i wyniki testów gry zapisujemy w docs/IMPLEMENTATION-LOG.md. | C29: Szczegóły wdrożenia i testów: docs/IMPLEMENTATION-LOG.md; Na pozniej.
... A34: Archiwum | B34: 36 zakładek źródła zachowanych; dawne rejestry i wpisy źródłowe są historią. Aktualny rejestr poprawiono i rozszerzono. | C34: Rejestr historyczny v7 / Rejestr historyczny v6

Sheet Zmiany v8
A1: ZMIANY V8 • komplet późniejszych uzgodnień
A2: Rozmowa po Excelu 7; zaakceptowany pakiet frontend v11 oraz późniejszy pakiet zatwierdzony „go”. Nowsza decyzja zastępuje poprzednią wersję tego samego widoku. Nowsze usunięcie podatków oraz zapasy lokalne/centralne na kartach Resources zastępują wcześniejsze wersje tych samych elementów.
A5: ID | B5: Obszar | C5: Asset / widok | D5: Ostateczna zasada | E5: Uwagi / źródło
A6: V8-001 | B6: Wersja | C6: Wszystkie | D6: V8 opiera się na niezmienionym pliku V7 i późniejszych uzgodnieniach. 17 decyzji D01–D17 nadal obowiązuje poza jawnymi nowszymi korektami. | E6: Decyzje v 7 są zachowane; źródła historyczne nie są nowymi wymaganiami.
A7: V8-002 | B7: Start | C7: Nowy gracz | D7: Ratusz 1, Dom 1, 12 mieszkańców w domu, 0 pracowników, 0% szczęścia; każdy z 6 zasobów po 100. Ścieżki: wszystkie 100 odcinków na 0. | E7: Normalny start nie przyznaje testowego magazynu ani 10 000 monet.
A8: V8-003 | B8: Start | C8: Podgląd testowy | D8: W dotychczasowym podglądzie jednorazowo uzupełniamy centralę do limitu na rodzaj i łącznie oraz do minimum 10 000 monet; większe saldo i postęp zachowane. | E8: Znacznik zapisu zapobiega ponownemu grantowi po odświeżeniu. To migracja piaskownicy, nie zasada startu.
A9: V8-004 | B9: Start | C9: Oddzielny nowy gracz | D9: Link profile=new-player używa oddzielnego zapisu i normalnych wartości startowych. Nie kasuje bieżącej wyspy; późniejsze otwarcie kontynuuje zapis tego profilu. | E9: Link i stan wdrożenia: docs/IMPLEMENTATION-LOG.md.
A10: V8-005 | B10: Produkcja | C10: Pięciu producentów | D10: Lokalny magazyn = 200 × WŁASNY poziom producenta. Następny poziom ma 200 × (L+1). Wczytanie nie usuwa starszej nadwyżki. | E10: Zastępuje zależność lokalnego bufora od ratusza.
A11: V8-006 | B11: Ludzie | C11: Osiem miejsc pracy | D11: Limit pozostaje 12 × własny poziom zakładu; przydział jest ograniczony wspólną pulą wolnych osób w domu. | E11: Wyświetlanie trzech liczb nie zmienia poziomu wyznaczającego limit.
A12: V8-007 | B12: Frontend | C12: Wszystkie budynki | D12: U góry panelu status odpowiedni do funkcji. Producent: Producing / Waiting for workers / Storage full / Waiting for resources. | E12: Status odświeża się według rzeczywistego stanu.
A13: V8-008 | B13: Frontend | C13: Produkcja | D13: Producing wskazuje produkt, liczbę najbliższych sztuk i czas ich złożenia w lokalnym magazynie. | E13: Uwzględnia rzeczywiste fazy pracy, dojście, głód, surowiec wejściowy i wolne miejsce.
A14: V8-009 | B14: Frontend | C14: Storage | D14: Trzy wartości: In stock / Current cap. / Next level cap. Krótkie podpisy znajdują się pod każdą liczbą. | E14: Np. 50 / 200 / 400; ostatnia liczba oznacza najbliższe ulepszenie, nie końcowy limit gry.
A15: V8-010 | B15: Frontend | C15: Workers | D15: Trzy wartości: Assigned / Free at home / Max workers; małe +/− korzystają z rzeczywistej dostępności mieszkańców. | E15: Np. 5 / 0 / 12. Osoba wracająca lub idąca nie jest wolna w domu.
A16: V8-011 | B16: Frontend | C16: Podatki | D16: Usuń wszystkie informacje o podatkach z interfejsu: nagłówka, ratusza, kart budynków, zarządzania ludźmi i objaśnień. Sam rachunek podatków pozostaje bez zmiany. | E16: Silnik nadal: 1 moneta/os./h po dotarciu, także przy przestoju; kaplica czasowo ×2. Excel dokumentuje tę regułę.
... A53: V8-048 | B53: Stan | C53: Język i zapis | D53: Aktywny interfejs po angielsku. Zachowujemy istniejące zasoby, mieszkańców, budowy, ładunki i zadania; osobne profile nie nadpisują sobie zapisów. | E53: Oryginalny Excel 7 pozostaje niezmieniony. Prawdziwe konta, OAuth, płatności i reklamy nadal wymagają osobnych integracji.

Sheet Frontend v8
A1: FRONTEND V8 • finalne zachowanie interfejsu
A2: Krótkie angielskie podpisy w grze, polski opis zasad. Późniejsza instrukcja usuwa Taxes ze wszystkich widoków i zastępuje dolne free/max na Resources zapasami lokalny/centralny. Rachunek podatków pozostaje bez zmiany.
A5: Widok | B5: Element / podpis | C5: Wartości i zachowanie | D5: Reguła / wyjątek
A6: Panel producenta | B6: Level | C6: Mniejsze pole po lewej. | D6: Pole Taxes zostało usunięte.
A7: Panel producenta | B7: Storage | C7: In stock / Current cap. / Next level cap. | D7: Zapas lokalny / 200 × L / 200 × (L+1).
A8: Miejsce pracy | B8: Workers | C8: Assigned / Free at home / Max workers | D8: Trzy podpisy pod liczbami, np. 5 / 0 / 12.
A9: Miejsce pracy | B9: +/− | C9: Przydział z faktycznie dostępnych osób. | D9: Droga trwa 5 min; brak wolnych osób blokuje plus.
A10: Każdy budynek | B10: Status | C10: Produkcja, blokada albo status odpowiedni do funkcji. | D10: Przy produkcji: produkt, ilość oraz ETA złożenia w lokalnym magazynie.
A11: Wszystkie widoki | B11: Podatki | C11: Bez wyświetlania podatków i ich opisu. | D11: Rachunek i premia kaplicy pozostają bez zmiany.
A12: House | B12: Housing capacity | C12: Populacja / limit ratusza / łóżka / przyrost lub spadek. | D12: Opisy znajdują się pod i.
A13: House | B13: House happiness | C13: Pula i zegar widoczne; opis pod i. | D13: Manage all workers otwierane wyłącznie tutaj.
A14: Town Hall | B14: Construction and queue | C14: Jedyny panel z licznikiem i zarządzaniem kolejką. | D14: Inne budynki zachowują własny Upgrade.
A15: Town Hall | B15: Active effects | C15: Aktywne błogosławieństwa, premie i kary u góry karty. | D15: Źródło, wartość, odbiorcy, czas lub warunek zakończenia; bez podatków.
A16: Producent | B16: Building upgrade | C16: Upgrade, dwa małe czasy i sąsiednia ramka Premium z dwoma przyciskami. | D16: Buy building package / Deliver local stock now. Opisy Coins/Instant pod i.
... A29: New player | B29: profile=new-player | C29: Oddzielny zapis, normalny start po 100 zasobów i 12 osób. | D29: Nie usuwa wyspy testowej; bez grantu 10 000 monet.

Sheet Decyzje v7
A1: DECYZJE V7 • 17 odpowiedzi zamkniętych
A2: Komplet rozstrzygnięć użytkownika z 23.10.2026 po analizie pliku 6. Wszystkie D01–D17 są zaakceptowane. Osobno pozostają jawnie odłożone tematy; nie blokują wydania tego arkusza.
A5: ID | B5: Temat | C5: Zatwierdzona zasada | D5: Źródło / zastosowanie
A6: D01 | B6: Długość premii populacji po latarni | C6: Premie od powrotu: uczestnik 100% na 24 h i blokada ponownej wizyty przez te same 24 h; każda osobno wysłana grupa daje populacji +10 pp przez 6 h. Premie grup sumują się w czasie nakładania. | D6: Odpowiedź użytkownika 23.10.2026; Czlowiek!C31, Blogoslawienstwa!B9, Decyzje i konflikty!G41, rozmowa23.10
A7: D02 | B7: Limit zwiedzania i płatne pakiety | C7: Darmowo 2 × poziom latarni wejść w ruchomych 24 h. Do 3 dodatkowych pakietów/24 h, każdy daje 2L wejść; cena 300 × numer pakietu (2, 3, 4) × L. Pakiet nie zwiększa liczby miejsc jednocześnie. | D7: Odpowiedź użytkownika 23.10.2026; Premium!G27, rozmowa23.10
A8: D03 | B8: Dom: efekt ręcznie rozdawanego szczęścia | C8: Punkty domu dodają pełne pp do H; kary i ich liczniki pozostają. Przykład: −50 +1 = −49%. | D8: Odpowiedź użytkownika 23.10.2026; Budynki!K7
A9: D04 | B9: Dom: pula i automat23h58 | C9: Pula domu = liczba mieszkańców przy odnowieniu, w pełnych pp, raz na 24 h. Ręczne punkty dodają H; nie kasują kar ani ich liczników. O 23 h 58 min automat rozdaje wyłącznie resztę, po 1 pp najniższemu H; remis losowy. Pula nie jest wydawana drugi raz. | D9: Odpowiedź użytkownika 23.10.2026; Budynki!K7
A10: D05 | B10: Zadania: trzy rozmiary czy kolejka dowolnych rozmiarów | C10: Zawsze 3 zadania. Początkowo małe/średnie/duże; kolejne losowego rozmiaru trafiają na koniec FIFO, dopuszczalne 3 małe lub 3 duże. Nowe po sukcesie natychmiast. | D10: Odpowiedź użytkownika 23.10.2026; Zadania latarni!C6, Zadania latarni!G19, Decyzje i konflikty!G33
A11: D06 | B11: Zadania: kotwica zegara i natychmiastowe odnowienie | C11: Trzy niezależne łańcuchy. Początkowy termin 6 h. Pierwsze ukończenie kotwiczy kolejne odnowienia do tej godziny następnego dnia (Europe/Warsaw). Wcześniejszy sukces natychmiast daje następcę z zachowaniem tej samej dobowej kotwicy; termin nie resetuje się do kolejnych 6 h. | D11: Odpowiedź użytkownika 23.10.2026; Zadania latarni!G12, Zadania latarni!G18, Decyzje i konflikty!G35
A12: D07 | B12: Zadania: wzór opłacalnej nagrody | C12: Stare zakresy stanowią bazę na poziomie ratusza 3: małe 100–200, średnie do 400, duże do 600 monet oraz 50–1000 każdego rodzaju towaru. Inne poziomy: współczynnik 12 × L × p(L) / 468; całe ilości w dół, minimum 1. Rodzajów nagrody: 1/2/3 dla małego/średniego/dużego. Mnożnik szybkiej reakcji dopiero od tej bazy. | D12: Odpowiedź użytkownika 23.10.2026; Zadania latarni!G25, Zadania latarni!G13, Zadania przyklady
A13: D08 | B13: Zadania: liczba rodzajów nagrody | C13: Nagroda towarowa małego: 1 rodzaj; średniego: 2 różne; dużego: 3 różne. Zakres dotyczy każdego rodzaju. | D13: Odpowiedź użytkownika 23.10.2026; Zadania latarni!E14, Decyzje i konflikty!G36
A14: D09 | B14: Pakiet budowlany: czas działania | C14: Pakiet: 1000 × poziom ratusza monet za 24 h; +4 aktywne budowy, dowolna kolejka, planowanie dostaw. Dopłata kolejki +10% pozostaje; ponowny zakup przedłuża ważność. | D14: Odpowiedź użytkownika 23.10.2026; Premium!G18, Premium!A18:E22
A15: D10 | B15: Planowanie przyszłej budowy: dopłaty i brakujące materiały | C15: W aktywnym pakiecie plan ma koszt kolejki +10% (każdy składnik w górę), plus opłatę 25% bazowej portowej wartości zakupu braków centralnych. Baza 300 kamienia, centrala 200 → wymagane 330, brak 130; bufor producenta nie jest centralą. Materiały muszą rzeczywiście dotrzeć. | D15: Odpowiedź użytkownika 23.10.2026; Budynki!J6, Premium!G22, Ustalenia - uwagi!V2-016
A16: D11 | B16: Kupno budynku: co kończy się natychmiast | C16: Pełny zakup budynku od poziomu gracza 4: wszystkie materiały według proporcjonalnych bazowych cen zakupu portu ×1,25 + nominalne monety budynku + natychmiastowy transport (10 monet za każdy potrzebny kurs, także niepełny). Nic nie pobieramy z własnych materiałów. Gotowe po 10 s; bez wymogu rzeczywistych tragarzy. | D16: Odpowiedź użytkownika 23.10.2026; Premium!G16, Decyzje i konflikty!G24, Premium!C16
... A22: D17 | B22: Kaplica: cena rozbudowy | C22: Zatwierdzono: nowy poziom N × (180 monet + 20 drewna + 60 kamienia + 10 desek). To koszt rozbudowy, odrębny od ceny użycia błogosławieństwa. | D22: Odpowiedź użytkownika 23.10.2026; Decyzje i konflikty!Q14, Budynki!E16

Sheet Budynki
A1: BUDYNKI V8 • aktualne reguły
A2: 12 budynków + asset Człowiek. Aktualne zasady: V7 + Zmiany v8. Kolumna K i komentarze są zachowaną historią użytkownika. Bufory producentów: 200 × własny poziom. Rachunek podatków zachowany, ich informacje usunięte z interfejsu. Czasy porównawcze zależą od parametrów: transport + budowa, bez zbierania i czekania w kolejce.
A5: Budynek / asset | B5: Po co jest | C5: Ludzie | D5: Co daje rozbudowa | E5: Koszt bazowy | F5: Czas łączny | G5: Stan | H5: Notyfikacje | I5: Uwagi i reguły | J5: Premium | K5: Twoje wpisy źródłowe — historia | L5: Źródło zmian | M5: 1→2 transport+budowa | N5: 2→3 transport+budowa | O5: 3→4 transport+budowa
A6: Ratusz | B6: Wyznacza poziom gry i limity rozwoju; skarbiec monet. U góry karty pokazuje aktywne błogosławieństwa, premie i kary. | C6: Brak własnych pracowników. | D6: Maksymalna populacja 24×L, wyższy limit ulepszeń, L budów + L miejsc kolejki. Lokalny magazyn producenta zależy od jego własnego poziomu, nie od ratusza. | E6: 500×L KAŻDEGO z 6 zasobów | F6: 2T = T transportu + T budowy | G6: Uzgodnione w V8; prototyp frontendowy. Szczegóły bieżącego wdrożenia i testów: docs/IMPLEMENTATION-LOG.md. Backend i integracje: Na pozniej. | H6: ZAWSZE: ukończenie budowy. Wcześniej także zlecenie/start/dostawa. Premie/kary: powiadomienie przy aktywacji, zmianie i końcu oraz aktywna lista u góry Town Hall. | I6: Ranking = poziom ratusza × monety. L budów + L miejsc kolejki; zlecenia zakolejkowane mają koszt wyższy o 10%. Ranking: aktualizacja o każdej pełnej godzinie według zastanego stanu ratusza i monet. | J6: Pakiet: 1000 × poziom ratusza monet za 24 h; +4 aktywne budowy, dowolna kolejka, planowanie dostaw. Dopłata kolejki +10% pozostaje; ponowny zakup przedłuża ważność. W aktywnym pakiecie plan ma koszt kolejki +10% (każdy składnik w górę), plus opłatę 25% bazowej portowej wartości zakupu braków centralnych. Baza 300 kamienia, centrala 200 → wymagane 330, brak 130; bufor producenta nie jest centralą. Materiały muszą rzeczywiście dotrzeć. | K6: Budowa: Ratusz na poziomie 1 daje możliwość 1 rozbudowy w tym samym czasie i (o ile mam surowce) jednej zakolejkowanej, ale na tą zakolejkowaną muszę mieć surowce w momencie zlecania. Ratusz na poziomie 2 daje prawo do 2 budów I dwóch obiektów w kolejce pod tym samym warunkiem. Budynki zakolejkowane są o 10 % droższe niż te budowane bez kolejki. Później dopiszemy co oferuje premium (na pewno jedną z opcji będzie skróć czas budowy) | L6: Budynki!wiersz 6; potwierdzenia w Odpowiedzi i zmiany | M6: =TEXT('Czas budowy'!Y6,"0")&" min bazowo; T="&TEXT('Czas budowy'!V6,"0")&" min; budowa="&TEXT('Czas budowy'!X6,"0")&" min. Kolejka +10%: "&TEXT('Czas budowy'!Y7,"0")&" min (bez czekania)." -> 80 min bazowo; T=40 min; budowa=40 min. Kolejka +10%: 90 min (bez czekania). | N6: =TEXT('Czas budowy'!Y8,"0")&" min bazowo; T="&TEXT('Czas budowy'!V8,"0")&" min; budowa="&TEXT('Czas budowy'!X8,"0")&" min. Kolejka +10%: "&TEXT('Czas budowy'!Y9,"0")&" min (bez czekania)." -> 140 min bazowo; T=70 min; budowa=70 min. Kolejka +10%: 150 min (bez czekania). | O6: =TEXT('Czas budowy'!Y10,"0")&" min bazowo; T="&TEXT('Czas budowy'!V10,"0")&" min; budowa="&TEXT('Czas budowy'!X10,"0")&" min. Kolejka +10%: "&TEXT('Czas budowy'!Y11,"0")&" min (bez czekania)." -> 180 min bazowo; T=90 min; budowa=90 min. Kolejka +10%: 200 min (bez czekania).
A7: Dom | B7: Zapewnia miejsca mieszkalne, osobno od maksymalnego limitu ratusza. | C7: Brak własnych pracowników. | D7: Miejsca: 24 × poziom domu; zmniejszenie kary przeludnienia. Panel pokazuje ludzi i przydziały oraz pozwala wysyłać wizyty do kaplicy i latarni. Manage all workers dostępne wyłącznie z domu. Cztery wskaźniki: populacja, limit ratusza, łóżka, przyrost/spadek; opisy pod i. | E7: 500×L KAŻDEGO z 6 zasobów | F7: 2T = T transportu + T budowy | G7: Uzgodnione w V8; prototyp frontendowy. Szczegóły bieżącego wdrożenia i testów: docs/IMPLEMENTATION-LOG.md. Backend i integracje: Na pozniej. | H7: ZAWSZE: ukończenie budowy. Wcześniej także zlecenie/start/dostawa. NOWE: przeludnienie; proponujemy na zmianę stanu, nie co klatkę. Premie/kary: powiadomienie przy aktywacji, zmianie i końcu oraz aktywna lista u góry Town Hall. | I7: Kara przeludnienia: max(0, P − 24 × poziom domu) pp/h każdej osobie. Nowi mieszkańcy zawsze trafiają do domu. Pula domu = liczba mieszkańców przy odnowieniu, w pełnych pp, raz na 24 h. Ręczne punkty dodają H; nie kasują kar ani ich liczników. O 23 h 58 min automat rozdaje wyłącznie resztę, po 1 pp najniższemu H; remis losowy. Pula nie jest wydawana drugi raz. | J7: Premium od L4: 25/50/75/100% pozostałej fazy budowania, bez transportu. Cena = MAX(5, FLOOR(zaoszczędzone sekundy / 60)) monet. Transport jest osobno rozliczany za potrzebne kursy. Pełny zakup budynku od poziomu gracza 4: wszystkie materiały według proporcjonalnych bazowych cen zakupu portu ×1,25 + nominalne monety budynku + natychmiastowy transport (10 monet za każdy potrzebny kurs, także niepełny). Nic nie pobieramy z własnych materiałów. Gotowe po 10 s; bez wymogu rzeczywistych tragarzy. | K7: Z poziomu domu widzę wszystkich ludzi gdzie są dopisani, mogę ich stąd wysyłać do kaplicy lub na latarnię. Mogę podejrzeć szczęście każdego mieszkańca indywidualnie. Dom dostaje 1 x na 24 h doładowanie szczęscia równe 1 pp x aktualna ilość mieszkańców, z poziomu domu mogę to szczęście dać indywidualnej osobie, czylui jeżeli mam 24 osoby podnieść jej szczęscie z 0 do 24 albo dać wszystkim po 1 pp., automat (tem co nada wszystkim) działa po 23h i 58 min i później przychodzi nowa pula. Doładiowanie szczęscia nadpisuje kary za bezrobocie i wszelkie inne. | L7: Budynki!wiersz 7; potwierdzenia w Odpowiedzi i zmiany | M7: =TEXT('Czas budowy'!Y12,"0")&" min bazowo; T="&TEXT('Czas budowy'!V12,"0")&" min; budowa="&TEXT('Czas budowy'!X12,"0")&" min. Kolejka +10%: "&TEXT('Czas budowy'!Y13,"0")&" min (bez czekania)." -> 80 min bazowo; T=40 min; budowa=40 min. Kolejka +10%: 90 min (bez czekania). | N7: =TEXT('Czas budowy'!Y14,"0")&" min bazowo; T="&TEXT('Czas budowy'!V14,"0")&" min; budowa="&TEXT('Czas budowy'!X14,"0")&" min. Kolejka +10%: "&TEXT('Czas budowy'!Y15,"0")&" min (bez czekania)." -> 140 min bazowo; T=70 min; budowa=70 min. Kolejka +10%: 150 min (bez czekania). | O7: =TEXT('Czas budowy'!Y16,"0")&" min bazowo; T="&TEXT('Czas budowy'!V16,"0")&" min; budowa="&TEXT('Czas budowy'!X16,"0")&" min. Kolejka +10%: "&TEXT('Czas budowy'!Y17,"0")&" min (bez czekania)." -> 180 min bazowo; T=90 min; budowa=90 min. Kolejka +10%: 200 min (bez czekania).
A8: Farma | B8: Produkuje zboże do młyna, budowy i wymiany. | C8: Start: 0; limit 12 × WŁASNY poziom budynku, ograniczony liczbą istniejących dostępnych ludzi. Ratusz tylko ogranicza poziom rozbudowy. | D8: Własny poziom daje limit 12 × L pracowników i wydajność na osobę/h: 10, 12, 13, 14…; L1 = 10, L ≥ 2: L + 10. Bufor lokalny: 200 × własny poziom producenta. | E8: L×(72 drewna+72 kamienia+120 zboża) | F8: 2T = T transportu + T budowy | G8: Uzgodnione w V8; prototyp frontendowy. Szczegóły bieżącego wdrożenia i testów: docs/IMPLEMENTATION-LOG.md. Backend i integracje: Na pozniej. | H8: ZAWSZE: ukończenie budowy. Wcześniej także zlecenie/start/dostawa. Powiadomienie o pełnym magazynie. Premie/kary: powiadomienie przy aktywacji, zmianie i końcu oraz aktywna lista u góry Town Hall. | I8: Przestój: podatek płynie, brak +1 pp/h za pracę i brak dodatkowej kary bezrobocia. Kara −10 od początku, kolejne −10 co 24 h, maksymalnie −50 z samego przestoju. Inne kary mogą obniżyć całe H poniżej −50. Reset licznika w drodze do domu. | J8: Premium od L4: 25/50/75/100% pozostałej fazy budowania, bez transportu. Cena = MAX(5, FLOOR(zaoszczędzone sekundy / 60)) monet. Transport jest osobno rozliczany za potrzebne kursy. Pełny zakup budynku od poziomu gracza 4: wszystkie materiały według proporcjonalnych bazowych cen zakupu portu ×1,25 + nominalne monety budynku + natychmiastowy transport (10 monet za każdy potrzebny kurs, także niepełny). Nic nie pobieramy z własnych materiałów. Gotowe po 10 s; bez wymogu rzeczywistych tragarzy. | K8: Do wszystkich produkcyjnych, zwiększenie levelu zwiększa produkcję na 1 h, dla levelu 1 jest to 10 szt / h dla levelu 2 będzie to 12, dla levelu 3 -13 dla 4 - 14 etc W premium dla wszystkich produkcyjnych możłiwość natychmiastowego transportu do magazynu oneclickiem. | L8: Budynki!wiersz 8; potwierdzenia w Odpowiedzi i zmiany | M8: =TEXT('Czas budowy'!Y18,"0")&" min bazowo; T="&TEXT('Czas budowy'!V18,"0")&" min; budowa="&TEXT('Czas budowy'!X18,"0")&" min. Kolejka +10%: "&TEXT('Czas budowy'!Y19,"0")&" min (bez czekania)." -> 10 min bazowo; T=5 min; budowa=5 min. Kolejka +10%: 20 min (bez czekania). | N8: =TEXT('Czas budowy'!Y20,"0")&" min bazowo; T="&TEXT('Czas budowy'!V20,"0")&" min; budowa="&TEXT('Czas budowy'!X20,"0")&" min. Kolejka +10%: "&TEXT('Czas budowy'!Y21,"0")&" min (bez czekania)." -> 20 min bazowo; T=10 min; budowa=10 min. Kolejka +10%: 20 min (bez czekania). | O8: =TEXT('Czas budowy'!Y22,"0")&" min bazowo; T="&TEXT('Czas budowy'!V22,"0")&" min; budowa="&TEXT('Czas budowy'!X22,"0")&" min. Kolejka +10%: "&TEXT('Czas budowy'!Y23,"0")&" min (bez czekania)." -> 20 min bazowo; T=10 min; budowa=10 min. Kolejka +10%: 30 min (bez czekania).
A9: Młyn | B9: Przetwarza 2 zboża z centrali→1 żywność do lokalnego bufora. | C9: Start: 0; limit 12 × WŁASNY poziom budynku, ograniczony liczbą istniejących dostępnych ludzi. Ratusz tylko ogranicza poziom rozbudowy. | D9: Własny poziom daje limit 12 × L pracowników i wydajność na osobę/h: 10, 12, 13, 14…; L1 = 10, L ≥ 2: L + 10. Bufor lokalny: 200 × własny poziom producenta. | E9: 2L×(72 drewna+72 kamienia+120 żywności) | F9: 2T = T transportu + T budowy | G9: Uzgodnione w V8; prototyp frontendowy. Szczegóły bieżącego wdrożenia i testów: docs/IMPLEMENTATION-LOG.md. Backend i integracje: Na pozniej. | H9: ZAWSZE: ukończenie budowy. Wcześniej także zlecenie/start/dostawa. Powiadomienie o pełnym magazynie. Premie/kary: powiadomienie przy aktywacji, zmianie i końcu oraz aktywna lista u góry Town Hall. | I9: Przestój: podatek płynie, brak +1 pp/h za pracę i brak dodatkowej kary bezrobocia. Kara −10 od początku, kolejne −10 co 24 h, maksymalnie −50 z samego przestoju. Inne kary mogą obniżyć całe H poniżej −50. Reset licznika w drodze do domu. | J9: Premium od L4: 25/50/75/100% pozostałej fazy budowania, bez transportu. Cena = MAX(5, FLOOR(zaoszczędzone sekundy / 60)) monet. Transport jest osobno rozliczany za potrzebne kursy. Pełny zakup budynku od poziomu gracza 4: wszystkie materiały według proporcjonalnych bazowych cen zakupu portu ×1,25 + nominalne monety budynku + natychmiastowy transport (10 monet za każdy potrzebny kurs, także niepełny). Nic nie pobieramy z własnych materiałów. Gotowe po 10 s; bez wymogu rzeczywistych tragarzy. | L9: Budynki!wiersz 9; potwierdzenia w Odpowiedzi i zmiany | M9: =TEXT('Czas budowy'!Y24,"0")&" min bazowo; T="&TEXT('Czas budowy'!V24,"0")&" min; budowa="&TEXT('Czas budowy'!X24,"0")&" min. Kolejka +10%: "&TEXT('Czas budowy'!Y25,"0")&" min (bez czekania)." -> 20 min bazowo; T=10 min; budowa=10 min. Kolejka +10%: 20 min (bez czekania). | N9: =TEXT('Czas budowy'!Y26,"0")&" min bazowo; T="&TEXT('Czas budowy'!V26,"0")&" min; budowa="&TEXT('Czas budowy'!X26,"0")&" min. Kolejka +10%: "&TEXT('Czas budowy'!Y27,"0")&" min (bez czekania)." -> 30 min bazowo; T=15 min; budowa=15 min. Kolejka +10%: 30 min (bez czekania). | O9: =TEXT('Czas budowy'!Y28,"0")&" min bazowo; T="&TEXT('Czas budowy'!V28,"0")&" min; budowa="&TEXT('Czas budowy'!X28,"0")&" min. Kolejka +10%: "&TEXT('Czas budowy'!Y29,"0")&" min (bez czekania)." -> 40 min bazowo; T=20 min; budowa=20 min. Kolejka +10%: 50 min (bez czekania).
A10: Drwale | B10: Produkują drewno do tartaku i budowy. | C10: Start: 0; limit 12 × WŁASNY poziom budynku, ograniczony liczbą istniejących dostępnych ludzi. Ratusz tylko ogranicza poziom rozbudowy. | D10: Własny poziom daje limit 12 × L pracowników i wydajność na osobę/h: 10, 12, 13, 14…; L1 = 10, L ≥ 2: L + 10. Bufor lokalny: 200 × własny poziom producenta. | E10: 2L×(192 drewna+72 kamienia) | F10: 2T = T transportu + T budowy | G10: Uzgodnione w V8; prototyp frontendowy. Szczegóły bieżącego wdrożenia i testów: docs/IMPLEMENTATION-LOG.md. Backend i integracje: Na pozniej. | H10: ZAWSZE: ukończenie budowy. Wcześniej także zlecenie/start/dostawa. Powiadomienie o pełnym magazynie. Premie/kary: powiadomienie przy aktywacji, zmianie i końcu oraz aktywna lista u góry Town Hall. | I10: Przestój: podatek płynie, brak +1 pp/h za pracę i brak dodatkowej kary bezrobocia. Kara −10 od początku, kolejne −10 co 24 h, maksymalnie −50 z samego przestoju. Inne kary mogą obniżyć całe H poniżej −50. Reset licznika w drodze do domu. | J10: Premium od L4: 25/50/75/100% pozostałej fazy budowania, bez transportu. Cena = MAX(5, FLOOR(zaoszczędzone sekundy / 60)) monet. Transport jest osobno rozliczany za potrzebne kursy. Pełny zakup budynku od poziomu gracza 4: wszystkie materiały według proporcjonalnych bazowych cen zakupu portu ×1,25 + nominalne monety budynku + natychmiastowy transport (10 monet za każdy potrzebny kurs, także niepełny). Nic nie pobieramy z własnych materiałów. Gotowe po 10 s; bez wymogu rzeczywistych tragarzy. | L10: Budynki!wiersz 10; potwierdzenia w Odpowiedzi i zmiany | M10: =TEXT('Czas budowy'!Y30,"0")&" min bazowo; T="&TEXT('Czas budowy'!V30,"0")&" min; budowa="&TEXT('Czas budowy'!X30,"0")&" min. Kolejka +10%: "&TEXT('Czas budowy'!Y31,"0")&" min (bez czekania)." -> 20 min bazowo; T=10 min; budowa=10 min. Kolejka +10%: 20 min (bez czekania). | N10: =TEXT('Czas budowy'!Y32,"0")&" min bazowo; T="&TEXT('Czas budowy'!V32,"0")&" min; budowa="&TEXT('Czas budowy'!X32,"0")&" min. Kolejka +10%: "&TEXT('Czas budowy'!Y33,"0")&" min (bez czekania)." -> 30 min bazowo; T=15 min; budowa=15 min. Kolejka +10%: 30 min (bez czekania). | O10: =TEXT('Czas budowy'!Y34,"0")&" min bazowo; T="&TEXT('Czas budowy'!V34,"0")&" min; budowa="&TEXT('Czas budowy'!X34,"0")&" min. Kolejka +10%: "&TEXT('Czas budowy'!Y35,"0")&" min (bez czekania)." -> 40 min bazowo; T=20 min; budowa=20 min. Kolejka +10%: 50 min (bez czekania).
A11: Tartak | B11: Przetwarza 2 drewna z centrali→1 deskę do lokalnego bufora. | C11: Start: 0; limit 12 × WŁASNY poziom budynku, ograniczony liczbą istniejących dostępnych ludzi. Ratusz tylko ogranicza poziom rozbudowy. | D11: Własny poziom daje limit 12 × L pracowników i wydajność na osobę/h: 10, 12, 13, 14…; L1 = 10, L ≥ 2: L + 10. Bufor lokalny: 200 × własny poziom producenta. | E11: 2L×(72 drewna+72 kamienia+120 desek) | F11: 2T = T transportu + T budowy | G11: Uzgodnione w V8; prototyp frontendowy. Szczegóły bieżącego wdrożenia i testów: docs/IMPLEMENTATION-LOG.md. Backend i integracje: Na pozniej. | H11: ZAWSZE: ukończenie budowy. Wcześniej także zlecenie/start/dostawa. Powiadomienie o pełnym magazynie. Premie/kary: powiadomienie przy aktywacji, zmianie i końcu oraz aktywna lista u góry Town Hall. | I11: Przestój: podatek płynie, brak +1 pp/h za pracę i brak dodatkowej kary bezrobocia. Kara −10 od początku, kolejne −10 co 24 h, maksymalnie −50 z samego przestoju. Inne kary mogą obniżyć całe H poniżej −50. Reset licznika w drodze do domu. | J11: Premium od L4: 25/50/75/100% pozostałej fazy budowania, bez transportu. Cena = MAX(5, FLOOR(zaoszczędzone sekundy / 60)) monet. Transport jest osobno rozliczany za potrzebne kursy. Pełny zakup budynku od poziomu gracza 4: wszystkie materiały według proporcjonalnych bazowych cen zakupu portu ×1,25 + nominalne monety budynku + natychmiastowy transport (10 monet za każdy potrzebny kurs, także niepełny). Nic nie pobieramy z własnych materiałów. Gotowe po 10 s; bez wymogu rzeczywistych tragarzy. | L11: Budynki!wiersz 11; potwierdzenia w Odpowiedzi i zmiany | M11: =TEXT('Czas budowy'!Y36,"0")&" min bazowo; T="&TEXT('Czas budowy'!V36,"0")&" min; budowa="&TEXT('Czas budowy'!X36,"0")&" min. Kolejka +10%: "&TEXT('Czas budowy'!Y37,"0")&" min (bez czekania)." -> 20 min bazowo; T=10 min; budowa=10 min. Kolejka +10%: 20 min (bez czekania). | N11: =TEXT('Czas budowy'!Y38,"0")&" min bazowo; T="&TEXT('Czas budowy'!V38,"0")&" min; budowa="&TEXT('Czas budowy'!X38,"0")&" min. Kolejka +10%: "&TEXT('Czas budowy'!Y39,"0")&" min (bez czekania)." -> 30 min bazowo; T=15 min; budowa=15 min. Kolejka +10%: 30 min (bez czekania). | O11: =TEXT('Czas budowy'!Y40,"0")&" min bazowo; T="&TEXT('Czas budowy'!V40,"0")&" min; budowa="&TEXT('Czas budowy'!X40,"0")&" min. Kolejka +10%: "&TEXT('Czas budowy'!Y41,"0")&" min (bez czekania)." -> 40 min bazowo; T=20 min; budowa=20 min. Kolejka +10%: 50 min (bez czekania).
A12: Kamieniołom | B12: Produkuje kamień do budowy i wymiany. | C12: Start: 0; limit 12 × WŁASNY poziom budynku, ograniczony liczbą istniejących dostępnych ludzi. Ratusz tylko ogranicza poziom rozbudowy. | D12: Własny poziom daje limit 12 × L pracowników i wydajność na osobę/h: 10, 12, 13, 14…; L1 = 10, L ≥ 2: L + 10. Bufor lokalny: 200 × własny poziom producenta. | E12: 2L×(72 drewna+192 kamienia) | F12: 2T = T transportu + T budowy | G12: Uzgodnione w V8; prototyp frontendowy. Szczegóły bieżącego wdrożenia i testów: docs/IMPLEMENTATION-LOG.md. Backend i integracje: Na pozniej. | H12: ZAWSZE: ukończenie budowy. Wcześniej także zlecenie/start/dostawa. Powiadomienie o pełnym magazynie. Premie/kary: powiadomienie przy aktywacji, zmianie i końcu oraz aktywna lista u góry Town Hall. | I12: Przestój: podatek płynie, brak +1 pp/h za pracę i brak dodatkowej kary bezrobocia. Kara −10 od początku, kolejne −10 co 24 h, maksymalnie −50 z samego przestoju. Inne kary mogą obniżyć całe H poniżej −50. Reset licznika w drodze do domu. | J12: Premium od L4: 25/50/75/100% pozostałej fazy budowania, bez transportu. Cena = MAX(5, FLOOR(zaoszczędzone sekundy / 60)) monet. Transport jest osobno rozliczany za potrzebne kursy. Pełny zakup budynku od poziomu gracza 4: wszystkie materiały według proporcjonalnych bazowych cen zakupu portu ×1,25 + nominalne monety budynku + natychmiastowy transport (10 monet za każdy potrzebny kurs, także niepełny). Nic nie pobieramy z własnych materiałów. Gotowe po 10 s; bez wymogu rzeczywistych tragarzy. | L12: Budynki!wiersz 12; potwierdzenia w Odpowiedzi i zmiany | M12: =TEXT('Czas budowy'!Y42,"0")&" min bazowo; T="&TEXT('Czas budowy'!V42,"0")&" min; budowa="&TEXT('Czas budowy'!X42,"0")&" min. Kolejka +10%: "&TEXT('Czas budowy'!Y43,"0")&" min (bez czekania)." -> 20 min bazowo; T=10 min; budowa=10 min. Kolejka +10%: 20 min (bez czekania). | N12: =TEXT('Czas budowy'!Y44,"0")&" min bazowo; T="&TEXT('Czas budowy'!V44,"0")&" min; budowa="&TEXT('Czas budowy'!X44,"0")&" min. Kolejka +10%: "&TEXT('Czas budowy'!Y45,"0")&" min (bez czekania)." -> 30 min bazowo; T=15 min; budowa=15 min. Kolejka +10%: 30 min (bez czekania). | O12: =TEXT('Czas budowy'!Y46,"0")&" min bazowo; T="&TEXT('Czas budowy'!V46,"0")&" min; budowa="&TEXT('Czas budowy'!X46,"0")&" min. Kolejka +10%: "&TEXT('Czas budowy'!Y47,"0")&" min (bez czekania)." -> 40 min bazowo; T=20 min; budowa=20 min. Kolejka +10%: 50 min (bez czekania).
A13: Magazyn | B13: Przechowuje materiały; własna załoga nosi produkcję do centrali i materiały na budowy. Ludzie jedzą z centrali automatycznie. | C13: Start: 0; limit 12 × WŁASNY poziom budynku, ograniczony liczbą istniejących dostępnych ludzi. Ratusz tylko ogranicza poziom rozbudowy. | D13: Limit załogi: 12 × własny L; ładunek na kurs +10%/poziom. Pojemność ×1.5/poziom; magazyn/port: 1000 na rodzaj i 4000 łącznie na poziomie 1; targ: 1000 łącznie na poziomie 1. | E13: 300 × L każdego z 6 zasobów; w kolejce ×1,1. | F13: 2T = T transportu + T budowy | G13: Uzgodnione w V8; prototyp frontendowy. Szczegóły bieżącego wdrożenia i testów: docs/IMPLEMENTATION-LOG.md. Backend i integracje: Na pozniej. | H13: ZAWSZE: ukończenie budowy. Wcześniej także zlecenie/start/dostawa. Powiadomienie o pełnym magazynie. Premie/kary: powiadomienie przy aktywacji, zmianie i końcu oraz aktywna lista u góry Town Hall. | I13: Rezerwa i próg ratunkowego Food: 50 × poziom magazynu. Gdy Food jest poniżej minimum, a czeka w młynie, nie można ręcznie wycofać całej obsady transportu. ETA budowy przeliczamy po zmianie priorytetów. Podgląd każdej osoby: ładunek, źródło→cel i ETA. Trzy trwałe priorytety spośród produktów i Construction, podział kursów 8/2, 5/3/2 lub 5/3/2. | J13: Premium od L4: 25/50/75/100% pozostałej fazy budowania, bez transportu. Cena = MAX(5, FLOOR(zaoszczędzone sekundy / 60)) monet. Transport jest osobno rozliczany za potrzebne kursy. Pełny zakup budynku od poziomu gracza 4: wszystkie materiały według proporcjonalnych bazowych cen zakupu portu ×1,25 + nominalne monety budynku + natychmiastowy transport (10 monet za każdy potrzebny kurs, także niepełny). Nic nie pobieramy z własnych materiałów. Gotowe po 10 s; bez wymogu rzeczywistych tragarzy. | K13: Transport. Nie rozróżniamy odległości, transport produków zawsze trwa 5 min z/do magazynu x capacity tragarza czyli jeżeli tragarz bierze 60 a potrzebuje przenieść 100 to I tak musi wykonać 2 kursy w jednym bierze 60 w drugim 40, tragarz nie może brać 2 produktow na raz, nie może czekać na towar. Jak klikam rozbudowa np drwala podświetla sie napis ile potrzeba surowców a ile zostało już dostarczonych np 60 /100 i estymowany czas zakońćzenia budowy czyli suma czasu transportu przy aktualnych ustawieniach priorytetów, i budowy. Z poziomu magazynu domyślne prirytety jest najpierw zaopatrz magazyn pózniej budowy, można je zmieniać, dodatkowo też można zmienić ustalić prio na konkretne gospodarstwo bądz konretną budowę, 1 tragarz zawsze będzie nosił żywność o ile jest wyprodukowana a w magazynie jest mniej niż 50 Premium szybszy transport do puntu odbioru | L13: Budynki!wiersz 13; potwierdzenia w Odpowiedzi i zmiany | M13: =TEXT('Czas budowy'!Y48,"0")&" min bazowo; T="&TEXT('Czas budowy'!V48,"0")&" min; budowa="&TEXT('Czas budowy'!X48,"0")&" min. Kolejka +10%: "&TEXT('Czas budowy'!Y49,"0")&" min (bez czekania)." -> 50 min bazowo; T=25 min; budowa=25 min. Kolejka +10%: 50 min (bez czekania). | N13: =TEXT('Czas budowy'!Y50,"0")&" min bazowo; T="&TEXT('Czas budowy'!V50,"0")&" min; budowa="&TEXT('Czas budowy'!X50,"0")&" min. Kolejka +10%: "&TEXT('Czas budowy'!Y51,"0")&" min (bez czekania)." -> 90 min bazowo; T=45 min; budowa=45 min. Kolejka +10%: 90 min (bez czekania). | O13: =TEXT('Czas budowy'!Y52,"0")&" min bazowo; T="&TEXT('Czas budowy'!V52,"0")&" min; budowa="&TEXT('Czas budowy'!X52,"0")&" min. Kolejka +10%: "&TEXT('Czas budowy'!Y53,"0")&" min (bez czekania)." -> 110 min bazowo; T=55 min; budowa=55 min. Kolejka +10%: 120 min (bez czekania).
A14: Targ | B14: Od poziomu gracza 2: wymiana w grupach drewno/kamień/zboże lub deski/żywność, nominalnie 1:1 z marżą 10%. Bez kupowania za monety. | C14: Start: 0; limit 12 × WŁASNY poziom budynku, ograniczony liczbą istniejących dostępnych ludzi. Ratusz tylko ogranicza poziom rozbudowy. | D14: Limit załogi: 12 × własny L; ładunek na kurs +10%/poziom. Pojemność ×1.5/poziom; magazyn/port: 1000 na rodzaj i 4000 łącznie na poziomie 1; targ: 1000 łącznie na poziomie 1. | E14: 300 × L każdego z 6 zasobów; w kolejce ×1,1. | F14: 2T = T transportu + T budowy | G14: Uzgodnione w V8; prototyp frontendowy. Szczegóły bieżącego wdrożenia i testów: docs/IMPLEMENTATION-LOG.md. Backend i integracje: Na pozniej. | H14: ZAWSZE: ukończenie budowy. Wcześniej także zlecenie/start/dostawa. Powiadomienie o pełnym magazynie. Premie/kary: powiadomienie przy aktywacji, zmianie i końcu oraz aktywna lista u góry Town Hall. | I14: Własna załoga w obu kierunkach. Barter w 2 grupach, marża 10%, bez monet. Pozostaje blokada dostaw 1 h; zapas przepada po 24 h od przyniesienia/wymiany. | J14: Premium od L4: 25/50/75/100% pozostałej fazy budowania, bez transportu. Cena = MAX(5, FLOOR(zaoszczędzone sekundy / 60)) monet. Transport jest osobno rozliczany za potrzebne kursy. Pełny zakup budynku od poziomu gracza 4: wszystkie materiały według proporcjonalnych bazowych cen zakupu portu ×1,25 + nominalne monety budynku + natychmiastowy transport (10 monet za każdy potrzebny kurs, także niepełny). Nic nie pobieramy z własnych materiałów. Gotowe po 10 s; bez wymogu rzeczywistych tragarzy. | K14: Premium transport oneclick Ceny grupa 2 140/150 | L14: Budynki!wiersz 14; potwierdzenia w Odpowiedzi i zmiany | M14: =TEXT('Czas budowy'!Y54,"0")&" min bazowo; T="&TEXT('Czas budowy'!V54,"0")&" min; budowa="&TEXT('Czas budowy'!X54,"0")&" min. Kolejka +10%: "&TEXT('Czas budowy'!Y55,"0")&" min (bez czekania)." -> 50 min bazowo; T=25 min; budowa=25 min. Kolejka +10%: 50 min (bez czekania). | N14: =TEXT('Czas budowy'!Y56,"0")&" min bazowo; T="&TEXT('Czas budowy'!V56,"0")&" min; budowa="&TEXT('Czas budowy'!X56,"0")&" min. Kolejka +10%: "&TEXT('Czas budowy'!Y57,"0")&" min (bez czekania)." -> 90 min bazowo; T=45 min; budowa=45 min. Kolejka +10%: 90 min (bez czekania). | O14: =TEXT('Czas budowy'!Y58,"0")&" min bazowo; T="&TEXT('Czas budowy'!V58,"0")&" min; budowa="&TEXT('Czas budowy'!X58,"0")&" min. Kolejka +10%: "&TEXT('Czas budowy'!Y59,"0")&" min (bez czekania)." -> 110 min bazowo; T=55 min; budowa=55 min. Kolejka +10%: 120 min (bez czekania).
A15: Przystań | B15: Od poziomu gracza 4: kupno i sprzedaż pięciu materiałów za monety. Wyłącznie pełne paczki 100. Monety są środkiem płatności, nie osobnym towarem. | C15: Start: 0; limit 12 × WŁASNY poziom budynku, ograniczony liczbą istniejących dostępnych ludzi. Ratusz tylko ogranicza poziom rozbudowy. | D15: Limit załogi: 12 × własny L; ładunek na kurs +10%/poziom. Pojemność ×1.5/poziom; magazyn/port: 1000 na rodzaj i 4000 łącznie na poziomie 1; targ: 1000 łącznie na poziomie 1. | E15: 400 × L każdego z 6 zasobów; w kolejce ×1,1. | F15: 2T = T transportu + T budowy | G15: Uzgodnione w V8; prototyp frontendowy. Szczegóły bieżącego wdrożenia i testów: docs/IMPLEMENTATION-LOG.md. Backend i integracje: Na pozniej. | H15: ZAWSZE: ukończenie budowy. Wcześniej także zlecenie/start/dostawa. Powiadomienie o pełnym magazynie. Premie/kary: powiadomienie przy aktywacji, zmianie i końcu oraz aktywna lista u góry Town Hall. | I15: Kliknięcie kup/sprzedaj: pobranie monet lub rezerwacja towaru. Sprzedaż: dwa etapy transportu, wypłata przy wypłynięciu; rejs 5 min. Osobny licznik dla KAŻDEGO produktu w ruchomych 3 h. Kolejne paczki zakupu po 100 podnoszą cenę liniowo o 10% ceny bazowej. Cena zamrożona przy kliknięciu zamówienia; kupno 100 drewna nie podnosi ceny kamienia. | J15: Premium od L4: 25/50/75/100% pozostałej fazy budowania, bez transportu. Cena = MAX(5, FLOOR(zaoszczędzone sekundy / 60)) monet. Transport jest osobno rozliczany za potrzebne kursy. Pełny zakup budynku od poziomu gracza 4: wszystkie materiały według proporcjonalnych bazowych cen zakupu portu ×1,25 + nominalne monety budynku + natychmiastowy transport (10 monet za każdy potrzebny kurs, także niepełny). Nic nie pobieramy z własnych materiałów. Gotowe po 10 s; bez wymogu rzeczywistych tragarzy. | K15: Tempo załogi jak w magazynie, premium jak w magazynie | L15: Budynki!wiersz 15; potwierdzenia w Odpowiedzi i zmiany | M15: =TEXT('Czas budowy'!Y60,"0")&" min bazowo; T="&TEXT('Czas budowy'!V60,"0")&" min; budowa="&TEXT('Czas budowy'!X60,"0")&" min. Kolejka +10%: "&TEXT('Czas budowy'!Y61,"0")&" min (bez czekania)." -> 60 min bazowo; T=30 min; budowa=30 min. Kolejka +10%: 70 min (bez czekania). | N15: =TEXT('Czas budowy'!Y62,"0")&" min bazowo; T="&TEXT('Czas budowy'!V62,"0")&" min; budowa="&TEXT('Czas budowy'!X62,"0")&" min. Kolejka +10%: "&TEXT('Czas budowy'!Y63,"0")&" min (bez czekania)." -> 110 min bazowo; T=55 min; budowa=55 min. Kolejka +10%: 120 min (bez czekania). | O15: =TEXT('Czas budowy'!Y64,"0")&" min bazowo; T="&TEXT('Czas budowy'!V64,"0")&" min; budowa="&TEXT('Czas budowy'!X64,"0")&" min. Kolejka +10%: "&TEXT('Czas budowy'!Y65,"0")&" min (bez czekania)." -> 150 min bazowo; T=75 min; budowa=75 min. Kolejka +10%: 160 min (bez czekania).
A16: Kaplica | B16: Daje premie szczęścia i podatków po rozbudowie; dotychczas była miejscem ręcznych błogosławieństw. | C16: Brak etatów; wizyty nie są zatrudnieniem. | D16: +1 użycie dotychczasowego błogosławieństwa; rozbudowa do N: +10 × N szczęścia, podatki ×2 na 10 h. Kaplica = błogosławieństwo. | E16: Zatwierdzono: nowy poziom N × (180 monet + 20 drewna + 60 kamienia + 10 desek). To koszt rozbudowy, odrębny od ceny użycia błogosławieństwa. | F16: T transportu + 3T × (N − 1) budowy; N = nowy poziom. Łącznie: 4T, 7T, 10T… | G16: Uzgodnione w V8; prototyp frontendowy. Szczegóły bieżącego wdrożenia i testów: docs/IMPLEMENTATION-LOG.md. Backend i integracje: Na pozniej. | H16: ZAWSZE: ukończenie budowy. Wcześniej także zlecenie/start/dostawa. Uruchomienie premii i ręczne błogosławieństwo. Premie/kary: powiadomienie przy aktywacji, zmianie i końcu oraz aktywna lista u góry Town Hall. | I16: Płatne błogosławieństwo: 100 × poziom kaplicy monet; +50 każdego zasobu i +20 pp na 1 h. Kolejne płatne użycie 4 h od KOŃCA efektu: 12:00–13:00 → następne 17:00. Nie można nakładać aktywnych błogosławieństw. | J16: Premium od L4: 25/50/75/100% pozostałej fazy budowania, bez transportu. Cena = MAX(5, FLOOR(zaoszczędzone sekundy / 60)) monet. Transport jest osobno rozliczany za potrzebne kursy. Pełny zakup budynku od poziomu gracza 4: wszystkie materiały według proporcjonalnych bazowych cen zakupu portu ×1,25 + nominalne monety budynku + natychmiastowy transport (10 monet za każdy potrzebny kurs, także niepełny). Nic nie pobieramy z własnych materiałów. Gotowe po 10 s; bez wymogu rzeczywistych tragarzy. | L16: Budynki!wiersz 16; potwierdzenia w Odpowiedzi i zmiany | M16: =TEXT('Czas budowy'!Y66,"0")&" min bazowo; T="&TEXT('Czas budowy'!V66,"0")&" min; budowa="&TEXT('Czas budowy'!X66,"0")&" min. Kolejka +10%: "&TEXT('Czas budowy'!Y67,"0")&" min (bez czekania)." -> 20 min bazowo; T=5 min; budowa=15 min. Kolejka +10%: 20 min (bez czekania). | N16: =TEXT('Czas budowy'!Y68,"0")&" min bazowo; T="&TEXT('Czas budowy'!V68,"0")&" min; budowa="&TEXT('Czas budowy'!X68,"0")&" min. Kolejka +10%: "&TEXT('Czas budowy'!Y69,"0")&" min (bez czekania)." -> 35 min bazowo; T=5 min; budowa=30 min. Kolejka +10%: 35 min (bez czekania). | O16: =TEXT('Czas budowy'!Y70,"0")&" min bazowo; T="&TEXT('Czas budowy'!V70,"0")&" min; budowa="&TEXT('Czas budowy'!X70,"0")&" min. Kolejka +10%: "&TEXT('Czas budowy'!Y71,"0")&" min (bez czekania)." -> 100 min bazowo; T=10 min; budowa=90 min. Kolejka +10%: 100 min (bez czekania).
A17: Latarnia | B17: Daje premie szczęścia i produkcji po ukończeniu poziomu. | C17: Brak etatów; wizyty nie są zatrudnieniem. | D17: Rozbudowa: szczęście 100% i produkcja ×2 przez 24 h × nowy poziom; podatki bez mnożnika. Premie od powrotu: uczestnik 100% na 24 h i blokada ponownej wizyty przez te same 24 h; każda osobno wysłana grupa daje populacji +10 pp przez 6 h. Premie grup sumują się w czasie nakładania. | E17: 500×max(1, L) KAŻDEGO z 6 zasobów. Pierwsza budowa 0→1:500 każdego. | F17: 5T = T transportu + 4T budowy | G17: Uzgodnione w V8; prototyp frontendowy. Szczegóły bieżącego wdrożenia i testów: docs/IMPLEMENTATION-LOG.md. Backend i integracje: Na pozniej. | H17: ZAWSZE: ukończenie budowy. Wcześniej także zlecenie/start/dostawa. Uruchomienie premii latarni. Premie/kary: powiadomienie przy aktywacji, zmianie i końcu oraz aktywna lista u góry Town Hall. | I17: Pobyt 4 h, bez czasu dojścia i możliwości wycofania. Wyłącznie wolne osoby z domu; jednocześnie 2 × poziom latarni miejsc. Darmowo 2 × poziom latarni wejść w ruchomych 24 h. Do 3 dodatkowych pakietów/24 h, każdy daje 2L wejść; cena 300 × numer pakietu (2, 3, 4) × L. Pakiet nie zwiększa liczby miejsc jednocześnie. Po premii powrót do wcześniejszego osobistego stanu. Każdy nowy mieszkaniec ma zamrożone 0% szczęścia przez pierwsze 24 h, również podczas premii; później zwykłe naliczanie od 0%. Początkowych 12 osób nie obejmuje zamrożenie. | J17: Premium od L4: 25/50/75/100% pozostałej fazy budowania, bez transportu. Cena = MAX(5, FLOOR(zaoszczędzone sekundy / 60)) monet. Transport jest osobno rozliczany za potrzebne kursy. Pełny zakup budynku od poziomu gracza 4: wszystkie materiały według proporcjonalnych bazowych cen zakupu portu ×1,25 + nominalne monety budynku + natychmiastowy transport (10 monet za każdy potrzebny kurs, także niepełny). Nic nie pobieramy z własnych materiałów. Gotowe po 10 s; bez wymogu rzeczywistych tragarzy. | K17: Nowe błogosławieństwo: kasa/challenge/udostępnienie/reklama. Zgodnie z decyzją użytkownika szczegóły ODŁOŻONE. Brak cen ani zatwierdzonej integracji. | L17: Budynki!wiersz 17; potwierdzenia w Odpowiedzi i zmiany | M17: =TEXT('Czas budowy'!Y72,"0")&" min bazowo; T="&TEXT('Czas budowy'!V72,"0")&" min; budowa="&TEXT('Czas budowy'!X72,"0")&" min. Kolejka +10%: "&TEXT('Czas budowy'!Y73,"0")&" min (bez czekania)." -> 200 min bazowo; T=40 min; budowa=160 min. Kolejka +10%: 225 min (bez czekania). | N17: =TEXT('Czas budowy'!Y74,"0")&" min bazowo; T="&TEXT('Czas budowy'!V74,"0")&" min; budowa="&TEXT('Czas budowy'!X74,"0")&" min. Kolejka +10%: "&TEXT('Czas budowy'!Y75,"0")&" min (bez czekania)." -> 350 min bazowo; T=70 min; budowa=280 min. Kolejka +10%: 375 min (bez czekania). | O17: =TEXT('Czas budowy'!Y76,"0")&" min bazowo; T="&TEXT('Czas budowy'!V76,"0")&" min; budowa="&TEXT('Czas budowy'!X76,"0")&" min. Kolejka +10%: "&TEXT('Czas budowy'!Y77,"0")&" min (bez czekania)." -> 450 min bazowo; T=90 min; budowa=360 min. Kolejka +10%: 500 min (bez czekania).
A18: CZŁOWIEK — ASSET | B18: Je, pracuje, produkuje/nosi, płaci podatki; własna historia szczęścia. | C18: 12 na starcie w domu; min. 6, max. 24 × Ratusz; jedno zatrudnienie, limit 12 × własny poziom budynku. | D18: Nie ulepsza się osoby poziomem; zmieniają się warunki życia i pracy. | E18: Utrzymanie: 1 Food/os./h; kupowania ludzi nie ustalono. | F18: Demografia zależy od średniego H, liczona zegarowo także offline. | G18: Uzgodnione w V8; prototyp frontendowy. Szczegóły bieżącego wdrożenia i testów: docs/IMPLEMENTATION-LOG.md. Backend i integracje: Na pozniej. | H18: Odejście, nigdy śmierć; nowy mieszkaniec zawsze w domu. Premie/kary: powiadomienie przy aktywacji, zmianie i końcu oraz aktywna lista u góry Town Hall. | I18: +1 za jedzenie, +1 za pracę; po 12 h braku danego warunku −5; oba braki −10/h. Przeludnienie i osobne kary pełnego bufora. Podatki 1/h; wizyty po zdefiniowaniu. | J18: Brak oferty sprzedaży osób. | K18: Odejścia:najpierwDom,potemnajwiększazałoga;remisywgpriorytetów;patrzCzlowiek. | L18: Czlowiek/Ustalenia/Populacja; potwierdzeniaoffline. | M18: Nie dotyczy. | N18: Nie dotyczy. | O18: Nie dotyczy.

Sheet Czlowiek
A1: CZŁOWIEK • zaktualizowany asset
A2: Pełne zasady człowieka po 17 decyzjach: indywidualne szczęście, praca i podatek od dotarcia, brak bonusu pracy przy przestoju, osobne kary, pula domu, zwiedzanie, zamrożenie nowych osób i gospodarka offline. V8 dodaje czasowe atrakcje dla wybranych osób; podatki nadal naliczane, ich informacji nie pokazujemy w UI. Workers ma podpisane Assigned / Free at home / Max workers.
A5: Stan / obszar | B5: Zasada | C5: Wzór / liczby | D5: Konsekwencje | E5: Status
A6: Rola assetu | B6: Każda osoba ma trwałe ID, własne szczęście, stan pracy/pobytu i niezależne liczniki głodu oraz bezrobocia. | C6: 12 na starcie; minimum 6; maksimum 24 × poziom ratusza. | D6: Nowe osoby trafiają do domu. Ubytek oznacza odejście, nie śmierć. | E6: UZGODNIONE; NOWE DOPRECYZOWANIA
A7: Start i dom | B7: Na starcie wszyscy ludzie są w domu, bez przypisania do gospodarki. Z domu widać ich przydziały; można kierować do kaplicy i latarni. | C7: 12 w domu, 0 pracowników we wszystkich budynkach; każdy zasób na starcie 100. | D7: Przed pierwszym przydziałem nie ma produkcji ani podatków, ale ludzie jedzą. | E7: UZGODNIONE / NOWE
A8: Limit miejsca pracy | B8: Limit zależy od poziomu konkretnego miejsca pracy, nie samego ratusza. Jedna wspólna pula wolnych ludzi. | C8: 0…12 × poziom budynku; nowy przydział ograniczony faktycznie wolnymi osobami w domu. | D8: Ratusz 2 i drwale 1: limit drwali nadal 12. Drwale 2: limit 24, jeżeli tylu wolnych istnieje. Nie wolno ulepszyć ponad ratusz. | E8: ZMIENIONE I WYJAŚNIONE
A9: Jedzenie | B9: Każdy je automatycznie wyłącznie z magazynu centralnego, niezależnie od pracy lub drogi. | C9: 1 Food/os./h zegarowej. | D9: Lokalny młyn, targ i port nie karmią bez przewiezienia do centrali. Rezerwę można zjadać. | E9: UZGODNIONE; CZAS ZEGAROWY
A10: Rezerwa jedzenia | B10: Rezerwa na żywienie rośnie z poziomem magazynu. Operacje nieżywieniowe mają ją zachować. | C10: Minimum Food = 50 × poziom magazynu. | D10: Potwierdzone minimum i próg ratunkowego transportu:50 × poziom magazynu. Przy gotowym Food w młynie nie można ręcznie wycofać wszystkich magazynierów, gdy centrala jest poniżej minimum. | E10: ROZSTRZYGNIĘTE V5
A11: Praca producenta | B11: Wydajność na osobę wynika z własnego poziomu producenta. | C11: Poziomy 1,2,3,4: dokładnie 10,12,13,14 szt./h; dalej +1 szt./h na poziom. | D11: Wybrany dosłowny ciąg zastępuje sprzeczny ogólny zapis +10%. Głód ×0,5, premia latarni ×2. | E11: POTWIERDZONE W ODPOWIEDZI
A12: Całe sztuki | B12: Każdy pracownik nalicza własny postęp; niedokończone części różnych osób nie łączą się. Zwolnienie odrzuca jego niedokończoną sztukę. | C12: Na poziomie 1: jedna sztuka/6 min; po 7 min 1, po 13 min 2. Na wyższych poziomach odstęp = 3600 / wydajność sekund. | D12: Gotowy produkt zostaje w lokalnym buforze i wymaga transportu. | E12: UZGODNIONE; DOSTOSOWANE DO WYDAJNOŚCI
A13: Przeróbka | B13: Młyn i tartak zużywają surowce centralne; zboże i drewno idą przez magazyn. | C13: 2 zboża → 1 Food; 2 drewna → 1 deska. | D13: Brak wejścia lub miejsca powoduje przestój i karę według reguły przestoju; przypisani pracownicy nadal płacą podatek. Nie dokładamy drugiej kary bezrobocia za tę samą blokadę. | E13: DOPRECYZOWANE V5
A14: Transport | B14: Tragarz wiezie jeden rodzaj towaru, nie czeka na pełne obłożenie. Pojemność to ładunek na kurs, nie sztuki na godzinę. | C14: Poziom 1: 60 szt./kurs; pełny kurs z powrotem 5 min; pojemność rośnie o 10% na poziom miejsca pracy. | D14: 100 jednego towaru wymaga dwóch kursów: 60 i 40. Magazyn, targ i port stosują takie same bazowe zasady; własne załogi. Ścieżki po ukończeniu całego poziomu zwiększają szybkość; od poziomu 3 również ładunek. | E14: POTWIERDZONE V7: FLOOR(60 × 1,1^(L−1))
A15: Podatek przy pracy | B15: Podatek zaczyna się po dojściu do zakładu i płynie także podczas przestoju, dopóki osoba pozostaje przypisana. Bezrobotny, idący do pracy, wracający i zwiedzający nie płaci. | C15: 1 moneta/os./h zegarowej; podczas premii kaplicy 2. | D15: Brak surowca lub miejsca nie zatrzymuje podatku. Kara przestoju obniża szczęście przypisanych osób. Premia kaplicy nadal podwaja podatek. V8: wartość i opis podatku ukryte we wszystkich widokach gry; to zmiana prezentacji, nie rachunku. | E15: POTWIERDZONE V5
A16: Je i pracuje | B16: Sumują się bonus jedzenia i bonus pracy. | C16: +1 pp/h za jedzenie +1 pp/h za pracę = +2 pp/h. | D16: Od osobistego 0% po 10 h takiego stanu ma 20%. | E16: UZGODNIONE
... A40: Informacja o efektach | B40: Wszystkie aktywne premie i kary mają źródło, wartość, odbiorców i czas/warunek zakończenia. | C40: Powiadomienia + góra Town Hall. | D40: Wpis na zmianę stanu, nie co klatkę. | E40: POTWIERDZONE V8

Sheet Atrakcje
A1: ATRAKCJE • 20 dekoracji i wydarzeń
A2: Pięć ofert zmienia się co 24 h. Y jest całkowite od 5 do 100 i zapisane w ofercie. Cena: Y × bieżący poziom ratusza L. Premia: Y × współczynnik przyzwyczajenia pp dla L osób przez 6 h. Każdy rodzaj ma osobny licznik; reset po 24 h bez jego zakupu. Przy zerowej premii zakup zablokowany.
A5: ID | B5: Nazwa w grze | C5: Znaczenie | D5: Typ | E5: Cena | F5: Efekt | G5: Czas | H5: Przyzwyczajanie
A6: flower-beds | B6: Flower beds | C6: Rabaty kwiatowe | D6: Dekoracja | E6: Y × L monet | F6: Y × współczynnik pp dla L osób | G6: 6 | H6: 100% →75% →50% →25% →0%; osobny reset 24 h
A7: village-benches | B7: Village benches | C7: Ławki we wsi | D7: Dekoracja | E7: Y × L monet | F7: Y × współczynnik pp dla L osób | G7: 6 | H7: 100% →75% →50% →25% →0%; osobny reset 24 h
A8: lantern-strings | B8: Lantern strings | C8: Girlandy lampionów | D8: Dekoracja | E8: Y × L monet | F8: Y × współczynnik pp dla L osób | G8: 6 | H8: 100% →75% →50% →25% →0%; osobny reset 24 h
A9: harbor-flags | B9: Harbor flags | C9: Flagi przystani | D9: Dekoracja | E9: Y × L monet | F9: Y × współczynnik pp dla L osób | G9: 6 | H9: 100% →75% →50% →25% →0%; osobny reset 24 h
A10: village-fountain | B10: Village fountain | C10: Fontanna wiejska | D10: Dekoracja | E10: Y × L monet | F10: Y × współczynnik pp dla L osób | G10: 6 | H10: 100% →75% →50% →25% →0%; osobny reset 24 h
A11: garden-pond | B11: Garden pond | C11: Oczko ogrodowe | D11: Dekoracja | E11: Y × L monet | F11: Y × współczynnik pp dla L osób | G11: 6 | H11: 100% →75% →50% →25% →0%; osobny reset 24 h
A12: wooden-sculptures | B12: Wooden sculptures | C12: Drewniane rzeźby | D12: Dekoracja | E12: Y × L monet | F12: Y × współczynnik pp dla L osób | G12: 6 | H12: 100% →75% →50% →25% →0%; osobny reset 24 h
A13: seaside-mural | B13: Seaside mural | C13: Mural nad morzem | D13: Dekoracja | E13: Y × L monet | F13: Y × współczynnik pp dla L osób | G13: 6 | H13: 100% →75% →50% →25% →0%; osobny reset 24 h
A14: lighthouse-garden | B14: Lighthouse garden | C14: Ogród przy latarni | D14: Dekoracja | E14: Y × L monet | F14: Y × współczynnik pp dla L osób | G14: 6 | H14: 100% →75% →50% →25% →0%; osobny reset 24 h
A15: ornamental-sails | B15: Ornamental sails | C15: Ozdobne żagle | D15: Dekoracja | E15: Y × L monet | F15: Y × współczynnik pp dla L osób | G15: 6 | H15: 100% →75% →50% →25% →0%; osobny reset 24 h
A16: travelling-circus | B16: Travelling circus | C16: Wędrowny cyrk | D16: Wydarzenie | E16: Y × L monet | F16: Y × współczynnik pp dla L osób | G16: 6 | H16: 100% →75% →50% →25% →0%; osobny reset 24 h
A17: theatre-troupe | B17: Theatre troupe | C17: Grupa teatralna | D17: Wydarzenie | E17: Y × L monet | F17: Y × współczynnik pp dla L osób | G17: 6 | H17: 100% →75% →50% →25% →0%; osobny reset 24 h
