Workbook

Sheet Start
A1: HARBORLIGHT 2 • zmiany i komentarze uwzględnione
A2: Tylko Excel. Oryginał 1 z Twoimi komentarzami pozostaje. Wersja 2 zawiera aktualne tabele, przeliczone ładunki i czasy, osobne Premium, archiwum Twoich wpisów i pełne ustalenia. Bez zmian w kodzie gry.
A5: Obszar | B5: Co zmieniono | C5: Gdzie sprawdzić
A6: Główna tabela | B6: 12 budynków + asset Człowiek; nowe koszty, limity własnego poziomu, efekty rozbudowy i czasy. | C6: Budynki
A7: Czasy | B7: 5 min — pełny kurs, jeden rodzaj towaru, ładunki 60/66/72; Ratusz/Dom 2 T, Latarnia 5 T, Kaplica 4 T/7 T/10 T. | C7: Czas budowy: 74 warianty (37 etapów × bazowy/kolejka).
A8: Kolejka | B8: Pełny koszt przy zleceniu +10%; dopłata materiałowa zmienia liczbę kursów i czas. | C8: Normalnie L budów + L miejsc kolejki. Czekanie w kolejce jest wyłączone z estymat.
A9: Zatrudnienie | B9: Własny limit 12 × poziom budynku; produkcja 10, 12, 13, 14…; 5 min do pracy i do domu. | C9: Czlowiek / Produkcja
A10: Offline | B10: Cała gospodarka działa również offline: podatki, jedzenie, szczęście, populacja, produkcja, transport i budowa. | C10: Transport i priorytety; Czlowiek
A11: Koszty | B11: Magazyn/Targ: 300 L każdego zasobu; Port: 400 L; Ratusz/Dom: 500 L; Latarnia: 500 × max(1, L). | C11: Parametry / Czas budowy
A12: Transport | B12: Rezerwa Food: 50 × poziom magazynu; priorytety: zaopatrzenie, potem budowy; własne załogi targu i portu. | C12: Transport i priorytety. Ratunkowy próg Food wymaga spójnego doprecyzowania.
A13: Ceny | B13: Port: podstawowe 40/50, produkty 140/150 za 100; podwyżki zakupowe +10% liniowo. Ostatnia korekta dotyczy PORTU, nie TARGU. | C13: Przystan; Targ: bez monet, marża 10%.
A14: Terminy | B14: Towar w porcie/targu nieodebrany przez 24 h przepada; portowa opłata 10 monet została zniesiona. | C14: Terminy zegarowe, również offline. | D14: usunąć znaczki stop play I przewin w prawym górnym rogu
A15: Premie i wizyty | B15: Kaplica = błogosławieństwo, Latarnia = zwiedzanie. Latarnia ustawia szczęście na 100%, nie dodaje +100. | C15: Blogoslawienstwa; szczegóły wizyt pozostają otwarte.
A16: Premium | B16: Zebrane oferty: 2× szybciej, natychmiast z zasobami, kup bez surowców, transport one-click, wcześniejsze +4/pipeline. | C16: Premium; ceny i limity do ustalenia później. | D16: w wersji 3 już rozpisane
A17: Ludzie i ranking | B17: Nowi trafiają do domu, ubytek = odejście; priorytet: dom / największa załoga; ranking = Ratusz × złoto. | C17: Czlowiek; niepełna kolejność przy remisach w arkuszu Decyzje i konflikty. | D17: odejścia 1 dom, póxniej tam gdzie wiecej, gdy remis port, kamieniołom, tartak, drwal, farma, wiatrak, transport
A18: Twoje wpisy | B18: Zachowano wszystkie 75 tekstowych różnic, również notatki w komórkach, nie tylko komentarze Excel. | C18: Twoje wpisy v1 / Odpowiedzi i zmiany
A19: Niewybrane szczegóły | B19: Zablokowana produkcja i podatek, ratunkowy próg Food, kolejność remisów, globalność cen, oferty Premium. | C19: Decyzje i konflikty: jasno opisane luki, bez wymyślonych ustaleń.
A20: Nowe pomysły z repozytorium | B20: Shakomat na komórkę z kulką (pisownia źródłowa zachowana), ekspedycje, wyzwania do latarni. Bez dopisywania zasad. | C20: Pomysly — źródło: docs/arkusze/pomysły

Sheet Budynki
A1: BUDYNKI V2 • uwzględnione wpisy i odpowiedzi
A2: Nowy plik 2; poprzednie pliki 0 i 1 pozostają. Czasy bazowe przy 6 DOSTĘPNYCH tragarzach, ładunki 60/66/72, pełny kurs 5 min. Bez zbierania, karmienia, oczekiwania w kolejce i wcześniejszych rozbudów. Kolejka ma osobne koszty i czasy z +10% w arkuszu Czas budowy. Wszystko działa offline.
A5: Budynek / asset | B5: Po co jest | C5: Ludzie | D5: Co daje rozbudowa | E5: Koszt bazowy | F5: Czas łączny | G5: Stan | H5: Notyfikacje | I5: Uwagi i reguły | J5: Premium | K5: Twoje uwagi3 / doprecyzowania | L5: Źródło zmian | M5: 1→2 transport+budowa | N5: 2→3 transport+budowa | O5: 3→4 transport+budowa
A6: Ratusz | B6: Wyznacza poziom gry i limity rozwoju; jest skarbcem monet i pokazuje podatek/h. | C6: Brak własnych pracowników. | D6: Maksymalna populacja: 24 × L; wyższy poziom innych budynków; L budów + L miejsc kolejki; lokalne bufory producentów: 200 × Ratusz. | E6: 500×L KAŻDEGO z 6 zasobów | F6: 2T = T transportu + T budowy | G6: Zasady uporządkowane; otwarte szczegóły w arkuszu Decyzje i konflikty. | H6: ZAWSZE: ukończenie budowy. Wcześniej także zlecenie/start/dostawa. | I6: Ranking = poziom ratusza × monety. L budów + L miejsc kolejki; zlecenia zakolejkowane mają koszt wyższy o 10%. | J6: patrz Premium. Doprecyzowane w kolejnej edycji | K6: Budowa: Ratusz na poziomie 1 daje możliwość 1 rozbudowy w tym samym czasie i (o ile mam surowce) jednej zakolejkowanej, ale na tą zakolejkowaną muszę mieć surowce w momencie zlecania. Ratusz na poziomie 2 daje prawo do 2 budów I dwóch obiektów w kolejce pod tym samym warunkiem. Budynki zakolejkowane są o 10 % droższe niż te budowane bez kolejki. Później dopiszemy co oferuje premium (na pewno jedną z opcji będzie skróć czas budowy) | L6: Budynki!wiersz 6; potwierdzenia w Odpowiedzi i zmiany | M6: =TEXT('Czas budowy'!Y6,"0")&" min bazowo; T="&TEXT('Czas budowy'!V6,"0")&" min; budowa="&TEXT('Czas budowy'!X6,"0")&" min. Kolejka +10%: "&TEXT('Czas budowy'!Y7,"0")&" min (bez czekania)." -> 80 min bazowo; T=40 min; budowa=40 min. Kolejka +10%: 90 min (bez czekania). | N6: =TEXT('Czas budowy'!Y8,"0")&" min bazowo; T="&TEXT('Czas budowy'!V8,"0")&" min; budowa="&TEXT('Czas budowy'!X8,"0")&" min. Kolejka +10%: "&TEXT('Czas budowy'!Y9,"0")&" min (bez czekania)." -> 140 min bazowo; T=70 min; budowa=70 min. Kolejka +10%: 150 min (bez czekania). | O6: =TEXT('Czas budowy'!Y10,"0")&" min bazowo; T="&TEXT('Czas budowy'!V10,"0")&" min; budowa="&TEXT('Czas budowy'!X10,"0")&" min. Kolejka +10%: "&TEXT('Czas budowy'!Y11,"0")&" min (bez czekania)." -> 180 min bazowo; T=90 min; budowa=90 min. Kolejka +10%: 200 min (bez czekania).
A7: Dom | B7: Zapewnia miejsca mieszkalne, osobno od maksymalnego limitu ratusza. | C7: Brak własnych pracowników. | D7: Miejsca: 24 × poziom domu; zmniejszenie kary przeludnienia. Panel pokazuje ludzi i przydziały oraz pozwala wysyłać wizyty do kaplicy i latarni. | E7: 500×L KAŻDEGO z 6 zasobów | F7: 2T = T transportu + T budowy | G7: Zasady uporządkowane; otwarte szczegóły w arkuszu Decyzje i konflikty. | H7: ZAWSZE: ukończenie budowy. Wcześniej także zlecenie/start/dostawa. NOWE: przeludnienie; proponujemy na zmianę stanu, nie co klatkę. | I7: Kara przeludnienia: max(0, P − 24 × poziom domu) pp/h każdej osobie. Nowi mieszkańcy zawsze trafiają do domu. | J7: patrz Premium. Doprecyzowane w kolejnej edycji | K7: Z poziomu domu widzę wszystkich ludzi gdzie są dopisani, mogę ich stąd wysyłać do kaplicy lub na latarnię | L7: Budynki!wiersz 7; potwierdzenia w Odpowiedzi i zmiany | M7: =TEXT('Czas budowy'!Y12,"0")&" min bazowo; T="&TEXT('Czas budowy'!V12,"0")&" min; budowa="&TEXT('Czas budowy'!X12,"0")&" min. Kolejka +10%: "&TEXT('Czas budowy'!Y13,"0")&" min (bez czekania)." -> 80 min bazowo; T=40 min; budowa=40 min. Kolejka +10%: 90 min (bez czekania). | N7: =TEXT('Czas budowy'!Y14,"0")&" min bazowo; T="&TEXT('Czas budowy'!V14,"0")&" min; budowa="&TEXT('Czas budowy'!X14,"0")&" min. Kolejka +10%: "&TEXT('Czas budowy'!Y15,"0")&" min (bez czekania)." -> 140 min bazowo; T=70 min; budowa=70 min. Kolejka +10%: 150 min (bez czekania). | O7: =TEXT('Czas budowy'!Y16,"0")&" min bazowo; T="&TEXT('Czas budowy'!V16,"0")&" min; budowa="&TEXT('Czas budowy'!X16,"0")&" min. Kolejka +10%: "&TEXT('Czas budowy'!Y17,"0")&" min (bez czekania)." -> 180 min bazowo; T=90 min; budowa=90 min. Kolejka +10%: 200 min (bez czekania).
A8: Farma | B8: Produkuje zboże do młyna, budowy i wymiany. | C8: Start: 0; limit 12 × WŁASNY poziom budynku, ograniczony liczbą istniejących dostępnych ludzi. Ratusz tylko ogranicza poziom rozbudowy. | D8: Własny poziom daje limit 12 × L pracowników i wydajność na osobę/h: 10, 12, 13, 14…; L1 = 10, L ≥ 2: L + 10. Bufor lokalny: 200 × Ratusz. | E8: L×(72 drewna+72 kamienia+120 zboża) | F8: 2T = T transportu + T budowy | G8: Zasady uporządkowane; otwarte szczegóły w arkuszu Decyzje i konflikty. | H8: ZAWSZE: ukończenie budowy. Wcześniej także zlecenie/start/dostawa. Powiadomienie o pełnym magazynie. | I8: Pełny lokalny bufor: produkcja STOP, osobny modyfikator −10…−50. Brak surowca/miejsca powoduje brak pracy; podatek i bonus +1 przy blokadzie pozostają do decyzji. Droga: 5 min w każdą stronę; drewno i zboże przez centralę. | J8: patrz Premium. Doprecyzowane w kolejnej edycji | K8: Do wszystkich produkcyjnych, zwiększenie levelu zwiększa produkcję na 1 h, dla levelu 1 jest to 10 szt / h dla levelu 2 będzie to 12, dla levelu 3 -13 dla 4 - 14 etc W premium dla wszystkich produkcyjnych możłiwość natychmiastowego transportu do magazynu oneclickiem. | L8: Budynki!wiersz 8; potwierdzenia w Odpowiedzi i zmiany | M8: =TEXT('Czas budowy'!Y18,"0")&" min bazowo; T="&TEXT('Czas budowy'!V18,"0")&" min; budowa="&TEXT('Czas budowy'!X18,"0")&" min. Kolejka +10%: "&TEXT('Czas budowy'!Y19,"0")&" min (bez czekania)." -> 10 min bazowo; T=5 min; budowa=5 min. Kolejka +10%: 20 min (bez czekania). | N8: =TEXT('Czas budowy'!Y20,"0")&" min bazowo; T="&TEXT('Czas budowy'!V20,"0")&" min; budowa="&TEXT('Czas budowy'!X20,"0")&" min. Kolejka +10%: "&TEXT('Czas budowy'!Y21,"0")&" min (bez czekania)." -> 20 min bazowo; T=10 min; budowa=10 min. Kolejka +10%: 20 min (bez czekania). | O8: =TEXT('Czas budowy'!Y22,"0")&" min bazowo; T="&TEXT('Czas budowy'!V22,"0")&" min; budowa="&TEXT('Czas budowy'!X22,"0")&" min. Kolejka +10%: "&TEXT('Czas budowy'!Y23,"0")&" min (bez czekania)." -> 20 min bazowo; T=10 min; budowa=10 min. Kolejka +10%: 30 min (bez czekania).
A9: Młyn | B9: Przetwarza 2 zboża z centrali→1 żywność do lokalnego bufora. | C9: Start: 0; limit 12 × WŁASNY poziom budynku, ograniczony liczbą istniejących dostępnych ludzi. Ratusz tylko ogranicza poziom rozbudowy. | D9: Własny poziom daje limit 12 × L pracowników i wydajność na osobę/h: 10, 12, 13, 14…; L1 = 10, L ≥ 2: L + 10. Bufor lokalny: 200 × Ratusz. | E9: 2L×(72 drewna+72 kamienia+120 żywności) | F9: 2T = T transportu + T budowy | G9: Zasady uporządkowane; otwarte szczegóły w arkuszu Decyzje i konflikty. | H9: ZAWSZE: ukończenie budowy. Wcześniej także zlecenie/start/dostawa. Powiadomienie o pełnym magazynie. | I9: Pełny lokalny bufor: produkcja STOP, osobny modyfikator −10…−50. Brak surowca/miejsca powoduje brak pracy; podatek i bonus +1 przy blokadzie pozostają do decyzji. Droga: 5 min w każdą stronę; drewno i zboże przez centralę. | J9: patrz Premium. Doprecyzowane w kolejnej edycji | L9: Budynki!wiersz 9; potwierdzenia w Odpowiedzi i zmiany | M9: =TEXT('Czas budowy'!Y24,"0")&" min bazowo; T="&TEXT('Czas budowy'!V24,"0")&" min; budowa="&TEXT('Czas budowy'!X24,"0")&" min. Kolejka +10%: "&TEXT('Czas budowy'!Y25,"0")&" min (bez czekania)." -> 10 min bazowo; T=5 min; budowa=5 min. Kolejka +10%: 20 min (bez czekania). | N9: =TEXT('Czas budowy'!Y26,"0")&" min bazowo; T="&TEXT('Czas budowy'!V26,"0")&" min; budowa="&TEXT('Czas budowy'!X26,"0")&" min. Kolejka +10%: "&TEXT('Czas budowy'!Y27,"0")&" min (bez czekania)." -> 20 min bazowo; T=10 min; budowa=10 min. Kolejka +10%: 20 min (bez czekania). | O9: =TEXT('Czas budowy'!Y28,"0")&" min bazowo; T="&TEXT('Czas budowy'!V28,"0")&" min; budowa="&TEXT('Czas budowy'!X28,"0")&" min. Kolejka +10%: "&TEXT('Czas budowy'!Y29,"0")&" min (bez czekania)." -> 20 min bazowo; T=10 min; budowa=10 min. Kolejka +10%: 30 min (bez czekania).
A10: Drwale | B10: Produkują drewno do tartaku i budowy. | C10: Start: 0; limit 12 × WŁASNY poziom budynku, ograniczony liczbą istniejących dostępnych ludzi. Ratusz tylko ogranicza poziom rozbudowy. | D10: Własny poziom daje limit 12 × L pracowników i wydajność na osobę/h: 10, 12, 13, 14…; L1 = 10, L ≥ 2: L + 10. Bufor lokalny: 200 × Ratusz. | E10: 2L×(192 drewna+72 kamienia) | F10: 2T = T transportu + T budowy | G10: Zasady uporządkowane; otwarte szczegóły w arkuszu Decyzje i konflikty. | H10: ZAWSZE: ukończenie budowy. Wcześniej także zlecenie/start/dostawa. Powiadomienie o pełnym magazynie. | I10: Pełny lokalny bufor: produkcja STOP, osobny modyfikator −10…−50. Brak surowca/miejsca powoduje brak pracy; podatek i bonus +1 przy blokadzie pozostają do decyzji. Droga: 5 min w każdą stronę; drewno i zboże przez centralę. | J10: patrz Premium. Doprecyzowane w kolejnej edycji | L10: Budynki!wiersz 10; potwierdzenia w Odpowiedzi i zmiany | M10: =TEXT('Czas budowy'!Y30,"0")&" min bazowo; T="&TEXT('Czas budowy'!V30,"0")&" min; budowa="&TEXT('Czas budowy'!X30,"0")&" min. Kolejka +10%: "&TEXT('Czas budowy'!Y31,"0")&" min (bez czekania)." -> 10 min bazowo; T=5 min; budowa=5 min. Kolejka +10%: 10 min (bez czekania). | N10: =TEXT('Czas budowy'!Y32,"0")&" min bazowo; T="&TEXT('Czas budowy'!V32,"0")&" min; budowa="&TEXT('Czas budowy'!X32,"0")&" min. Kolejka +10%: "&TEXT('Czas budowy'!Y33,"0")&" min (bez czekania)." -> 20 min bazowo; T=10 min; budowa=10 min. Kolejka +10%: 20 min (bez czekania). | O10: =TEXT('Czas budowy'!Y34,"0")&" min bazowo; T="&TEXT('Czas budowy'!V34,"0")&" min; budowa="&TEXT('Czas budowy'!X34,"0")&" min. Kolejka +10%: "&TEXT('Czas budowy'!Y35,"0")&" min (bez czekania)." -> 20 min bazowo; T=10 min; budowa=10 min. Kolejka +10%: 30 min (bez czekania).
A11: Tartak | B11: Przetwarza 2 drewna z centrali→1 deskę do lokalnego bufora. | C11: Start: 0; limit 12 × WŁASNY poziom budynku, ograniczony liczbą istniejących dostępnych ludzi. Ratusz tylko ogranicza poziom rozbudowy. | D11: Własny poziom daje limit 12 × L pracowników i wydajność na osobę/h: 10, 12, 13, 14…; L1 = 10, L ≥ 2: L + 10. Bufor lokalny: 200 × Ratusz. | E11: 2L×(72 drewna+72 kamienia+120 desek) | F11: 2T = T transportu + T budowy | G11: Zasady uporządkowane; otwarte szczegóły w arkuszu Decyzje i konflikty. | H11: ZAWSZE: ukończenie budowy. Wcześniej także zlecenie/start/dostawa. Powiadomienie o pełnym magazynie. | I11: Pełny lokalny bufor: produkcja STOP, osobny modyfikator −10…−50. Brak surowca/miejsca powoduje brak pracy; podatek i bonus +1 przy blokadzie pozostają do decyzji. Droga: 5 min w każdą stronę; drewno i zboże przez centralę. | J11: patrz Premium. Doprecyzowane w kolejnej edycji | L11: Budynki!wiersz 11; potwierdzenia w Odpowiedzi i zmiany | M11: =TEXT('Czas budowy'!Y36,"0")&" min bazowo; T="&TEXT('Czas budowy'!V36,"0")&" min; budowa="&TEXT('Czas budowy'!X36,"0")&" min. Kolejka +10%: "&TEXT('Czas budowy'!Y37,"0")&" min (bez czekania)." -> 10 min bazowo; T=5 min; budowa=5 min. Kolejka +10%: 20 min (bez czekania). | N11: =TEXT('Czas budowy'!Y38,"0")&" min bazowo; T="&TEXT('Czas budowy'!V38,"0")&" min; budowa="&TEXT('Czas budowy'!X38,"0")&" min. Kolejka +10%: "&TEXT('Czas budowy'!Y39,"0")&" min (bez czekania)." -> 20 min bazowo; T=10 min; budowa=10 min. Kolejka +10%: 20 min (bez czekania). | O11: =TEXT('Czas budowy'!Y40,"0")&" min bazowo; T="&TEXT('Czas budowy'!V40,"0")&" min; budowa="&TEXT('Czas budowy'!X40,"0")&" min. Kolejka +10%: "&TEXT('Czas budowy'!Y41,"0")&" min (bez czekania)." -> 20 min bazowo; T=10 min; budowa=10 min. Kolejka +10%: 30 min (bez czekania).
A12: Kamieniołom | B12: Produkuje kamień do budowy i wymiany. | C12: Start: 0; limit 12 × WŁASNY poziom budynku, ograniczony liczbą istniejących dostępnych ludzi. Ratusz tylko ogranicza poziom rozbudowy. | D12: Własny poziom daje limit 12 × L pracowników i wydajność na osobę/h: 10, 12, 13, 14…; L1 = 10, L ≥ 2: L + 10. Bufor lokalny: 200 × Ratusz. | E12: 2L×(72 drewna+192 kamienia) | F12: 2T = T transportu + T budowy | G12: Zasady uporządkowane; otwarte szczegóły w arkuszu Decyzje i konflikty. | H12: ZAWSZE: ukończenie budowy. Wcześniej także zlecenie/start/dostawa. Powiadomienie o pełnym magazynie. | I12: Pełny lokalny bufor: produkcja STOP, osobny modyfikator −10…−50. Brak surowca/miejsca powoduje brak pracy; podatek i bonus +1 przy blokadzie pozostają do decyzji. Droga: 5 min w każdą stronę; drewno i zboże przez centralę. | J12: patrz Premium. Doprecyzowane w kolejnej edycji | L12: Budynki!wiersz 12; potwierdzenia w Odpowiedzi i zmiany | M12: =TEXT('Czas budowy'!Y42,"0")&" min bazowo; T="&TEXT('Czas budowy'!V42,"0")&" min; budowa="&TEXT('Czas budowy'!X42,"0")&" min. Kolejka +10%: "&TEXT('Czas budowy'!Y43,"0")&" min (bez czekania)." -> 10 min bazowo; T=5 min; budowa=5 min. Kolejka +10%: 10 min (bez czekania). | N12: =TEXT('Czas budowy'!Y44,"0")&" min bazowo; T="&TEXT('Czas budowy'!V44,"0")&" min; budowa="&TEXT('Czas budowy'!X44,"0")&" min. Kolejka +10%: "&TEXT('Czas budowy'!Y45,"0")&" min (bez czekania)." -> 20 min bazowo; T=10 min; budowa=10 min. Kolejka +10%: 20 min (bez czekania). | O12: =TEXT('Czas budowy'!Y46,"0")&" min bazowo; T="&TEXT('Czas budowy'!V46,"0")&" min; budowa="&TEXT('Czas budowy'!X46,"0")&" min. Kolejka +10%: "&TEXT('Czas budowy'!Y47,"0")&" min (bez czekania)." -> 20 min bazowo; T=10 min; budowa=10 min. Kolejka +10%: 30 min (bez czekania).
A13: Magazyn | B13: Przechowuje materiały; własna załoga nosi produkcję do centrali i materiały na budowy. Ludzie jedzą z centrali automatycznie. | C13: Start: 0; limit 12 × WŁASNY poziom budynku, ograniczony liczbą istniejących dostępnych ludzi. Ratusz tylko ogranicza poziom rozbudowy. | D13: Limit załogi: 12 × własny L; ładunek na kurs +10%/poziom. Pojemność ×1.5/poziom; magazyn/port: 1000 na rodzaj i 4000 łącznie na poziomie 1; targ: 1000 łącznie na poziomie 1. | E13: 300 × L każdego z 6 zasobów; w kolejce ×1,1. | F13: 2T = T transportu + T budowy | G13: Zasady uporządkowane; otwarte szczegóły w arkuszu Decyzje i konflikty. | H13: ZAWSZE: ukończenie budowy. Wcześniej także zlecenie/start/dostawa. Powiadomienie o pełnym magazynie. | I13: Rezerwa Food: 50 × poziom magazynu. Domyślnie uzupełnij centralę, potem budowy. Zmienne priorytety według budynku/zlecenia; ratunkowy 1 tragarz Food — próg do doprecyzowania. Pełny kurs: 5 min, 1 rodzaj towaru; niepełny ładunek wysyłany od razu. | J13: patrz Premium. Doprecyzowane w kolejnej edycji | K13: Transport. Nie rozróżniamy odległości, transport produków zawsze trwa 5 min z/do magazynu x capacity tragarza czyli jeżeli tragarz bierze 60 a potrzebuje przenieść 100 to I tak musi wykonać 2 kursy w jednym bierze 60 w drugim 40, tragarz nie może brać 2 produktow na raz, nie może czekać na towar. Jak klikam rozbudowa np drwala podświetla sie napis ile potrzeba surowców a ile zostało już dostarczonych np 60 /100 i estymowany czas zakońćzenia budowy czyli suma czasu transportu przy aktualnych ustawieniach priorytetów, i budowy. Z poziomu magazynu domyślne prirytety jest najpierw zaopatrz magazyn pózniej budowy, można je zmieniać, dodatkowo też można zmienić ustalić prio na konkretne gospodarstwo bądz konretną budowę, 1 tragarz zawsze będzie nosił żywność o ile jest wyprodukowana a w magazynie jest mniej niż 50 Premium szybszy transport do puntu odbioru | L13: Budynki!wiersz 13; potwierdzenia w Odpowiedzi i zmiany | M13: =TEXT('Czas budowy'!Y48,"0")&" min bazowo; T="&TEXT('Czas budowy'!V48,"0")&" min; budowa="&TEXT('Czas budowy'!X48,"0")&" min. Kolejka +10%: "&TEXT('Czas budowy'!Y49,"0")&" min (bez czekania)." -> 50 min bazowo; T=25 min; budowa=25 min. Kolejka +10%: 50 min (bez czekania). | N13: =TEXT('Czas budowy'!Y50,"0")&" min bazowo; T="&TEXT('Czas budowy'!V50,"0")&" min; budowa="&TEXT('Czas budowy'!X50,"0")&" min. Kolejka +10%: "&TEXT('Czas budowy'!Y51,"0")&" min (bez czekania)." -> 90 min bazowo; T=45 min; budowa=45 min. Kolejka +10%: 90 min (bez czekania). | O13: =TEXT('Czas budowy'!Y52,"0")&" min bazowo; T="&TEXT('Czas budowy'!V52,"0")&" min; budowa="&TEXT('Czas budowy'!X52,"0")&" min. Kolejka +10%: "&TEXT('Czas budowy'!Y53,"0")&" min (bez czekania)." -> 110 min bazowo; T=55 min; budowa=55 min. Kolejka +10%: 120 min (bez czekania).
A14: Targ | B14: Od poziomu gracza 2: wymiana w grupach drewno/kamień/zboże lub deski/żywność, nominalnie 1:1 z marżą 10%. Bez kupowania za monety. | C14: Start: 0; limit 12 × WŁASNY poziom budynku, ograniczony liczbą istniejących dostępnych ludzi. Ratusz tylko ogranicza poziom rozbudowy. | D14: Limit załogi: 12 × własny L; ładunek na kurs +10%/poziom. Pojemność ×1.5/poziom; magazyn/port: 1000 na rodzaj i 4000 łącznie na poziomie 1; targ: 1000 łącznie na poziomie 1. | E14: 300 × L każdego z 6 zasobów; w kolejce ×1,1. | F14: 2T = T transportu + T budowy | G14: Zasady uporządkowane; otwarte szczegóły w arkuszu Decyzje i konflikty. | H14: ZAWSZE: ukończenie budowy. Wcześniej także zlecenie/start/dostawa. Powiadomienie o pełnym magazynie. | I14: Własna załoga w obu kierunkach. Barter w 2 grupach, marża 10%, bez monet. Pozostaje blokada dostaw 1 h; zapas przepada po 24 h od przyniesienia/wymiany. | J14: patrz Premium. Doprecyzowane w kolejnej edycji | K14: Premium transport oneclick Ceny grupa 2 140/150 | L14: Budynki!wiersz 14; potwierdzenia w Odpowiedzi i zmiany | M14: =TEXT('Czas budowy'!Y54,"0")&" min bazowo; T="&TEXT('Czas budowy'!V54,"0")&" min; budowa="&TEXT('Czas budowy'!X54,"0")&" min. Kolejka +10%: "&TEXT('Czas budowy'!Y55,"0")&" min (bez czekania)." -> 50 min bazowo; T=25 min; budowa=25 min. Kolejka +10%: 50 min (bez czekania). | N14: =TEXT('Czas budowy'!Y56,"0")&" min bazowo; T="&TEXT('Czas budowy'!V56,"0")&" min; budowa="&TEXT('Czas budowy'!X56,"0")&" min. Kolejka +10%: "&TEXT('Czas budowy'!Y57,"0")&" min (bez czekania)." -> 90 min bazowo; T=45 min; budowa=45 min. Kolejka +10%: 90 min (bez czekania). | O14: =TEXT('Czas budowy'!Y58,"0")&" min bazowo; T="&TEXT('Czas budowy'!V58,"0")&" min; budowa="&TEXT('Czas budowy'!X58,"0")&" min. Kolejka +10%: "&TEXT('Czas budowy'!Y59,"0")&" min (bez czekania)." -> 110 min bazowo; T=55 min; budowa=55 min. Kolejka +10%: 120 min (bez czekania).
A15: Przystań | B15: Od poziomu gracza 4: kupno i sprzedaż pięciu materiałów za monety. Wyłącznie pełne paczki 100. Monety są środkiem płatności, nie osobnym towarem. | C15: Start: 0; limit 12 × WŁASNY poziom budynku, ograniczony liczbą istniejących dostępnych ludzi. Ratusz tylko ogranicza poziom rozbudowy. | D15: Limit załogi: 12 × własny L; ładunek na kurs +10%/poziom. Pojemność ×1.5/poziom; magazyn/port: 1000 na rodzaj i 4000 łącznie na poziomie 1; targ: 1000 łącznie na poziomie 1. | E15: 400 × L każdego z 6 zasobów; w kolejce ×1,1. | F15: 2T = T transportu + T budowy | G15: Zasady uporządkowane; otwarte szczegóły w arkuszu Decyzje i konflikty. | H15: ZAWSZE: ukończenie budowy. Wcześniej także zlecenie/start/dostawa. Powiadomienie o pełnym magazynie. | I15: Za 100: podstawowe 40/50, przetworzone 140/150. Podwyżka zakupu liniowo +10% w 3 h. Własna załoga, dwa cykle; statek = pojemność portu; płatność za sprzedaż przy wypłynięciu, za zakup przy przypłynięciu. Nieodebrane przez 24 h przepada, bez opłaty 10. | J15: patrz Premium. Doprecyzowane w kolejnej edycji | K15: Tempo załogi jak w magazynie, premium jak w magazynie | L15: Budynki!wiersz 15; potwierdzenia w Odpowiedzi i zmiany | M15: =TEXT('Czas budowy'!Y60,"0")&" min bazowo; T="&TEXT('Czas budowy'!V60,"0")&" min; budowa="&TEXT('Czas budowy'!X60,"0")&" min. Kolejka +10%: "&TEXT('Czas budowy'!Y61,"0")&" min (bez czekania)." -> 60 min bazowo; T=30 min; budowa=30 min. Kolejka +10%: 70 min (bez czekania). | N15: =TEXT('Czas budowy'!Y62,"0")&" min bazowo; T="&TEXT('Czas budowy'!V62,"0")&" min; budowa="&TEXT('Czas budowy'!X62,"0")&" min. Kolejka +10%: "&TEXT('Czas budowy'!Y63,"0")&" min (bez czekania)." -> 110 min bazowo; T=55 min; budowa=55 min. Kolejka +10%: 120 min (bez czekania). | O15: =TEXT('Czas budowy'!Y64,"0")&" min bazowo; T="&TEXT('Czas budowy'!V64,"0")&" min; budowa="&TEXT('Czas budowy'!X64,"0")&" min. Kolejka +10%: "&TEXT('Czas budowy'!Y65,"0")&" min (bez czekania)." -> 150 min bazowo; T=75 min; budowa=75 min. Kolejka +10%: 160 min (bez czekania).
A16: Kaplica | B16: Daje premie szczęścia i podatków po rozbudowie; dotychczas była miejscem ręcznych błogosławieństw. | C16: Brak etatów; wizyty nie są zatrudnieniem. | D16: +1 użycie dotychczasowego błogosławieństwa; rozbudowa do N: +10 × N szczęścia, podatki ×2 na 10 h. Kaplica = błogosławieństwo. | E16: TYMCZASOWO:N×(180 monet+20 drewna+60 kamienia+10 desek). N=nowy poziom. | F16: T transportu + 3T × (N − 1) budowy; N = nowy poziom. Łącznie: 4T, 7T, 10T… | G16: Zasady uporządkowane; otwarte szczegóły w arkuszu Decyzje i konflikty. | H16: ZAWSZE: ukończenie budowy. Wcześniej także zlecenie/start/dostawa. Uruchomienie premii i ręczne błogosławieństwo. | I16: Ręczne: +50 każdego zasobu, +20 szczęścia na 1 h; nowe odstępy i reklamy nadal odłożone. Wyjaśnienie dawnych notatek D09/D16 w arkuszu Decyzje i konflikty. | J16: patrz Premium. Doprecyzowane w kolejnej edycji | L16: Budynki!wiersz 16; potwierdzenia w Odpowiedzi i zmiany | M16: =TEXT('Czas budowy'!Y66,"0")&" min bazowo; T="&TEXT('Czas budowy'!V66,"0")&" min; budowa="&TEXT('Czas budowy'!X66,"0")&" min. Kolejka +10%: "&TEXT('Czas budowy'!Y67,"0")&" min (bez czekania)." -> 20 min bazowo; T=5 min; budowa=15 min. Kolejka +10%: 20 min (bez czekania). | N16: =TEXT('Czas budowy'!Y68,"0")&" min bazowo; T="&TEXT('Czas budowy'!V68,"0")&" min; budowa="&TEXT('Czas budowy'!X68,"0")&" min. Kolejka +10%: "&TEXT('Czas budowy'!Y69,"0")&" min (bez czekania)." -> 35 min bazowo; T=5 min; budowa=30 min. Kolejka +10%: 35 min (bez czekania). | O16: =TEXT('Czas budowy'!Y70,"0")&" min bazowo; T="&TEXT('Czas budowy'!V70,"0")&" min; budowa="&TEXT('Czas budowy'!X70,"0")&" min. Kolejka +10%: "&TEXT('Czas budowy'!Y71,"0")&" min (bez czekania)." -> 100 min bazowo; T=10 min; budowa=90 min. Kolejka +10%: 100 min (bez czekania).
A17: Latarnia | B17: Daje premie szczęścia i produkcji po ukończeniu poziomu. | C17: Brak etatów; wizyty nie są zatrudnieniem. | D17: Ustawia efektywne szczęście wszystkich na 100% i produkcję ×2 na 24 h × N. Latarnia = zwiedzanie; szczegóły wizyt nie zostały jeszcze opisane. | E17: 500×max(1, L) KAŻDEGO z 6 zasobów. Pierwsza budowa 0→1:500 każdego. | F17: 5T = T transportu + 4T budowy | G17: Zasady uporządkowane; otwarte szczegóły w arkuszu Decyzje i konflikty. | H17: ZAWSZE: ukończenie budowy. Wcześniej także zlecenie/start/dostawa. Uruchomienie premii latarni. | I17: 100% to nie +100; wszyscy mają maksymalne efektywne szczęście w czasie premii. Produkcja ×2, podatki i transport bez mnożnika. Wizyta niesprecyzowana, premium osobno. | J17: patrz Premium. Doprecyzowane w kolejnej edycji | K17: Nowe błogosławieństwo: kasa/challenge/udostępnienie/reklama. Zgodnie z decyzją użytkownika szczegóły ODŁOŻONE. Brak cen ani zatwierdzonej integracji. | L17: Budynki!wiersz 17; potwierdzenia w Odpowiedzi i zmiany | M17: =TEXT('Czas budowy'!Y72,"0")&" min bazowo; T="&TEXT('Czas budowy'!V72,"0")&" min; budowa="&TEXT('Czas budowy'!X72,"0")&" min. Kolejka +10%: "&TEXT('Czas budowy'!Y73,"0")&" min (bez czekania)." -> 200 min bazowo; T=40 min; budowa=160 min. Kolejka +10%: 225 min (bez czekania). | N17: =TEXT('Czas budowy'!Y74,"0")&" min bazowo; T="&TEXT('Czas budowy'!V74,"0")&" min; budowa="&TEXT('Czas budowy'!X74,"0")&" min. Kolejka +10%: "&TEXT('Czas budowy'!Y75,"0")&" min (bez czekania)." -> 350 min bazowo; T=70 min; budowa=280 min. Kolejka +10%: 375 min (bez czekania). | O17: =TEXT('Czas budowy'!Y76,"0")&" min bazowo; T="&TEXT('Czas budowy'!V76,"0")&" min; budowa="&TEXT('Czas budowy'!X76,"0")&" min. Kolejka +10%: "&TEXT('Czas budowy'!Y77,"0")&" min (bez czekania)." -> 450 min bazowo; T=90 min; budowa=360 min. Kolejka +10%: 500 min (bez czekania).
A18: CZŁOWIEK — ASSET | B18: Je, pracuje, produkuje/nosi, płaci podatki; własna historia szczęścia. | C18: 12 na starcie w domu; min. 6, max. 24 × Ratusz; jedno zatrudnienie, limit 12 × własny poziom budynku. | D18: Nie ulepsza się osoby poziomem; zmieniają się warunki życia i pracy. | E18: Utrzymanie: 1 Food/os./h; kupowania ludzi nie ustalono. | F18: Demografia zależy od średniego H, liczona zegarowo także offline. | G18: Karta Czlowiek zaktualizowana. | H18: Odejście, nigdy śmierć; nowy mieszkaniec zawsze w domu. | I18: +1 za jedzenie, +1 za pracę; po 12 h braku danego warunku −5; oba braki −10/h. Przeludnienie i osobne kary pełnego bufora. Podatki 1/h; wizyty po zdefiniowaniu. | J18: Brak oferty sprzedaży osób. | K18: Odejścia:najpierwDom,potemnajwiększazałoga;remisywgpriorytetów;patrzCzlowiek. | L18: Czlowiek/Ustalenia/Populacja; potwierdzeniaoffline. | M18: Nie dotyczy. | N18: Nie dotyczy. | O18: Nie dotyczy.

Sheet Czlowiek
A1: CZŁOWIEK • zaktualizowany asset
A2: Wersja 2: własny limit budynku 12×L, 5 min do pracy i 5 min do domu, cała gospodarka offline; nowi ludzie do Domu, ubytek to odejście. Latarnia ustawia 100%, nie dodaje 100. Tematy wizyt i zablokowanej produkcji oznaczone tam, gdzie brakuje szczegółów.
A5: Stan / obszar | B5: Zasada | C5: Wzór / liczby | D5: Konsekwencje | E5: Status
A6: Rola assetu | B6: Każda osoba ma trwałe ID, własne szczęście, stan pracy/pobytu i niezależne liczniki głodu oraz bezrobocia. | C6: 12 na starcie; minimum 6; maksimum 24 × poziom ratusza. | D6: Nowe osoby trafiają do domu. Ubytek oznacza odejście, nie śmierć. | E6: UZGODNIONE; NOWE DOPRECYZOWANIA
A7: Start i dom | B7: Na starcie wszyscy ludzie są w domu, bez przypisania do gospodarki. Z domu widać ich przydziały; można kierować do kaplicy i latarni. | C7: 12 w domu, 0 pracowników we wszystkich budynkach; każdy zasób na starcie 100. | D7: Przed pierwszym przydziałem nie ma produkcji ani podatków, ale ludzie jedzą. | E7: UZGODNIONE / NOWE
A8: Limit miejsca pracy | B8: Limit zależy od poziomu konkretnego miejsca pracy, nie samego ratusza. Jedna wspólna pula wolnych ludzi. | C8: 0…12 × poziom budynku; nowy przydział ograniczony faktycznie wolnymi osobami w domu. | D8: Ratusz 2 i drwale 1: limit drwali nadal 12. Drwale 2: limit 24, jeżeli tylu wolnych istnieje. Nie wolno ulepszyć ponad ratusz. | E8: ZMIENIONE I WYJAŚNIONE
A9: Jedzenie | B9: Każdy je automatycznie wyłącznie z magazynu centralnego, niezależnie od pracy lub drogi. | C9: 1 Food/os./h zegarowej. | D9: Lokalny młyn, targ i port nie karmią bez przewiezienia do centrali. Rezerwę można zjadać. | E9: UZGODNIONE; CZAS ZEGAROWY
A10: Rezerwa jedzenia | B10: Rezerwa na żywienie rośnie z poziomem magazynu. Operacje nieżywieniowe mają ją zachować. | C10: Minimum Food = 50 × poziom magazynu. | D10: Osobny wpis mówi o tragarzu żywności dopiero poniżej 50; próg 50 kontra 50 × poziom pozostaje do ujednolicenia. | E10: NOWE; PRÓG TRAGARZA DO DECYZJI | H10: Decyzja 50 x level
A11: Praca producenta | B11: Wydajność na osobę wynika z własnego poziomu producenta. | C11: Poziomy 1,2,3,4: dokładnie 10,12,13,14 szt./h; dalej +1 szt./h na poziom. | D11: Wybrany dosłowny ciąg zastępuje sprzeczny ogólny zapis +10%. Głód ×0,5, premia latarni ×2. | E11: POTWIERDZONE W ODPOWIEDZI
A12: Całe sztuki | B12: Każdy pracownik nalicza własny postęp; niedokończone części różnych osób nie łączą się. Zwolnienie odrzuca jego niedokończoną sztukę. | C12: Na poziomie 1: jedna sztuka/6 min; po 7 min 1, po 13 min 2. Na wyższych poziomach odstęp = 3600 / wydajność sekund. | D12: Gotowy produkt zostaje w lokalnym buforze i wymaga transportu. | E12: UZGODNIONE; DOSTOSOWANE DO WYDAJNOŚCI
A13: Przeróbka | B13: Młyn i tartak zużywają surowce centralne; zboże i drewno idą przez magazyn. | C13: 2 zboża → 1 Food; 2 drewna → 1 deska. | D13: Brak surowca lub miejsca zatrzymuje pracę. Nowy wpis nakazuje karę za brak pracy także mimo przypisania; szczegóły podatku do decyzji. | E13: UZGODNIONE + NOWY PRZESTÓJ | G13: podatek płaci ale jest mniej szczęsliwy
A14: Transport | B14: Tragarz wiezie jeden rodzaj towaru, nie czeka na pełne obłożenie. Pojemność to ładunek na kurs, nie sztuki na godzinę. | C14: Poziom 1: 60 szt./kurs; pełny kurs z powrotem 5 min; pojemność rośnie o 10% na poziom miejsca pracy. | D14: 100 jednego towaru wymaga dwóch kursów: 60 i 40. Magazyn, targ i port stosują takie same bazowe zasady; własne załogi. | E14: POTWIERDZONE; ZAOKRĄGLENIE POJEMNOŚCI DO DECYZJI
A15: Podatek przy pracy | B15: Pracujący płaci podatek, bezrobotny lub idący do domu nie płaci. Premia kaplicy podwaja dochód. | C15: 1 moneta/os./h zegarowej; podczas premii kaplicy 2. | D15: Dla osoby przypisanej, ale zablokowanej brakiem surowca lub miejsca, nowe zasady wymagają kary za brak pracy; dalsze naliczanie podatku nie zostało rozstrzygnięte. | E15: UZGODNIONE; PODATEK PODCZAS PRZESTOJU DO DECYZJI | G15: podatek płaci przez cały czas
A16: Je i pracuje | B16: Sumują się bonus jedzenia i bonus pracy. | C16: +1 pp/h za jedzenie +1 pp/h za pracę = +2 pp/h. | D16: Od osobistego 0% po 10 h takiego stanu ma 20%. | E16: UZGODNIONE
A17: Je, bez pracy do 12 h | B17: Jedzenie daje bonus; pierwszy ciągły okres bezrobocia nie jest jeszcze karany. | C17: +1 pp/h. | D17: Po 10 h pracy i jedzenia ma 20%; następne 12 h jedzenia bez pracy daje 32%. | E17: UZGODNIONE
A18: Je, bez pracy ponad 12 h | B18: Po okresie bez kary dochodzi kara bezrobocia. | C18: +1 za jedzenie −5 za bezrobocie = −4 pp/h. | D18: Po powyższym 32% następna godzina bezrobocia daje 28%. | E18: UZGODNIONE
A19: Nie je do 12 h, pracuje | B19: Nie dostaje bonusu jedzenia, dostaje bonus pracy; jeszcze bez kary głodu. | C19: +1 pp/h; wydajność pracy 50% od początku głodu. | D19: Podatek pracującego nie zmniejsza się z powodu głodu. | E19: UZGODNIONE
A20: Nie je ponad 12 h, pracuje | B20: Po okresie bez kary dochodzi kara głodu. | C20: +1 za pracę −5 za głód = −4 pp/h. | D20: Wydajność 50%; podatek pracującego nadal 1 moneta/h przed premią kaplicy. | E20: UZGODNIONE
A21: Nie je i nie pracuje | B21: Głód i bezrobocie liczą się niezależnie i sumują. | C21: 0 pp/h, gdy oba braki <12 h; −5 pp/h, gdy tylko jeden przekroczył próg; −10 pp/h, gdy oba. | D21: Brak produkcji i podatku. Progi nie muszą wystąpić jednocześnie. | E21: UZGODNIONE
A22: Resety | B22: Jedzenie resetuje tylko głód, a podjęcie pracy tylko bezrobocie. Brak naliczania kary wstecz. | C22: Każdy brak ma osobne 12 ciągłych godzin bez kary. | D22: Reset licznika nie oddaje utraconego szczęścia i nie kasuje historii człowieka. Przestój rzeczywistej pracy wymaga doprecyzowania tego resetu. | E22: UZGODNIONE; PRZESTÓJ DO DOPRECYZOWANIA | G22: wytłumaczone poniżej
A23: Droga do pracy | B23: Po wysłaniu do nowego miejsca pracy osoba idzie przez ustalony czas. | C23: 5 min do pracy. | D23: W drodze nie produkuje. Podatek i bonus pracy w czasie dojścia nie zostały określone osobno; proponowany brak pracy do chwili dojścia należy oznaczyć jako propozycję. | E23: NOWE; EFEKTY W DRODZE DO USTALENIA | G23: tak, zaczyna pracować I płacić podatek jak dociera do zakładu,
A24: Powrót do domu | B24: Zwolniony zawsze wraca do domu; dopiero po powrocie może być ponownie przydzielony. | C24: 5 min do domu. | D24: Nie pracuje, nie płaci podatku; je i jest liczony jako bezrobotny od zwolnienia. Zachowuje ID oraz szczęście. | E24: UZGODNIONE
A25: Przestój gospodarczy | B25: Brak surowca lub miejsca zatrzymuje produkcję i według nowej notatki powoduje karę za brak pracy. | C25: Docelowo zastosowanie kary bezrobocia −5 pp/h po 12 h wymaga zgodności z dotychczasowym algorytmem. | D25: Nie wiadomo, czy nadal działa +1 za przypisanie, czy płynie podatek i kiedy resetuje się licznik. Nie zapisano tego jako gotowej decyzji. | E25: NOWE; SZCZEGÓŁY DO DECYZJI | G25: zatosuj karę I logikę jak linia niżej
A26: Pełny lokalny magazyn | B26: Produkcja staje. Kara szczęścia dotyczy załogi zapełnionego budynku. | C26: −10 od razu; po 24 h −20, 48 h −30, 72 h −40, 96 h i dalej −50. | D26: Nigdy mniej niż −50 z tego tytułu. To osobny modyfikator, nie −10 pp/h. Opróżnienie poniżej limitu usuwa ten modyfikator. Nowa kara przestoju może być drugą karą — do rozstrzygnięcia. | E26: UZGODNIONE + NOWY PRZESTÓJ | G26: tu nie ma kwestii opróżnienia poniżej limitu. Lokalny magazyn pridukcji może być całkiem opóźniony kara jest tylko wtedy gdy magazyn okalny blokuje produkcje - dottczy tylko tych ludków co są w tym przedsiębiorstwie na czas przestoju, jak kliknę aby przeszli do domu, to po drodze ich licznik sie resetuje do 0, jak będę ich trzymał mimo braku odbiorów do magazynu głównego to ich szczęscie spada do -50 nie wiecej
A27: Przeludnienie | B27: Brak miejsca w domu zmniejsza szczęście każdej osoby; limit populacji nadal wyznacza ratusz. | C27: U = max(0, populacja − 24 × poziom domu); każdemu −U pp/h. | D27: 78 osób i 72 miejsca → −6 pp/h każdej osobie. Zapewnienie miejsc zatrzymuje przyszłą karę, bez zwrotu utraconych punktów. | E27: UZGODNIONE
A28: Kaplica: premia poziomu | B28: Rozbudowa do N daje bonus szczęścia i podatków; poziom 1 bez pasywnej premii. | C28: +10 × N szczęścia wszystkim i podatki ×2 przez 10 h zegarowych. | D28: Premia czasowa, nie +10 × N pp co godzinę. Kolejna rozbudowa odświeża okres, nie robi podatków ×4. | E28: UZGODNIONE
A29: Kaplica: błogosławieństwo | B29: Ręczne błogosławieństwo należy do kaplicy; latarnia oferuje zwiedzanie. | C29: Dotychczas +50 każdego zasobu i +20 szczęścia wszystkim na 1 h. | D29: Nowe odstępy, płatne użycia, reklamy i konflikt natychmiastowego użycia pozostają odłożone. Przydział ludzi do wizyty i zasięg nagrody wymagają osobnej reguły. | E29: NAZWA WYJAŚNIONA; NOWE OFERTY ODŁOŻONE | G29: płatne błogosławieństwo kosztuje 100 x level, efekt daje taki sam, nie można mieć ich wiecej niż 1 na 4 h
A30: Latarnia: premia poziomu | B30: W czasie premii wszyscy mają maksymalne szczęście, a produkcja materiałów jest podwojona. | C30: Szczęście USTAWIONE NA100%, nie +100; produkcja ×2. Obie premie 24 h × N. | D30: Osoba −50% ma mieć 100%, nie 50%. Nie ustalono jeszcze, jak powrócić do osobistej wartości po końcu tej wymuszonej premii. Podatki i transport bez mnożnika latarni. | E30: NOWA ZMIANA; ZAKOŃCZENIE EFEKTU DO DOPRECYZOWANIA | G30: po ustaniu premi wracamy do stanu sprzed premii
A31: Latarnia: zwiedzanie | B31: Dom pozwala wysłać mieszkańca do latarni na zwiedzanie prowadzące do premii. | C31: Czas pobytu i konkretna premia za wizytę nie zostały określone. | D31: Nie należy utożsamiać automatycznie bonusu wizyty z globalną premią rozbudowy latarni. | E31: NOWE; DO USTALENIA | G31: czas pobytu 4 h, ilosć pracowników jakich mogę wysłać 2 x poziom, mogę wtsłać tylko pracowników z domu, podnoszą poziom szczęścia tym którzy idą zwiedzać do 100% niezależnie od stanu wcześniej na 24 h, całości dają + 10 % na 6 , człowiek nie płaci wtedy podatku, je normalnie
A32: Średnia i prezentacja | B32: Osobiste wartości ograniczamy do −100…+100%, następnie liczymy średnią populacji. | C32: H wyspy = suma H osób / populacja. | D32: Pokazujemy pełne procenty zaokrąglone w górę. W obliczeniach zachowujemy ułamki. Czasowy force 100 latarni jest wyjątkiem wymagającym obsługi końca efektu. | E32: UZGODNIONE + NOWA LATARNIA
A33: Tempo demografii | B33: Dodatnia dokładna średnia daje przyrost, ujemna odejścia, 0% brak zmiany. | C33: ±25%: 1/12 h; ±50%: 1/6 h; ±75%: około 1/1 h 43 min; ±100%: 1/h. | D33: Odejścia mają symetryczne tempo do przyrostu. Minimum 6; maksimum 24 × ratusz, nie pojemność domu. | E33: UZGODNIONE I POTWIERDZONE
A34: Nowy mieszkaniec | B34: Nowa osoba zawsze trafia do domu i jest dostępna z domowej puli. | C34: Wcześniejszy model: własne szczęście 0% przed aktualnymi premiami wyspy. | D34: Nie przydziela się automatycznie do produkcji. Brak mieszkań może uruchomić karę przeludnienia. | E34: NOWE MIEJSCE; SZCZĘŚCIE 0 PRZYJĘTE WCZEŚNIEJ W MODELU
A35: Odejście mieszkańca | B35: Najpierw odchodzą osoby z domu. Jeśli ich brak, z gospodarstwa o największej obsadzie. | C35: Przy remisie: port → tartak → kamieniołom → drwale → na końcu produkcja żywności i transport. | D35: Kolejność targu, rozróżnienie farmy/młyna, ludzi w drodze lub na wizytach nie zostały określone. Nigdy poniżej 6 osób. | E35: NOWE; NIEPEŁNA KOLEJNOŚĆ REMISÓW | G35: opisane w innym miejscu
A36: Czas świata | B36: Wszystkie procesy działają w czasie rzeczywistym zegarowym także po zamknięciu karty i wylogowaniu. | C36: Produkcja, jedzenie, szczęście, podatki, budowy i zegary także offline. | D36: Przyspieszenia mają działać czasowo z premiami; dokładne mnożniki i zakres przyspieszeń są jeszcze nieustalone. To zastępuje wcześniejsze zatrzymywanie po ukryciu/offline. | E36: POTWIERDZONE W ODPOWIEDZI | G36: tak, trzeba usunąć ikonkę stop, play przwin
A37: Ranking | B37: Ranking w ustawieniach według poziomu i posiadanych monet. | C37: Wynik = poziom ratusza × ilość złota. | D37: Moment aktualizacji i remisy nie zostały doprecyzowane. Wydanie monet może obniżyć wynik. | E37: NOWE | G37: aktualizacja o każdej pełnej godzinie wg stanu zastanego

Sheet Produkcja
A1: PRODUKCJA I ŁADUNEK • korzyść własnego poziomu
A2: Użytkownik potwierdził dokładnie 10, 12, 13, 14… zamiast ogólnego +10%. Poziom producenta wpływa na wydajność i limit 12 × L; Ratusz jest warunkiem rozbudowy. Ładunek dotyczy własnego poziomu budynku transportowego; głód obniża efektywną wydajność transportu o połowę.
A5: Poziom budynku | B5: Wydajność/os./h | C5: Wydajność głodnego/os./h | D5: Limit załogi | E5: Ładunek magazyn/targ/port | F5: Uwagi
A6: 1 | B6: =IF(A6=1,10,A6+10) -> 10 | C6: =B6/2 -> 5 | D6: =A6*Parametry!$C$8 -> 12 | E6: =ROUNDDOWN(Parametry!$C$9*Parametry!$C$10^(A6-1),0) -> 60 | F6: Każda osoba osobno; całe sztuki i własna faza pracy. Młyn/tartak nadal 2:1. Bufor lokalny nadal 200×Ratusz.
A7: 2 | B7: =IF(A7=1,10,A7+10) -> 12 | C7: =B7/2 -> 6 | D7: =A7*Parametry!$C$8 -> 24 | E7: =ROUNDDOWN(Parametry!$C$9*Parametry!$C$10^(A7-1),0) -> 66 | F7: Każda osoba osobno; całe sztuki i własna faza pracy. Młyn/tartak nadal 2:1. Bufor lokalny nadal 200×Ratusz.
A8: 3 | B8: =IF(A8=1,10,A8+10) -> 13 | C8: =B8/2 -> 6.5 | D8: =A8*Parametry!$C$8 -> 36 | E8: =ROUNDDOWN(Parametry!$C$9*Parametry!$C$10^(A8-1),0) -> 72 | F8: Każda osoba osobno; całe sztuki i własna faza pracy. Młyn/tartak nadal 2:1. Bufor lokalny nadal 200×Ratusz.
A9: 4 | B9: =IF(A9=1,10,A9+10) -> 14 | C9: =B9/2 -> 7 | D9: =A9*Parametry!$C$8 -> 48 | E9: =ROUNDDOWN(Parametry!$C$9*Parametry!$C$10^(A9-1),0) -> 79 | F9: Każda osoba osobno; całe sztuki i własna faza pracy. Młyn/tartak nadal 2:1. Bufor lokalny nadal 200×Ratusz.
A10: 5 | B10: =IF(A10=1,10,A10+10) -> 15 | C10: =B10/2 -> 7.5 | D10: =A10*Parametry!$C$8 -> 60 | E10: =ROUNDDOWN(Parametry!$C$9*Parametry!$C$10^(A10-1),0) -> 87 | F10: Każda osoba osobno; całe sztuki i własna faza pracy. Młyn/tartak nadal 2:1. Bufor lokalny nadal 200×Ratusz.
A11: 6 | B11: =IF(A11=1,10,A11+10) -> 16 | C11: =B11/2 -> 8 | D11: =A11*Parametry!$C$8 -> 72 | E11: =ROUNDDOWN(Parametry!$C$9*Parametry!$C$10^(A11-1),0) -> 96 | F11: Każda osoba osobno; całe sztuki i własna faza pracy. Młyn/tartak nadal 2:1. Bufor lokalny nadal 200×Ratusz.
A12: 7 | B12: =IF(A12=1,10,A12+10) -> 17 | C12: =B12/2 -> 8.5 | D12: =A12*Parametry!$C$8 -> 84 | E12: =ROUNDDOWN(Parametry!$C$9*Parametry!$C$10^(A12-1),0) -> 106 | F12: Każda osoba osobno; całe sztuki i własna faza pracy. Młyn/tartak nadal 2:1. Bufor lokalny nadal 200×Ratusz.
A13: 8 | B13: =IF(A13=1,10,A13+10) -> 18 | C13: =B13/2 -> 9 | D13: =A13*Parametry!$C$8 -> 96 | E13: =ROUNDDOWN(Parametry!$C$9*Parametry!$C$10^(A13-1),0) -> 116 | F13: Każda osoba osobno; całe sztuki i własna faza pracy. Młyn/tartak nadal 2:1. Bufor lokalny nadal 200×Ratusz.
A14: 9 | B14: =IF(A14=1,10,A14+10) -> 19 | C14: =B14/2 -> 9.5 | D14: =A14*Parametry!$C$8 -> 108 | E14: =ROUNDDOWN(Parametry!$C$9*Parametry!$C$10^(A14-1),0) -> 128 | F14: Każda osoba osobno; całe sztuki i własna faza pracy. Młyn/tartak nadal 2:1. Bufor lokalny nadal 200×Ratusz.
A15: 10 | B15: =IF(A15=1,10,A15+10) -> 20 | C15: =B15/2 -> 10 | D15: =A15*Parametry!$C$8 -> 120 | E15: =ROUNDDOWN(Parametry!$C$9*Parametry!$C$10^(A15-1),0) -> 141 | F15: Każda osoba osobno; całe sztuki i własna faza pracy. Młyn/tartak nadal 2:1. Bufor lokalny nadal 200×Ratusz.

Sheet Ustalenia - uwagi
A1: USTALENIA V2 • starsze wartości zastąpione jawnie
A2: Pełny rejestr dotychczasowych ustaleń z aktualizacją po pliku 1 i odpowiedziach. ZASTĄPIONE oznacza historię, nie obecną zasadę. Nowe komentarze źródłowe zachowano osobno. Bez implementacji w grze.
A5: ID | B5: Obszar | C5: Assety | D5: Status | E5: Zasada | F5: Uwagi / źródło
A6: U001 | B6: Start | C6: Wszystkie | D6: AKTUALNE | E6: Nowa wyspa: Ratusz 1, Dom 1,12 mieszkańców, szczęście 0; 100 każdego zasobu. | F6: Zasoby: monety, drewno, kamień, zboże, Food, deski.
A7: U002 | B7: Start | C7: Człowiek | D7: NOWSZE USTALENIE | E7: W gospodarce 0 pracowników na starcie; 12 wolnych ludzi do ręcznego przydziału. | F7: Zastępuje wcześniejsze 6 startowych przydziałów.
A8: U003 | B8: Start | C8: Wszystkie | D8: AKTUALNE | E8: Odświeżenie zachowuje postęp; zestaw startowy nie jest przyznawany ponownie. | F8: Logowanie i serwer to przyszły zakres; plik Excel niczego nie wdraża.
A9: U004 | B9: Poziom | C9: Ratusz | D9: AKTUALNE | E9: Poziom gracza=poziom Ratusza. | F9: Ratusz nie zatrudnia pracowników.
A10: U005 | B10: Poziom | C10: Wszystkie | D10: AKTUALNE | E10: Pozostałe budynki mogą mieć najwyżej poziom Ratusza. | F10: Podniesienie ratusza odblokowuje możliwość rozbudowy, nie wykonuje jej za gracza.
A11: U006 | B11: Ludność | C11: Ratusz | D11: AKTUALNE | E11: Teoretyczny limit mieszkańców=24×poziom Ratusza. | F11: Przykład Ratusz 4→96; Ratusz 6→144. To limit, nie automatyczna liczba osób.
A12: U007 | B12: Mieszkania | C12: Dom | D12: AKTUALNE | E12: Dom daje 24×swój poziom miejsc mieszkalnych. | F12: Ratusz i Dom mają niezależne limity; Ratusz 4, Dom 3→limit 96, miejsca 72.
A13: U008 | B13: Mieszkania | C13: Dom;Człowiek | D13: AKTUALNE | E13: Przeludnienie U=max(0, P−24×poziom Domu). Każdej osobie naliczamy−Upp/h. | F13: 78 osób/72 miejsca→−6 pp/h każdemu; kara sumuje się z innymi stawkami.
A14: U009 | B14: Mieszkania | C14: Dom;Człowiek | D14: AKTUALNE | E14: Nowe miejsca po ukończeniu Domu zatrzymują przyszłą karę w pokrytym zakresie, bez zwracania utraconego szczęścia. | F14: Nie ma natychmiastowego dodania ludzi po rozbudowie.
A15: U010 | B15: Limit pracy | C15: Człowiek;Wszystkie | D15: POTWIERDZONE V2 | E15: Limit każdego miejsca pracy=12×POZIOM TEGO BUDYNKU, ograniczony faktyczną pulą wolnych. | F15: Drwale 1:max 12; Ratusz 2 bezdrwali 2 nicniezmienia; drwale 2:max 24.
A16: U011 | B16: Limit pracy | C16: Człowiek;Wszystkie | D16: ZASTĄPIONE | E16: Wcześniej limit zapisano jako połowę aktualnej populacji. | F16: W tym Excelu po najnowszym doprecyzowaniu obowiązuje połowa MAKSIMUM z Ratusza.
... A135: V2-038 | B135: Premium i pytania | C135: Kaplica; Latarnia; Wszystkie | D135: ODŁOŻONE | E135: Nowe oferty, reklamy, challenge i social pozostają do późniejszego opisania. | F135: Uwagi „nie rozumiem” przy dawnych cooldownach nie są zatwierdzeniem mechaniki; wyjaśnić prostym językiem. Źródło: Decyzje i konflikty! I14; I20; I22

Sheet Czas budowy
A1: NOWE CZASY • liczymy kursy, nie sztuki na godzinę
A2: Potwierdzone:5 min cały kurs, 1 rodzaj na kurs; 6 tragarzy faktycznie dostępnych; materiały gotowe, bez zbierania, karmienia, wcześniejszych rozbudów i oczekiwania. Osobny wariant+10%kolejki zwiększa koszt i liczbę kursów. Pojemność bazowa 60, magazyn L→floor(60×1.1^(L−1)).
A5: Budynek | B5: Etap | C5: Tryb kosztu | D5: Obecny L | E5: Nowy N | F5: Poziom magazynu | G5: Dostępni tragarze | H5: Ładunek/os./kurs | I5: Monety | J5: Drewno | K5: Kamień | L5: Zboże | M5: Food | N5: Deski | O5: Kursy drewno | P5: Kursy kamień | Q5: Kursy zboże | R5: Kursy Food | S5: Kursy deski | T5: Kursy razem | U5: Fale | V5: Transport T [min] | W5: Łącznie ×T | X5: Sama budowa [min] | Y5: Razem [min] | Z5: Materiały razem | AA5: Założenia
A6: Ratusz | B6: 1→2 | C6: Bez kolejki | D6: 1 | E6: =D6+1 -> 2 | F6: 1 | G6: =Parametry!$C$12 -> 6 | H6: =ROUNDDOWN(Parametry!$C$9*Parametry!$C$10^(F6-1),0) -> 60 | I6: =ROUNDUP((Parametry!$C$20*MAX(1,D6))*1,0) -> 500 | J6: =ROUNDUP((Parametry!$C$20*MAX(1,D6))*1,0) -> 500 | K6: =ROUNDUP((Parametry!$C$20*MAX(1,D6))*1,0) -> 500 | L6: =ROUNDUP((Parametry!$C$20*MAX(1,D6))*1,0) -> 500 | M6: =ROUNDUP((Parametry!$C$20*MAX(1,D6))*1,0) -> 500 | N6: =ROUNDUP((Parametry!$C$20*MAX(1,D6))*1,0) -> 500 | O6: =ROUNDUP(J6/H6,0) -> 9 | P6: =ROUNDUP(K6/H6,0) -> 9 | Q6: =ROUNDUP(L6/H6,0) -> 9 | R6: =ROUNDUP(M6/H6,0) -> 9 | S6: =ROUNDUP(N6/H6,0) -> 9 | T6: =SUM(O6:S6) -> 45 | U6: =ROUNDUP(T6/G6,0) -> 8 | V6: =U6*Parametry!$C$11 -> 40 | W6: =2 -> 2 | X6: =V6*(W6-1) -> 40 | Y6: =V6*W6 -> 80 | Z6: =SUM(J6:N6) -> 2500 | AA6: Tylko ta budowa; 6 dostępnych po uwzględnieniu priorytetów; poziom magazynu=scenariusz L. Jeśli priorytety blokują dostawy, rzeczywiste ETA rośnie.
A7: Ratusz | B7: 1→2 | C7: Kolejka +10% | D7: 1 | E7: =D7+1 -> 2 | F7: 1 | G7: =Parametry!$C$12 -> 6 | H7: =ROUNDDOWN(Parametry!$C$9*Parametry!$C$10^(F7-1),0) -> 60 | I7: =ROUNDUP((Parametry!$C$20*MAX(1,D7))*Parametry!$C$15,0) -> 550 | J7: =ROUNDUP((Parametry!$C$20*MAX(1,D7))*Parametry!$C$15,0) -> 550 | K7: =ROUNDUP((Parametry!$C$20*MAX(1,D7))*Parametry!$C$15,0) -> 550 | L7: =ROUNDUP((Parametry!$C$20*MAX(1,D7))*Parametry!$C$15,0) -> 550 | M7: =ROUNDUP((Parametry!$C$20*MAX(1,D7))*Parametry!$C$15,0) -> 550 | N7: =ROUNDUP((Parametry!$C$20*MAX(1,D7))*Parametry!$C$15,0) -> 550 | O7: =ROUNDUP(J7/H7,0) -> 10 | P7: =ROUNDUP(K7/H7,0) -> 10 | Q7: =ROUNDUP(L7/H7,0) -> 10 | R7: =ROUNDUP(M7/H7,0) -> 10 | S7: =ROUNDUP(N7/H7,0) -> 10 | T7: =SUM(O7:S7) -> 50 | U7: =ROUNDUP(T7/G7,0) -> 9 | V7: =U7*Parametry!$C$11 -> 45 | W7: =2 -> 2 | X7: =V7*(W7-1) -> 45 | Y7: =V7*W7 -> 90 | Z7: =SUM(J7:N7) -> 2750 | AA7: Tylko ta budowa; 6 dostępnych po uwzględnieniu priorytetów; poziom magazynu=scenariusz L. Jeśli priorytety blokują dostawy, rzeczywiste ETA rośnie.
A8: Ratusz | B8: 2→3 | C8: Bez kolejki | D8: 2 | E8: =D8+1 -> 3 | F8: 2 | G8: =Parametry!$C$12 -> 6 | H8: =ROUNDDOWN(Parametry!$C$9*Parametry!$C$10^(F8-1),0) -> 66 | I8: =ROUNDUP((Parametry!$C$20*MAX(1,D8))*1,0) -> 1000 | J8: =ROUNDUP((Parametry!$C$20*MAX(1,D8))*1,0) -> 1000 | K8: =ROUNDUP((Parametry!$C$20*MAX(1,D8))*1,0) -> 1000 | L8: =ROUNDUP((Parametry!$C$20*MAX(1,D8))*1,0) -> 1000 | M8: =ROUNDUP((Parametry!$C$20*MAX(1,D8))*1,0) -> 1000 | N8: =ROUNDUP((Parametry!$C$20*MAX(1,D8))*1,0) -> 1000 | O8: =ROUNDUP(J8/H8,0) -> 16 | P8: =ROUNDUP(K8/H8,0) -> 16 | Q8: =ROUNDUP(L8/H8,0) -> 16 | R8: =ROUNDUP(M8/H8,0) -> 16 | S8: =ROUNDUP(N8/H8,0) -> 16 | T8: =SUM(O8:S8) -> 80 | U8: =ROUNDUP(T8/G8,0) -> 14 | V8: =U8*Parametry!$C$11 -> 70 | W8: =2 -> 2 | X8: =V8*(W8-1) -> 70 | Y8: =V8*W8 -> 140 | Z8: =SUM(J8:N8) -> 5000 | AA8: Tylko ta budowa; 6 dostępnych po uwzględnieniu priorytetów; poziom magazynu=scenariusz L. Jeśli priorytety blokują dostawy, rzeczywiste ETA rośnie.
A9: Ratusz | B9: 2→3 | C9: Kolejka +10% | D9: 2 | E9: =D9+1 -> 3 | F9: 2 | G9: =Parametry!$C$12 -> 6 | H9: =ROUNDDOWN(Parametry!$C$9*Parametry!$C$10^(F9-1),0) -> 66 | I9: =ROUNDUP((Parametry!$C$20*MAX(1,D9))*Parametry!$C$15,0) -> 1100 | J9: =ROUNDUP((Parametry!$C$20*MAX(1,D9))*Parametry!$C$15,0) -> 1100 | K9: =ROUNDUP((Parametry!$C$20*MAX(1,D9))*Parametry!$C$15,0) -> 1100 | L9: =ROUNDUP((Parametry!$C$20*MAX(1,D9))*Parametry!$C$15,0) -> 1100 | M9: =ROUNDUP((Parametry!$C$20*MAX(1,D9))*Parametry!$C$15,0) -> 1100 | N9: =ROUNDUP((Parametry!$C$20*MAX(1,D9))*Parametry!$C$15,0) -> 1100 | O9: =ROUNDUP(J9/H9,0) -> 17 | P9: =ROUNDUP(K9/H9,0) -> 17 | Q9: =ROUNDUP(L9/H9,0) -> 17 | R9: =ROUNDUP(M9/H9,0) -> 17 | S9: =ROUNDUP(N9/H9,0) -> 17 | T9: =SUM(O9:S9) -> 85 | U9: =ROUNDUP(T9/G9,0) -> 15 | V9: =U9*Parametry!$C$11 -> 75 | W9: =2 -> 2 | X9: =V9*(W9-1) -> 75 | Y9: =V9*W9 -> 150 | Z9: =SUM(J9:N9) -> 5500 | AA9: Tylko ta budowa; 6 dostępnych po uwzględnieniu priorytetów; poziom magazynu=scenariusz L. Jeśli priorytety blokują dostawy, rzeczywiste ETA rośnie.
A10: Ratusz | B10: 3→4 | C10: Bez kolejki | D10: 3 | E10: =D10+1 -> 4 | F10: 3 | G10: =Parametry!$C$12 -> 6 | H10: =ROUNDDOWN(Parametry!$C$9*Parametry!$C$10^(F10-1),0) -> 72 | I10: =ROUNDUP((Parametry!$C$20*MAX(1,D10))*1,0) -> 1500 | J10: =ROUNDUP((Parametry!$C$20*MAX(1,D10))*1,0) -> 1500 | K10: =ROUNDUP((Parametry!$C$20*MAX(1,D10))*1,0) -> 1500 | L10: =ROUNDUP((Parametry!$C$20*MAX(1,D10))*1,0) -> 1500 | M10: =ROUNDUP((Parametry!$C$20*MAX(1,D10))*1,0) -> 1500 | N10: =ROUNDUP((Parametry!$C$20*MAX(1,D10))*1,0) -> 1500 | O10: =ROUNDUP(J10/H10,0) -> 21 | P10: =ROUNDUP(K10/H10,0) -> 21 | Q10: =ROUNDUP(L10/H10,0) -> 21 | R10: =ROUNDUP(M10/H10,0) -> 21 | S10: =ROUNDUP(N10/H10,0) -> 21 | T10: =SUM(O10:S10) -> 105 | U10: =ROUNDUP(T10/G10,0) -> 18 | V10: =U10*Parametry!$C$11 -> 90 | W10: =2 -> 2 | X10: =V10*(W10-1) -> 90 | Y10: =V10*W10 -> 180 | Z10: =SUM(J10:N10) -> 7500 | AA10: Tylko ta budowa; 6 dostępnych po uwzględnieniu priorytetów; poziom magazynu=scenariusz L. Jeśli priorytety blokują dostawy, rzeczywiste ETA rośnie.
A11: Ratusz | B11: 3→4 | C11: Kolejka +10% | D11: 3 | E11: =D11+1 -> 4 | F11: 3 | G11: =Parametry!$C$12 -> 6 | H11: =ROUNDDOWN(Parametry!$C$9*Parametry!$C$10^(F11-1),0) -> 72 | I11: =ROUNDUP((Parametry!$C$20*MAX(1,D11))*Parametry!$C$15,0) -> 1650 | J11: =ROUNDUP((Parametry!$C$20*MAX(1,D11))*Parametry!$C$15,0) -> 1650 | K11: =ROUNDUP((Parametry!$C$20*MAX(1,D11))*Parametry!$C$15,0) -> 1650 | L11: =ROUNDUP((Parametry!$C$20*MAX(1,D11))*Parametry!$C$15,0) -> 1650 | M11: =ROUNDUP((Parametry!$C$20*MAX(1,D11))*Parametry!$C$15,0) -> 1650 | N11: =ROUNDUP((Parametry!$C$20*MAX(1,D11))*Parametry!$C$15,0) -> 1650 | O11: =ROUNDUP(J11/H11,0) -> 23 | P11: =ROUNDUP(K11/H11,0) -> 23 | Q11: =ROUNDUP(L11/H11,0) -> 23 | R11: =ROUNDUP(M11/H11,0) -> 23 | S11: =ROUNDUP(N11/H11,0) -> 23 | T11: =SUM(O11:S11) -> 115 | U11: =ROUNDUP(T11/G11,0) -> 20 | V11: =U11*Parametry!$C$11 -> 100 | W11: =2 -> 2 | X11: =V11*(W11-1) -> 100 | Y11: =V11*W11 -> 200 | Z11: =SUM(J11:N11) -> 8250 | AA11: Tylko ta budowa; 6 dostępnych po uwzględnieniu priorytetów; poziom magazynu=scenariusz L. Jeśli priorytety blokują dostawy, rzeczywiste ETA rośnie.
A12: Dom | B12: 1→2 | C12: Bez kolejki | D12: 1 | E12: =D12+1 -> 2 | F12: 1 | G12: =Parametry!$C$12 -> 6 | H12: =ROUNDDOWN(Parametry!$C$9*Parametry!$C$10^(F12-1),0) -> 60 | I12: =ROUNDUP((Parametry!$C$20*MAX(1,D12))*1,0) -> 500 | J12: =ROUNDUP((Parametry!$C$20*MAX(1,D12))*1,0) -> 500 | K12: =ROUNDUP((Parametry!$C$20*MAX(1,D12))*1,0) -> 500 | L12: =ROUNDUP((Parametry!$C$20*MAX(1,D12))*1,0) -> 500 | M12: =ROUNDUP((Parametry!$C$20*MAX(1,D12))*1,0) -> 500 | N12: =ROUNDUP((Parametry!$C$20*MAX(1,D12))*1,0) -> 500 | O12: =ROUNDUP(J12/H12,0) -> 9 | P12: =ROUNDUP(K12/H12,0) -> 9 | Q12: =ROUNDUP(L12/H12,0) -> 9 | R12: =ROUNDUP(M12/H12,0) -> 9 | S12: =ROUNDUP(N12/H12,0) -> 9 | T12: =SUM(O12:S12) -> 45 | U12: =ROUNDUP(T12/G12,0) -> 8 | V12: =U12*Parametry!$C$11 -> 40 | W12: =2 -> 2 | X12: =V12*(W12-1) -> 40 | Y12: =V12*W12 -> 80 | Z12: =SUM(J12:N12) -> 2500 | AA12: Tylko ta budowa; 6 dostępnych po uwzględnieniu priorytetów; poziom magazynu=scenariusz L. Jeśli priorytety blokują dostawy, rzeczywiste ETA rośnie.
A13: Dom | B13: 1→2 | C13: Kolejka +10% | D13: 1 | E13: =D13+1 -> 2 | F13: 1 | G13: =Parametry!$C$12 -> 6 | H13: =ROUNDDOWN(Parametry!$C$9*Parametry!$C$10^(F13-1),0) -> 60 | I13: =ROUNDUP((Parametry!$C$20*MAX(1,D13))*Parametry!$C$15,0) -> 550 | J13: =ROUNDUP((Parametry!$C$20*MAX(1,D13))*Parametry!$C$15,0) -> 550 | K13: =ROUNDUP((Parametry!$C$20*MAX(1,D13))*Parametry!$C$15,0) -> 550 | L13: =ROUNDUP((Parametry!$C$20*MAX(1,D13))*Parametry!$C$15,0) -> 550 | M13: =ROUNDUP((Parametry!$C$20*MAX(1,D13))*Parametry!$C$15,0) -> 550 | N13: =ROUNDUP((Parametry!$C$20*MAX(1,D13))*Parametry!$C$15,0) -> 550 | O13: =ROUNDUP(J13/H13,0) -> 10 | P13: =ROUNDUP(K13/H13,0) -> 10 | Q13: =ROUNDUP(L13/H13,0) -> 10 | R13: =ROUNDUP(M13/H13,0) -> 10 | S13: =ROUNDUP(N13/H13,0) -> 10 | T13: =SUM(O13:S13) -> 50 | U13: =ROUNDUP(T13/G13,0) -> 9 | V13: =U13*Parametry!$C$11 -> 45 | W13: =2 -> 2 | X13: =V13*(W13-1) -> 45 | Y13: =V13*W13 -> 90 | Z13: =SUM(J13:N13) -> 2750 | AA13: Tylko ta budowa; 6 dostępnych po uwzględnieniu priorytetów; poziom magazynu=scenariusz L. Jeśli priorytety blokują dostawy, rzeczywiste ETA rośnie.
A14: Dom | B14: 2→3 | C14: Bez kolejki | D14: 2 | E14: =D14+1 -> 3 | F14: 2 | G14: =Parametry!$C$12 -> 6 | H14: =ROUNDDOWN(Parametry!$C$9*Parametry!$C$10^(F14-1),0) -> 66 | I14: =ROUNDUP((Parametry!$C$20*MAX(1,D14))*1,0) -> 1000 | J14: =ROUNDUP((Parametry!$C$20*MAX(1,D14))*1,0) -> 1000 | K14: =ROUNDUP((Parametry!$C$20*MAX(1,D14))*1,0) -> 1000 | L14: =ROUNDUP((Parametry!$C$20*MAX(1,D14))*1,0) -> 1000 | M14: =ROUNDUP((Parametry!$C$20*MAX(1,D14))*1,0) -> 1000 | N14: =ROUNDUP((Parametry!$C$20*MAX(1,D14))*1,0) -> 1000 | O14: =ROUNDUP(J14/H14,0) -> 16 | P14: =ROUNDUP(K14/H14,0) -> 16 | Q14: =ROUNDUP(L14/H14,0) -> 16 | R14: =ROUNDUP(M14/H14,0) -> 16 | S14: =ROUNDUP(N14/H14,0) -> 16 | T14: =SUM(O14:S14) -> 80 | U14: =ROUNDUP(T14/G14,0) -> 14 | V14: =U14*Parametry!$C$11 -> 70 | W14: =2 -> 2 | X14: =V14*(W14-1) -> 70 | Y14: =V14*W14 -> 140 | Z14: =SUM(J14:N14) -> 5000 | AA14: Tylko ta budowa; 6 dostępnych po uwzględnieniu priorytetów; poziom magazynu=scenariusz L. Jeśli priorytety blokują dostawy, rzeczywiste ETA rośnie.
A15: Dom | B15: 2→3 | C15: Kolejka +10% | D15: 2 | E15: =D15+1 -> 3 | F15: 2 | G15: =Parametry!$C$12 -> 6 | H15: =ROUNDDOWN(Parametry!$C$9*Parametry!$C$10^(F15-1),0) -> 66 | I15: =ROUNDUP((Parametry!$C$20*MAX(1,D15))*Parametry!$C$15,0) -> 1100 | J15: =ROUNDUP((Parametry!$C$20*MAX(1,D15))*Parametry!$C$15,0) -> 1100 | K15: =ROUNDUP((Parametry!$C$20*MAX(1,D15))*Parametry!$C$15,0) -> 1100 | L15: =ROUNDUP((Parametry!$C$20*MAX(1,D15))*Parametry!$C$15,0) -> 1100 | M15: =ROUNDUP((Parametry!$C$20*MAX(1,D15))*Parametry!$C$15,0) -> 1100 | N15: =ROUNDUP((Parametry!$C$20*MAX(1,D15))*Parametry!$C$15,0) -> 1100 | O15: =ROUNDUP(J15/H15,0) -> 17 | P15: =ROUNDUP(K15/H15,0) -> 17 | Q15: =ROUNDUP(L15/H15,0) -> 17 | R15: =ROUNDUP(M15/H15,0) -> 17 | S15: =ROUNDUP(N15/H15,0) -> 17 | T15: =SUM(O15:S15) -> 85 | U15: =ROUNDUP(T15/G15,0) -> 15 | V15: =U15*Parametry!$C$11 -> 75 | W15: =2 -> 2 | X15: =V15*(W15-1) -> 75 | Y15: =V15*W15 -> 150 | Z15: =SUM(J15:N15) -> 5500 | AA15: Tylko ta budowa; 6 dostępnych po uwzględnieniu priorytetów; poziom magazynu=scenariusz L. Jeśli priorytety blokują dostawy, rzeczywiste ETA rośnie.
A16: Dom | B16: 3→4 | C16: Bez kolejki | D16: 3 | E16: =D16+1 -> 4 | F16: 3 | G16: =Parametry!$C$12 -> 6 | H16: =ROUNDDOWN(Parametry!$C$9*Parametry!$C$10^(F16-1),0) -> 72 | I16: =ROUNDUP((Parametry!$C$20*MAX(1,D16))*1,0) -> 1500 | J16: =ROUNDUP((Parametry!$C$20*MAX(1,D16))*1,0) -> 1500 | K16: =ROUNDUP((Parametry!$C$20*MAX(1,D16))*1,0) -> 1500 | L16: =ROUNDUP((Parametry!$C$20*MAX(1,D16))*1,0) -> 1500 | M16: =ROUNDUP((Parametry!$C$20*MAX(1,D16))*1,0) -> 1500 | N16: =ROUNDUP((Parametry!$C$20*MAX(1,D16))*1,0) -> 1500 | O16: =ROUNDUP(J16/H16,0) -> 21 | P16: =ROUNDUP(K16/H16,0) -> 21 | Q16: =ROUNDUP(L16/H16,0) -> 21 | R16: =ROUNDUP(M16/H16,0) -> 21 | S16: =ROUNDUP(N16/H16,0) -> 21 | T16: =SUM(O16:S16) -> 105 | U16: =ROUNDUP(T16/G16,0) -> 18 | V16: =U16*Parametry!$C$11 -> 90 | W16: =2 -> 2 | X16: =V16*(W16-1) -> 90 | Y16: =V16*W16 -> 180 | Z16: =SUM(J16:N16) -> 7500 | AA16: Tylko ta budowa; 6 dostępnych po uwzględnieniu priorytetów; poziom magazynu=scenariusz L. Jeśli priorytety blokują dostawy, rzeczywiste ETA rośnie.
A17: Dom | B17: 3→4 | C17: Kolejka +10% | D17: 3 | E17: =D17+1 -> 4 | F17: 3 | G17: =Parametry!$C$12 -> 6 | H17: =ROUNDDOWN(Parametry!$C$9*Parametry!$C$10^(F17-1),0) -> 72 | I17: =ROUNDUP((Parametry!$C$20*MAX(1,D17))*Parametry!$C$15,0) -> 1650 | J17: =ROUNDUP((Parametry!$C$20*MAX(1,D17))*Parametry!$C$15,0) -> 1650 | K17: =ROUNDUP((Parametry!$C$20*MAX(1,D17))*Parametry!$C$15,0) -> 1650 | L17: =ROUNDUP((Parametry!$C$20*MAX(1,D17))*Parametry!$C$15,0) -> 1650 | M17: =ROUNDUP((Parametry!$C$20*MAX(1,D17))*Parametry!$C$15,0) -> 1650 | N17: =ROUNDUP((Parametry!$C$20*MAX(1,D17))*Parametry!$C$15,0) -> 1650 | O17: =ROUNDUP(J17/H17,0) -> 23 | P17: =ROUNDUP(K17/H17,0) -> 23 | Q17: =ROUNDUP(L17/H17,0) -> 23 | R17: =ROUNDUP(M17/H17,0) -> 23 | S17: =ROUNDUP(N17/H17,0) -> 23 | T17: =SUM(O17:S17) -> 115 | U17: =ROUNDUP(T17/G17,0) -> 20 | V17: =U17*Parametry!$C$11 -> 100 | W17: =2 -> 2 | X17: =V17*(W17-1) -> 100 | Y17: =V17*W17 -> 200 | Z17: =SUM(J17:N17) -> 8250 | AA17: Tylko ta budowa; 6 dostępnych po uwzględnieniu priorytetów; poziom magazynu=scenariusz L. Jeśli priorytety blokują dostawy, rzeczywiste ETA rośnie.
